Workbook

Sheet 期望
B1: 最小攻击 | C1: 最大攻击 | D1: 穿透 | E1: 伤害加成 | F1: 武学属性 | G1: 鸣金 | H1: 怪物属性 | K1: 真气比列 | L1: 期望 | M1: 会心期望 | N1: 会意期望 | O1: 普通期望 | P1: 擦伤期望 | Q1: 次数 | R1: 技能 | S1: 增益1 | T1: 增益2 | U1: 增益3 | V1: 增益4 | W1: 增益5 | X1: 增益6 | Y1: 增益7 | Z1: 增益8 | AA1: 增益9 | AB1: 增益10 | AC1: 增益11 | AD1: 增益12 | AE1: 增益13 | AF1: 增益14 | AG1: 增益15 | AH1: 类型 | AI1: 外功倍率 | AJ1: 外攻固伤 | AK1: 属性倍率 | AL1: 属性固伤 | AM1: 通用增伤 | AN1: 外攻加成 | AO1: 即时小外 | AP1: 即时大外 | AQ1: 外穿加成 | AR1: 外伤加成 | AS1: 属攻加成 | AT1: 即时小鸣 | AU1: 即时大鸣 | AV1: 鸣金穿透 | AW1: 鸣金加成 | AX1: 即时小裂 | AY1: 即时大裂 | AZ1: 裂石穿透 | BA1: 裂石加成 | BB1: 即时小牵 | BC1: 即时大牵 | BD1: 牵丝穿透 | BE1: 牵丝加成 | BF1: 即时小破 | BG1: 即时大破 | BH1: 破竹穿透 | BI1: 破竹加成 | BJ1: 生效精准 | BK1: 生效会心 | BL1: 生效会心伤害 | BM1: 生效会意 | BN1: 生效会意伤害 | BO1: 会心占比 | BP1: 普攻占比 | BQ1: 擦伤占比 | BR1: 特殊增伤
A2: 外功 | B2: 1994.8 | C2: 7187.6 | D2: 63.8 | F2: 套装 | G2: 飞隼 | H2: 防御 | I2: =620*IF(F17="√",0.94,1) -> 582.8 | K2: =$L2*VLOOKUP($R2,武学奇术!$A:$ZZ,31,FALSE) -> 24725.152 | L2: =($M2*$BO2+$N2*$BM2+$O2*$BP2+$P2*$BQ2) -> 24725.152 | M2: =((($AO2+$AP2)/2*$AI2+$AJ2)*(1+$AQ2)*(1+$AR2)+(($AT2+$AU2)/2*IF($G$1="鸣金",$AK2,$AI2)+IF($G$1="鸣金",$AL2*1.5,0))*(1+$AV2)*(1+$AW2)+(($AX2+$AY2)/2*IF($G$1="裂石",$AK2,$AI2)+IF($G$1="裂石",$AL2*1.5,0))*(1+$AZ2)*(1+$BA2)+(($BB2+$BC2)/2*IF($G$1="牵丝",$AK2,$AI2)+IF($G$1="牵丝",$AL2*1.5,0))*(1+$BD2)*(1+$BE2)+(($BF2+$BG2)/2*IF($G$1="破竹",$AK2,$AI2)+IF($G$1="破竹",$AL2*1.5,0))*(1+$BH2)*(1+$BI2))*(1+$AM2)*$BL2*$Q2*(1+IF(VLOOKUP($R2,武学奇术!$A:$ZZ,30,FALSE)="流血",$B$21,0))*(1+$BR2) -> 24597.577 | N2: =(($AP2*$AI2+$AJ2)*(1+$AQ2)*(1+$AR2)+($AU2*IF($G$1="鸣金",$AK2,$AI2)+IF($G$1="鸣金",$AL2*1.5,0))*(1+$AV2)*(1+$AW2)+($AY2*IF($G$1="裂石",$AK2,$AI2)+IF($G$1="裂石",$AL2*1.5,0))*(1+$AZ2)*(1+$BA2)+($BC2*IF($G$1="牵丝",$AK2,$AI2)+IF($G$1="牵丝",$AL2*1.5,0))*(1+$BD2)*(1+$BE2)+($BG2*IF($G$1="破竹",$AK2,$AI2)+IF($G$1="破竹",$AL2*1.5,0))*(1+$BH2)*(1+$BI2))*(1+$AM2)*$BN2*$Q2*(1+IF(VLOOKUP($R2,武学奇术!$A:$ZZ,30,FALSE)="流血",$B$21,0))*(1+$BR2) -> 34550.417 | O2: =((($AO2+$AP2)/2*$AI2+$AJ2)*(1+$AQ2)*(1+$AR2)+(($AT2+$AU2)/2*IF($G$1="鸣金",$AK2,$AI2)+IF($G$1="鸣金",$AL2*1.5,0))*(1+$AV2)*(1+$AW2)+(($AX2+$AY2)/2*IF($G$1="裂石",$AK2,$AI2)+IF($G$1="裂石",$AL2*1.5,0))*(1+$AZ2)*(1+$BA2)+(($BB2+$BC2)/2*IF($G$1="牵丝",$AK2,$AI2)+IF($G$1="牵丝",$AL2*1.5,0))*(1+$BD2)*(1+$BE2)+(($BF2+$BG2)/2*IF($G$1="破竹",$AK2,$AI2)+IF($G$1="破竹",$AL2*1.5,0))*(1+$BH2)*(1+$BI2))*(1+$AM2)*$Q2*(1+IF(VLOOKUP($R2,武学奇术!$A:$ZZ,30,FALSE)="流血",$B$21,0))*(1+$BR2) -> 16398.384 | P2: =((($AO2*$AI2+$AJ2)*(1+$AQ2)*(1+$AR2)+($AT2*IF($G$1="鸣金",$AK2,$AI2)+IF($G$1="鸣金",$AL2*1.5,0))*(1+$AV2)*(1+$AW2)+($AX2*IF($G$1="裂石",$AK2,$AI2)+IF($G$1="裂石",$AL2*1.5,0))*(1+$AZ2)*(1+$BA2)+($BB2*IF($G$1="牵丝",$AK2,$AI2)+IF($G$1="牵丝",$AL2*1.5,0))*(1+$BD2)*(1+$BE2)+($BF2*IF($G$1="破竹",$AK2,$AI2)+IF($G$1="破竹",$AL2*1.5,0))*(1+$BH2)*(1+$BI2))*(1+$AM2))*$Q2*(1+IF(VLOOKUP($R2,武学奇术!$A:$ZZ,30,FALSE)="流血",$B$21,0))*(1+$BR2) -> 8327.6352 | Q2: 1 | R2: 剑R一段前4hit | S2: 滴水 | T2: N/a | U2: N/a | V2: N/a | W2: N/a | X2: 易水歌1层 | Y2: N/a | Z2: N/a | AA2: N/a | AB2: 裁云(拐) | AC2: 扶风(拐) | AD2: N/a | AE2: N/a | AF2: 近战笛 | AG2: 秋瞑帖1层 | AH2: =VLOOKUP($R2,武学奇术!$A:$ZZ,25,FALSE) -> 剑 | AI2: =VLOOKUP($R2,武学奇术!$A:$ZZ,26,FALSE) -> 1.2087643 | AJ2: =VLOOKUP($R2,武学奇术!$A:$ZZ,27,FALSE)*(1+IF(OR($AH2=$F$4,$AH2=$F$5),$B$22,0)) -> 501.42857 | AK2: =VLOOKUP($R2,武学奇术!$A:$ZZ,28,FALSE) -> 1.8131786 | AL2: =VLOOKUP($R2,武学奇术!$A:$ZZ,29,FALSE)*(1+IF(OR($AH2=$F$4,$AH2=$F$5),$B$22,0)) -> 272.89286 | AM2: {=$G$3+IFERROR(VLOOKUP($AH2,$F$4:$G$7,2,FALSE),0)+VLOOKUP($R2,武学奇术!$A:$ZZ,2,FALSE)+SUM(_xlfn.XLOOKUP($S2:$AG2,增益!$A:$A,增益!$B:$B,0))} -> 0.4841 | AN2: {=VLOOKUP($R2,武学奇术!$A:$ZZ,5,FALSE)+SUM(_xlfn.XLOOKUP($S2:$AG2,增益!$A:$A,增益!$E:$E,0))} -> 0 | AO2: {=$D$10*(1+$AN2)+VLOOKUP($R2,武学奇术!$A:$ZZ,3,FALSE)+SUM(_xlfn.XLOOKUP($S2:$AG2,增益!$A:$A,增益!$C:$C,0))-$I$2} -> 1831.48 | AP2: {=$E$10*(1+$AN2)+VLOOKUP($R2,武学奇术!$A:$ZZ,4,FALSE)+SUM(_xlfn.XLOOKUP($S2:$AG2,增益!$A:$A,增益!$D:$D,0))-$I$2} -> 7763.56 | AQ2: {=IF($F$10-$I$3+VLOOKUP($R2,武学奇术!$A:$ZZ,6,FALSE)+SUM(_xlfn.XLOOKUP(S2:AG2,增益!$A:$A,增益!$F:$F,0))>0,($F$10-$I$3+VLOOKUP($R2,武学奇术!$A:$ZZ,6,FALSE)+SUM(_xlfn.XLOOKUP(S2:AG2,增益!$A:$A,增益!$F:$F,0)))/200,($F$10-$I$3+VLOOKUP($R2,武学奇术!$A:$ZZ,6,FALSE)+SUM(_xlfn.XLOOKUP(S2:AG2,增益!$A:$A,增益!$F:$F,0)))/100)} -> 0.254 | AR2: {=$G$10+VLOOKUP($R2,武学奇术!$A:$ZZ,7,FALSE)+SUM(_xlfn.XLOOKUP(S2:AG2,增益!$A:$A,增益!$G:$G,0))} -> 0 | AS2: {=VLOOKUP($R2,武学奇术!$A:$ZZ,8,FALSE)+SUM(_xlfn.XLOOKUP(S2:AG2,增益!$A:$A,增益!$H:$H,0))} -> 0 | AT2: =$D$11*(1+$AS2) -> 680.02 | AU2: =$E$11*(1+$AS2) -> 1288.54 | AV2: {=IF($F$11-$I$4+VLOOKUP($R2,武学奇术!$A:$ZZ,9,FALSE)+SUM(_xlfn.XLOOKUP(S2:AG2,增益!$A:$A,增益!$I:$I,0))>0,($F$11-$I$4+VLOOKUP($R2,武学奇术!$A:$ZZ,9,FALSE)+SUM(_xlfn.XLOOKUP(S2:AG2,增益!$A:$A,增益!$I:$I,0)))/200,($F$11-$I$4+VLOOKUP($R2,武学奇术!$A:$ZZ,9,FALSE)+SUM(_xlfn.XLOOKUP(S2:AG2,增益!$A:$A,增益!$I:$I,0)))/100)} -> 0 | AW2: {=$G$11+VLOOKUP($R2,武学奇术!$A:$ZZ,10,FALSE)+SUM(_xlfn.XLOOKUP(S2:AG2,增益!$A:$A,增益!$J:$J,0))} -> 0.15 | AX2: =$D$12*(1+$AS2) -> 0 | AY2: =$E$12*(1+$AS2) -> 0 | AZ2: {=IF($F$12-$I$4+VLOOKUP($R2,武学奇术!$A:$ZZ,11,FALSE)+SUM(_xlfn.XLOOKUP(S2:AG2,增益!$A:$A,增益!$K:$K,0))>0,($F$12-$I$4+VLOOKUP($R2,武学奇术!$A:$ZZ,11,FALSE)+SUM(_xlfn.XLOOKUP(S2:AG2,增益!$A:$A,增益!$K:$K,0)))/200,($F$12-$I$4+VLOOKUP($R2,武学奇术!$A:$ZZ,11,FALSE)+SUM(_xlfn.XLOOKUP(S2:AG2,增益!$A:$A,增益!$K:$K,0)))/100)} -> -0.3 | BA2: {=$G$12+VLOOKUP($R2,武学奇术!$A:$ZZ,12,FALSE)+SUM(_xlfn.XLOOKUP(S2:AG2,增益!$A:$A,增益!$L:$L,0))} -> 0 | BB2: =$D$13*(1+$AS2) -> 0 | BC2: =$E$13*(1+$AS2) -> 0 | BD2: {=IF($F$13-$I$4+VLOOKUP($R2,武学奇术!$A:$ZZ,13,FALSE)+SUM(_xlfn.XLOOKUP(S2:AG2,增益!$A:$A,增益!$M:$M,0))>0,($F$13-$I$4+VLOOKUP($R2,武学奇术!$A:$ZZ,13,FALSE)+SUM(_xlfn.XLOOKUP(S2:AG2,增益!$A:$A,增益!$K:$K,0)))/200,($F$13-$I$4+VLOOKUP($R2,武学奇术!$A:$ZZ,13,FALSE)+SUM(_xlfn.XLOOKUP(S2:AG2,增益!$A:$A,增益!$M:$M,0)))/100)} -> -0.3 | BE2: {=$G$13+VLOOKUP($R2,武学奇术!$A:$ZZ,14,FALSE)+SUM(_xlfn.XLOOKUP(S2:AG2,增益!$A:$A,增益!$N:$N,0))} -> 0 | BF2: =$D$14*(1+$AS2) -> 0 | BG2: =$E$14*(1+$AS2) -> 0 | BH2: {=IF($F$14-$I$4+VLOOKUP($R2,武学奇术!$A:$ZZ,15,FALSE)+SUM(_xlfn.XLOOKUP(S2:AG2,增益!$A:$A,增益!$O:$O,0))>0,($F$14-$I$4+VLOOKUP($R2,武学奇术!$A:$ZZ,15,FALSE)+SUM(_xlfn.XLOOKUP(S2:AG2,增益!$A:$A,增益!$O:$O,0)))/200,($F$14-$I$4+VLOOKUP($R2,武学奇术!$A:$ZZ,15,FALSE)+SUM(_xlfn.XLOOKUP(S2:AG2,增益!$A:$A,增益!$O:$O,0)))/100)} -> -0.3 | BI2: {=$G$14+VLOOKUP($R2,武学奇术!$A:$ZZ,16,FALSE)+SUM(_xlfn.XLOOKUP(S2:AG2,增益!$A:$A,增益!$P:$P,0))} -> 0 | BJ2: =MIN(IF(VLOOKUP($R2,武学奇术!$A:$ZZ,23,FALSE)=1,100%,$B$8),100%) -> 0.8229 | BK2: {=IF(VLOOKUP($R2,武学奇术!$A:$ZZ,23,FALSE)=1,100%,MIN(80%,$B$9+VLOOKUP($R2,武学奇术!$A:$ZZ,17,FALSE)+SUM(_xlfn.XLOOKUP(S2:AG2,增益!$A:$A,增益!$Q:$Q,0)))+$B$11+SUM(_xlfn.XLOOKUP(S2:AG2,增益!$A:$A,增益!$U:$U,0)))*IF(VLOOKUP($R2,武学奇术!$A:$ZZ,24,FALSE)=1,0,1)} -> 0.2285 | BL2: {=1+$B$13+VLOOKUP($R2,武学奇术!$A:$ZZ,18,FALSE)+SUM(_xlfn.XLOOKUP(S2:AG2,增益!$A:$A,增益!$R:$R,0))} -> 1.5 | BM2: {=IF(VLOOKUP($R2,武学奇术!$A:$ZZ,24,FALSE)=1,100%,MIN(40%,$B$10+VLOOKUP($R2,武学奇术!$A:$ZZ,19,FALSE)+SUM(_xlfn.XLOOKUP(S2:AG2,增益!$A:$A,增益!$S:$S,0)))+$B$12+SUM(_xlfn.XLOOKUP(S2:AG2,增益!$A:$A,增益!$V:$V,0)))*IF(VLOOKUP($R2,武学奇术!$A:$ZZ,23,FALSE)=1,0,1)} -> 0.4195 | BN2: {=1+$B$14+VLOOKUP($R2,武学奇术!$A:$ZZ,20,FALSE)+SUM(_xlfn.XLOOKUP(S2:AG2,增益!$A:$A,增益!$T:$T,0))} -> 1.412 | BO2: =MIN((1-BM2)*BJ2,BJ2*BK2) -> 0.18803265 | BP2: =1-BM2-BO2-BQ2 -> 0.2896608 | BQ2: =IF(VLOOKUP($R2,武学奇术!$A:$ZZ,22,FALSE)=1,0,(1-$BJ2))*(1-$BM2) -> 0.10280655 | BR2: {=SUM(_xlfn.XLOOKUP(S2:AG2,增益!$A:$A,增益!$W:$W,0))+$I$5} -> 0.06
A3: 鸣金 | B3: 539 | C3: 1079 | D3: 30 | E3: 0.15 | F3: 通用增伤 | G3: =B16+1.5%+IF($D$16="√",8%,0) -> 0.1842 | H3: 外抗 | I3: =25-IF(D17="√",10,0)-IF(F17="√",10,0) -> 15 | K3: =$L3*VLOOKUP($R3,武学奇术!$A:$ZZ,31,FALSE) -> 41238.373 | L3: =($M3*$BO3+$N3*$BM3+$O3*$BP3+$P3*$BQ3) -> 41238.373 | M3: =((($AO3+$AP3)/2*$AI3+$AJ3)*(1+$AQ3)*(1+$AR3)+(($AT3+$AU3)/2*IF($G$1="鸣金",$AK3,$AI3)+IF($G$1="鸣金",$AL3*1.5,0))*(1+$AV3)*(1+$AW3)+(($AX3+$AY3)/2*IF($G$1="裂石",$AK3,$AI3)+IF($G$1="裂石",$AL3*1.5,0))*(1+$AZ3)*(1+$BA3)+(($BB3+$BC3)/2*IF($G$1="牵丝",$AK3,$AI3)+IF($G$1="牵丝",$AL3*1.5,0))*(1+$BD3)*(1+$BE3)+(($BF3+$BG3)/2*IF($G$1="破竹",$AK3,$AI3)+IF($G$1="破竹",$AL3*1.5,0))*(1+$BH3)*(1+$BI3))*(1+$AM3)*$BL3*$Q3*(1+IF(VLOOKUP($R3,武学奇术!$A:$ZZ,30,FALSE)="流血",$B$21,0))*(1+$BR3) -> 41021.072 | N3: =(($AP3*$AI3+$AJ3)*(1+$AQ3)*(1+$AR3)+($AU3*IF($G$1="鸣金",$AK3,$AI3)+IF($G$1="鸣金",$AL3*1.5,0))*(1+$AV3)*(1+$AW3)+($AY3*IF($G$1="裂石",$AK3,$AI3)+IF($G$1="裂石",$AL3*1.5,0))*(1+$AZ3)*(1+$BA3)+($BC3*IF($G$1="牵丝",$AK3,$AI3)+IF($G$1="牵丝",$AL3*1.5,0))*(1+$BD3)*(1+$BE3)+($BG3*IF($G$1="破竹",$AK3,$AI3)+IF($G$1="破竹",$AL3*1.5,0))*(1+$BH3)*(1+$BI3))*(1+$AM3)*$BN3*$Q3*(1+IF(VLOOKUP($R3,武学奇术!$A:$ZZ,30,FALSE)="流血",$B$21,0))*(1+$BR3) -> 57632.409 | O3: =((($AO3+$AP3)/2*$AI3+$AJ3)*(1+$AQ3)*(1+$AR3)+(($AT3+$AU3)/2*IF($G$1="鸣金",$AK3,$AI3)+IF($G$1="鸣金",$AL3*1.5,0))*(1+$AV3)*(1+$AW3)+(($AX3+$AY3)/2*IF($G$1="裂石",$AK3,$AI3)+IF($G$1="裂石",$AL3*1.5,0))*(1+$AZ3)*(1+$BA3)+(($BB3+$BC3)/2*IF($G$1="牵丝",$AK3,$AI3)+IF($G$1="牵丝",$AL3*1.5,0))*(1+$BD3)*(1+$BE3)+(($BF3+$BG3)/2*IF($G$1="破竹",$AK3,$AI3)+IF($G$1="破竹",$AL3*1.5,0))*(1+$BH3)*(1+$BI3))*(1+$AM3)*$Q3*(1+IF(VLOOKUP($R3,武学奇术!$A:$ZZ,30,FALSE)="流血",$B$21,0))*(1+$BR3) -> 27347.381 | P3: =((($AO3*$AI3+$AJ3)*(1+$AQ3)*(1+$AR3)+($AT3*IF($G$1="鸣金",$AK3,$AI3)+IF($G$1="鸣金",$AL3*1.5,0))*(1+$AV3)*(1+$AW3)+($AX3*IF($G$1="裂石",$AK3,$AI3)+IF($G$1="裂石",$AL3*1.5,0))*(1+$AZ3)*(1+$BA3)+($BB3*IF($G$1="牵丝",$AK3,$AI3)+IF($G$1="牵丝",$AL3*1.5,0))*(1+$BD3)*(1+$BE3)+($BF3*IF($G$1="破竹",$AK3,$AI3)+IF($G$1="破竹",$AL3*1.5,0))*(1+$BH3)*(1+$BI3))*(1+$AM3))*$Q3*(1+IF(VLOOKUP($R3,武学奇术!$A:$ZZ,30,FALSE)="流血",$B$21,0))*(1+$BR3) -> 13878.609 | Q3: 1 | R3: 枪Q | S3: 滴水 | T3: N/a | U3: N/a | V3: N/a | W3: N/a | X3: 易水歌1层 | Y3: N/a | Z3: N/a | AA3: 惧刃(拐) | AB3: 裁云(拐) | AC3: 扶风(拐) | AD3: 离猎(拐) | AE3: N/a | AF3: 近战笛 | AG3: 秋瞑帖1层 | AH3: =VLOOKUP($R3,武学奇术!$A:$ZZ,25,FALSE) -> 枪 | AI3: =VLOOKUP($R3,武学奇术!$A:$ZZ,26,FALSE) -> 2.1401 | AJ3: =VLOOKUP($R3,武学奇术!$A:$ZZ,27,FALSE)*(1+IF(OR($AH3=$F$4,$AH3=$F$5),$B$22,0)) -> 882 | AK3: =VLOOKUP($R3,武学奇术!$A:$ZZ,28,FALSE) -> 3.2101 | AL3: =VLOOKUP($R3,武学奇术!$A:$ZZ,29,FALSE)*(1+IF(OR($AH3=$F$4,$AH3=$F$5),$B$22,0)) -> 480 | AM3: {=$G$3+IFERROR(VLOOKUP($AH3,$F$4:$G$7,2,FALSE),0)+VLOOKUP($R3,武学奇术!$A:$ZZ,2,FALSE)+SUM(_xlfn.XLOOKUP($S3:$AG3,增益!$A:$A,增益!$B:$B,0))} -> 0.3989 | AN3: {=VLOOKUP($R3,武学奇术!$A:$ZZ,5,FALSE)+SUM(_xlfn.XLOOKUP($S3:$AG3,增益!$A:$A,增益!$E:$E,0))} -> 0 | AO3: {=$D$10*(1+$AN3)+VLOOKUP($R3,武学奇术!$A:$ZZ,3,FALSE)+SUM(_xlfn.XLOOKUP($S3:$AG3,增益!$A:$A,增益!$C:$C,0))-$I$2} -> 1831.48 | AP3: {=$E$10*(1+$AN3)+VLOOKUP($R3,武学奇术!$A:$ZZ,4,FALSE)+SUM(_xlfn.XLOOKUP($S3:$AG3,增益!$A:$A,增益!$D:$D,0))-$I$2} -> 7763.56 | AQ3: {=IF($F$10-$I$3+VLOOKUP($R3,武学奇术!$A:$ZZ,6,FALSE)+SUM(_xlfn.XLOOKUP(S3:AG3,增益!$A:$A,增益!$F:$F,0))>0,($F$10-$I$3+VLOOKUP($R3,武学奇术!$A:$ZZ,6,FALSE)+SUM(_xlfn.XLOOKUP(S3:AG3,增益!$A:$A,增益!$F:$F,0)))/200,($F$10-$I$3+VLOOKUP($R3,武学奇术!$A:$ZZ,6,FALSE)+SUM(_xlfn.XLOOKUP(S3:AG3,增益!$A:$A,增益!$F:$F,0)))/100)} -> 0.254 | AR3: {=$G$10+VLOOKUP($R3,武学奇术!$A:$ZZ,7,FALSE)+SUM(_xlfn.XLOOKUP(S3:AG3,增益!$A:$A,增益!$G:$G,0))} -> 0 | AS3: {=VLOOKUP($R3,武学奇术!$A:$ZZ,8,FALSE)+SUM(_xlfn.XLOOKUP(S3:AG3,增益!$A:$A,增益!$H:$H,0))} -> 0 | AT3: =$D$11*(1+$AS3) -> 680.02 | AU3: =$E$11*(1+$AS3) -> 1288.54 | AV3: {=IF($F$11-$I$4+VLOOKUP($R3,武学奇术!$A:$ZZ,9,FALSE)+SUM(_xlfn.XLOOKUP(S3:AG3,增益!$A:$A,增益!$I:$I,0))>0,($F$11-$I$4+VLOOKUP($R3,武学奇术!$A:$ZZ,9,FALSE)+SUM(_xlfn.XLOOKUP(S3:AG3,增益!$A:$A,增益!$I:$I,0)))/200,($F$11-$I$4+VLOOKUP($R3,武学奇术!$A:$ZZ,9,FALSE)+SUM(_xlfn.XLOOKUP(S3:AG3,增益!$A:$A,增益!$I:$I,0)))/100)} -> 0 | AW3: {=$G$11+VLOOKUP($R3,武学奇术!$A:$ZZ,10,FALSE)+SUM(_xlfn.XLOOKUP(S3:AG3,增益!$A:$A,增益!$J:$J,0))} -> 0.15 | AX3: =$D$12*(1+$AS3) -> 0 | AY3: =$E$12*(1+$AS3) -> 0 | AZ3: {=IF($F$12-$I$4+VLOOKUP($R3,武学奇术!$A:$ZZ,11,FALSE)+SUM(_xlfn.XLOOKUP(S3:AG3,增益!$A:$A,增益!$K:$K,0))>0,($F$12-$I$4+VLOOKUP($R3,武学奇术!$A:$ZZ,11,FALSE)+SUM(_xlfn.XLOOKUP(S3:AG3,增益!$A:$A,增益!$K:$K,0)))/200,($F$12-$I$4+VLOOKUP($R3,武学奇术!$A:$ZZ,11,FALSE)+SUM(_xlfn.XLOOKUP(S3:AG3,增益!$A:$A,增益!$K:$K,0)))/100)} -> -0.3 | BA3: {=$G$12+VLOOKUP($R3,武学奇术!$A:$ZZ,12,FALSE)+SUM(_xlfn.XLOOKUP(S3:AG3,增益!$A:$A,增益!$L:$L,0))} -> 0 | BB3: =$D$13*(1+$AS3) -> 0 | BC3: =$E$13*(1+$AS3) -> 0 | BD3: {=IF($F$13-$I$4+VLOOKUP($R3,武学奇术!$A:$ZZ,13,FALSE)+SUM(_xlfn.XLOOKUP(S3:AG3,增益!$A:$A,增益!$M:$M,0))>0,($F$13-$I$4+VLOOKUP($R3,武学奇术!$A:$ZZ,13,FALSE)+SUM(_xlfn.XLOOKUP(S3:AG3,增益!$A:$A,增益!$K:$K,0)))/200,($F$13-$I$4+VLOOKUP($R3,武学奇术!$A:$ZZ,13,FALSE)+SUM(_xlfn.XLOOKUP(S3:AG3,增益!$A:$A,增益!$M:$M,0)))/100)} -> -0.3 | BE3: {=$G$13+VLOOKUP($R3,武学奇术!$A:$ZZ,14,FALSE)+SUM(_xlfn.XLOOKUP(S3:AG3,增益!$A:$A,增益!$N:$N,0))} -> 0 | BF3: =$D$14*(1+$AS3) -> 0 | BG3: =$E$14*(1+$AS3) -> 0 | BH3: {=IF($F$14-$I$4+VLOOKUP($R3,武学奇术!$A:$ZZ,15,FALSE)+SUM(_xlfn.XLOOKUP(S3:AG3,增益!$A:$A,增益!$O:$O,0))>0,($F$14-$I$4+VLOOKUP($R3,武学奇术!$A:$ZZ,15,FALSE)+SUM(_xlfn.XLOOKUP(S3:AG3,增益!$A:$A,增益!$O:$O,0)))/200,($F$14-$I$4+VLOOKUP($R3,武学奇术!$A:$ZZ,15,FALSE)+SUM(_xlfn.XLOOKUP(S3:AG3,增益!$A:$A,增益!$O:$O,0)))/100)} -> -0.3 | BI3: {=$G$14+VLOOKUP($R3,武学奇术!$A:$ZZ,16,FALSE)+SUM(_xlfn.XLOOKUP(S3:AG3,增益!$A:$A,增益!$P:$P,0))} -> 0 | BJ3: =MIN(IF(VLOOKUP($R3,武学奇术!$A:$ZZ,23,FALSE)=1,100%,$B$8),100%) -> 0.8229 | BK3: {=IF(VLOOKUP($R3,武学奇术!$A:$ZZ,23,FALSE)=1,100%,MIN(80%,$B$9+VLOOKUP($R3,武学奇术!$A:$ZZ,17,FALSE)+SUM(_xlfn.XLOOKUP(S3:AG3,增益!$A:$A,增益!$Q:$Q,0)))+$B$11+SUM(_xlfn.XLOOKUP(S3:AG3,增益!$A:$A,增益!$U:$U,0)))*IF(VLOOKUP($R3,武学奇术!$A:$ZZ,24,FALSE)=1,0,1)} -> 0.2285 | BL3: {=1+$B$13+VLOOKUP($R3,武学奇术!$A:$ZZ,18,FALSE)+SUM(_xlfn.XLOOKUP(S3:AG3,增益!$A:$A,增益!$R:$R,0))} -> 1.5 | BM3: {=IF(VLOOKUP($R3,武学奇术!$A:$ZZ,24,FALSE)=1,100%,MIN(40%,$B$10+VLOOKUP($R3,武学奇术!$A:$ZZ,19,FALSE)+SUM(_xlfn.XLOOKUP(S3:AG3,增益!$A:$A,增益!$S:$S,0)))+$B$12+SUM(_xlfn.XLOOKUP(S3:AG3,增益!$A:$A,增益!$V:$V,0)))*IF(VLOOKUP($R3,武学奇术!$A:$ZZ,23,FALSE)=1,0,1)} -> 0.4195 | BN3: {=1+$B$14+VLOOKUP($R3,武学奇术!$A:$ZZ,20,FALSE)+SUM(_xlfn.XLOOKUP(S3:AG3,增益!$A:$A,增益!$T:$T,0))} -> 1.412 | BO3: =MIN((1-BM3)*BJ3,BJ3*BK3) -> 0.18803265 | BP3: =1-BM3-BO3-BQ3 -> 0.2896608 | BQ3: =IF(VLOOKUP($R3,武学奇术!$A:$ZZ,22,FALSE)=1,0,(1-$BJ3))*(1-$BM3) -> 0.10280655 | BR3: {=SUM(_xlfn.XLOOKUP(S3:AG3,增益!$A:$A,增益!$W:$W,0))+$I$5} -> 0.06
A4: 裂石 | F4: 剑 | G4: =B15+B17 -> 0.1699 | H4: 属抗 | I4: =30 -> 30 | K4: =$L4*VLOOKUP($R4,武学奇术!$A:$ZZ,31,FALSE) -> 31729.418 | L4: =($M4*$BO4+$N4*$BM4+$O4*$BP4+$P4*$BQ4) -> 31729.418 | M4: =((($AO4+$AP4)/2*$AI4+$AJ4)*(1+$AQ4)*(1+$AR4)+(($AT4+$AU4)/2*IF($G$1="鸣金",$AK4,$AI4)+IF($G$1="鸣金",$AL4*1.5,0))*(1+$AV4)*(1+$AW4)+(($AX4+$AY4)/2*IF($G$1="裂石",$AK4,$AI4)+IF($G$1="裂石",$AL4*1.5,0))*(1+$AZ4)*(1+$BA4)+(($BB4+$BC4)/2*IF($G$1="牵丝",$AK4,$AI4)+IF($G$1="牵丝",$AL4*1.5,0))*(1+$BD4)*(1+$BE4)+(($BF4+$BG4)/2*IF($G$1="破竹",$AK4,$AI4)+IF($G$1="破竹",$AL4*1.5,0))*(1+$BH4)*(1+$BI4))*(1+$AM4)*$BL4*$Q4*(1+IF(VLOOKUP($R4,武学奇术!$A:$ZZ,30,FALSE)="流血",$B$21,0))*(1+$BR4) -> 31430.249 | N4: =(($AP4*$AI4+$AJ4)*(1+$AQ4)*(1+$AR4)+($AU4*IF($G$1="鸣金",$AK4,$AI4)+IF($G$1="鸣金",$AL4*1.5,0))*(1+$AV4)*(1+$AW4)+($AY4*IF($G$1="裂石",$AK4,$AI4)+IF($G$1="裂石",$AL4*1.5,0))*(1+$AZ4)*(1+$BA4)+($BC4*IF($G$1="牵丝",$AK4,$AI4)+IF($G$1="牵丝",$AL4*1.5,0))*(1+$BD4)*(1+$BE4)+($BG4*IF($G$1="破竹",$AK4,$AI4)+IF($G$1="破竹",$AL4*1.5,0))*(1+$BH4)*(1+$BI4))*(1+$AM4)*$BN4*$Q4*(1+IF(VLOOKUP($R4,武学奇术!$A:$ZZ,30,FALSE)="流血",$B$21,0))*(1+$BR4) -> 44474.818 | O4: =((($AO4+$AP4)/2*$AI4+$AJ4)*(1+$AQ4)*(1+$AR4)+(($AT4+$AU4)/2*IF($G$1="鸣金",$AK4,$AI4)+IF($G$1="鸣金",$AL4*1.5,0))*(1+$AV4)*(1+$AW4)+(($AX4+$AY4)/2*IF($G$1="裂石",$AK4,$AI4)+IF($G$1="裂石",$AL4*1.5,0))*(1+$AZ4)*(1+$BA4)+(($BB4+$BC4)/2*IF($G$1="牵丝",$AK4,$AI4)+IF($G$1="牵丝",$AL4*1.5,0))*(1+$BD4)*(1+$BE4)+(($BF4+$BG4)/2*IF($G$1="破竹",$AK4,$AI4)+IF($G$1="破竹",$AL4*1.5,0))*(1+$BH4)*(1+$BI4))*(1+$AM4)*$Q4*(1+IF(VLOOKUP($R4,武学奇术!$A:$ZZ,30,FALSE)="流血",$B$21,0))*(1+$BR4) -> 20953.499 | P4: =((($AO4*$AI4+$AJ4)*(1+$AQ4)*(1+$AR4)+($AT4*IF($G$1="鸣金",$AK4,$AI4)+IF($G$1="鸣金",$AL4*1.5,0))*(1+$AV4)*(1+$AW4)+($AX4*IF($G$1="裂石",$AK4,$AI4)+IF($G$1="裂石",$AL4*1.5,0))*(1+$AZ4)*(1+$BA4)+($BB4*IF($G$1="牵丝",$AK4,$AI4)+IF($G$1="牵丝",$AL4*1.5,0))*(1+$BD4)*(1+$BE4)+($BF4*IF($G$1="破竹",$AK4,$AI4)+IF($G$1="破竹",$AL4*1.5,0))*(1+$BH4)*(1+$BI4))*(1+$AM4))*$Q4*(1+IF(VLOOKUP($R4,武学奇术!$A:$ZZ,30,FALSE)="流血",$B$21,0))*(1+$BR4) -> 10630.756 | Q4: 1 | R4: 剑～ | S4: 强效江流 | T4: N/a | U4: N/a | V4: N/a | W4: N/a | X4: 易水歌2层 | Y4: N/a | Z4: N/a | AA4: 惧刃(拐) | AB4: 裁云(拐) | AC4: 烁鼓(拐) | AD4: 离猎(拐) | AE4: 伞增(拐) | AF4: 近战笛 | AG4: 秋瞑帖2层 | AH4: =VLOOKUP($R4,武学奇术!$A:$ZZ,25,FALSE) -> 剑 | AI4: =VLOOKUP($R4,武学奇术!$A:$ZZ,26,FALSE) -> 1.1781 | AJ4: =VLOOKUP($R4,武学奇术!$A:$ZZ,27,FALSE)*(1+IF(OR($AH4=$F$4,$AH4=$F$5),$B$22,0)) -> 489 | AK4: =VLOOKUP($R4,武学奇术!$A:$ZZ,28,FALSE) -> 1.7672 | AL4: =VLOOKUP($R4,武学奇术!$A:$ZZ,29,FALSE)*(1+IF(OR($AH4=$F$4,$AH4=$F$5),$B$22,0)) -> 265.5 | AM4: {=$G$3+IFERROR(VLOOKUP($AH4,$F$4:$G$7,2,FALSE),0)+VLOOKUP($R4,武学奇术!$A:$ZZ,2,FALSE)+SUM(_xlfn.XLOOKUP($S4:$AG4,增益!$A:$A,增益!$B:$B,0))} -> 0.9341 | AN4: {=VLOOKUP($R4,武学奇术!$A:$ZZ,5,FALSE)+SUM(_xlfn.XLOOKUP($S4:$AG4,增益!$A:$A,增益!$E:$E,0))} -> 0 | AO4: {=$D$10*(1+$AN4)+VLOOKUP($R4,武学奇术!$A:$ZZ,3,FALSE)+SUM(_xlfn.XLOOKUP($S4:$AG4,增益!$A:$A,增益!$C:$C,0))-$I$2} -> 1831.48 | AP4: {=$E$10*(1+$AN4)+VLOOKUP($R4,武学奇术!$A:$ZZ,4,FALSE)+SUM(_xlfn.XLOOKUP($S4:$AG4,增益!$A:$A,增益!$D:$D,0))-$I$2} -> 7763.56 | AQ4: {=IF($F$10-$I$3+VLOOKUP($R4,武学奇术!$A:$ZZ,6,FALSE)+SUM(_xlfn.XLOOKUP(S4:AG4,增益!$A:$A,增益!$F:$F,0))>0,($F$10-$I$3+VLOOKUP($R4,武学奇术!$A:$ZZ,6,FALSE)+SUM(_xlfn.XLOOKUP(S4:AG4,增益!$A:$A,增益!$F:$F,0)))/200,($F$10-$I$3+VLOOKUP($R4,武学奇术!$A:$ZZ,6,FALSE)+SUM(_xlfn.XLOOKUP(S4:AG4,增益!$A:$A,增益!$F:$F,0)))/100)} -> 0.264 | AR4: {=$G$10+VLOOKUP($R4,武学奇术!$A:$ZZ,7,FALSE)+SUM(_xlfn.XLOOKUP(S4:AG4,增益!$A:$A,增益!$G:$G,0))} -> 0 | AS4: {=VLOOKUP($R4,武学奇术!$A:$ZZ,8,FALSE)+SUM(_xlfn.XLOOKUP(S4:AG4,增益!$A:$A,增益!$H:$H,0))} -> 0 | AT4: =$D$11*(1+$AS4) -> 680.02 | AU4: =$E$11*(1+$AS4) -> 1288.54 | AV4: {=IF($F$11-$I$4+VLOOKUP($R4,武学奇术!$A:$ZZ,9,FALSE)+SUM(_xlfn.XLOOKUP(S4:AG4,增益!$A:$A,增益!$I:$I,0))>0,($F$11-$I$4+VLOOKUP($R4,武学奇术!$A:$ZZ,9,FALSE)+SUM(_xlfn.XLOOKUP(S4:AG4,增益!$A:$A,增益!$I:$I,0)))/200,($F$11-$I$4+VLOOKUP($R4,武学奇术!$A:$ZZ,9,FALSE)+SUM(_xlfn.XLOOKUP(S4:AG4,增益!$A:$A,增益!$I:$I,0)))/100)} -> 0 | AW4: {=$G$11+VLOOKUP($R4,武学奇术!$A:$ZZ,10,FALSE)+SUM(_xlfn.XLOOKUP(S4:AG4,增益!$A:$A,增益!$J:$J,0))} -> 0.15 | AX4: =$D$12*(1+$AS4) -> 0 | AY4: =$E$12*(1+$AS4) -> 0 | AZ4: {=IF($F$12-$I$4+VLOOKUP($R4,武学奇术!$A:$ZZ,11,FALSE)+SUM(_xlfn.XLOOKUP(S4:AG4,增益!$A:$A,增益!$K:$K,0))>0,($F$12-$I$4+VLOOKUP($R4,武学奇术!$A:$ZZ,11,FALSE)+SUM(_xlfn.XLOOKUP(S4:AG4,增益!$A:$A,增益!$K:$K,0)))/200,($F$12-$I$4+VLOOKUP($R4,武学奇术!$A:$ZZ,11,FALSE)+SUM(_xlfn.XLOOKUP(S4:AG4,增益!$A:$A,增益!$K:$K,0)))/100)} -> -0.3 | BA4: {=$G$12+VLOOKUP($R4,武学奇术!$A:$ZZ,12,FALSE)+SUM(_xlfn.XLOOKUP(S4:AG4,增益!$A:$A,增益!$L:$L,0))} -> 0 | BB4: =$D$13*(1+$AS4) -> 0 | BC4: =$E$13*(1+$AS4) -> 0 | BD4: {=IF($F$13-$I$4+VLOOKUP($R4,武学奇术!$A:$ZZ,13,FALSE)+SUM(_xlfn.XLOOKUP(S4:AG4,增益!$A:$A,增益!$M:$M,0))>0,($F$13-$I$4+VLOOKUP($R4,武学奇术!$A:$ZZ,13,FALSE)+SUM(_xlfn.XLOOKUP(S4:AG4,增益!$A:$A,增益!$K:$K,0)))/200,($F$13-$I$4+VLOOKUP($R4,武学奇术!$A:$ZZ,13,FALSE)+SUM(_xlfn.XLOOKUP(S4:AG4,增益!$A:$A,增益!$M:$M,0)))/100)} -> -0.3 | BE4: {=$G$13+VLOOKUP($R4,武学奇术!$A:$ZZ,14,FALSE)+SUM(_xlfn.XLOOKUP(S4:AG4,增益!$A:$A,增益!$N:$N,0))} -> 0 | BF4: =$D$14*(1+$AS4) -> 0 | BG4: =$E$14*(1+$AS4) -> 0 | BH4: {=IF($F$14-$I$4+VLOOKUP($R4,武学奇术!$A:$ZZ,15,FALSE)+SUM(_xlfn.XLOOKUP(S4:AG4,增益!$A:$A,增益!$O:$O,0))>0,($F$14-$I$4+VLOOKUP($R4,武学奇术!$A:$ZZ,15,FALSE)+SUM(_xlfn.XLOOKUP(S4:AG4,增益!$A:$A,增益!$O:$O,0)))/200,($F$14-$I$4+VLOOKUP($R4,武学奇术!$A:$ZZ,15,FALSE)+SUM(_xlfn.XLOOKUP(S4:AG4,增益!$A:$A,增益!$O:$O,0)))/100)} -> -0.3 | BI4: {=$G$14+VLOOKUP($R4,武学奇术!$A:$ZZ,16,FALSE)+SUM(_xlfn.XLOOKUP(S4:AG4,增益!$A:$A,增益!$P:$P,0))} -> 0 | BJ4: =MIN(IF(VLOOKUP($R4,武学奇术!$A:$ZZ,23,FALSE)=1,100%,$B$8),100%) -> 0.8229 | BK4: {=IF(VLOOKUP($R4,武学奇术!$A:$ZZ,23,FALSE)=1,100%,MIN(80%,$B$9+VLOOKUP($R4,武学奇术!$A:$ZZ,17,FALSE)+SUM(_xlfn.XLOOKUP(S4:AG4,增益!$A:$A,增益!$Q:$Q,0)))+$B$11+SUM(_xlfn.XLOOKUP(S4:AG4,增益!$A:$A,增益!$U:$U,0)))*IF(VLOOKUP($R4,武学奇术!$A:$ZZ,24,FALSE)=1,0,1)} -> 0.2285 | BL4: {=1+$B$13+VLOOKUP($R4,武学奇术!$A:$ZZ,18,FALSE)+SUM(_xlfn.XLOOKUP(S4:AG4,增益!$A:$A,增益!$R:$R,0))} -> 1.5 | BM4: {=IF(VLOOKUP($R4,武学奇术!$A:$ZZ,24,FALSE)=1,100%,MIN(40%,$B$10+VLOOKUP($R4,武学奇术!$A:$ZZ,19,FALSE)+SUM(_xlfn.XLOOKUP(S4:AG4,增益!$A:$A,增益!$S:$S,0)))+$B$12+SUM(_xlfn.XLOOKUP(S4:AG4,增益!$A:$A,增益!$V:$V,0)))*IF(VLOOKUP($R4,武学奇术!$A:$ZZ,23,FALSE)=1,0,1)} -> 0.4195 | BN4: {=1+$B$14+VLOOKUP($R4,武学奇术!$A:$ZZ,20,FALSE)+SUM(_xlfn.XLOOKUP(S4:AG4,增益!$A:$A,增益!$T:$T,0))} -> 1.422 | BO4: =MIN((1-BM4)*BJ4,BJ4*BK4) -> 0.18803265 | BP4: =1-BM4-BO4-BQ4 -> 0.2896608 | BQ4: =IF(VLOOKUP($R4,武学奇术!$A:$ZZ,22,FALSE)=1,0,(1-$BJ4))*(1-$BM4) -> 0.10280655 | BR4: {=SUM(_xlfn.XLOOKUP(S4:AG4,增益!$A:$A,增益!$W:$W,0))+$I$5} -> 0.06
A5: 牵丝 | F5: 枪 | G5: =B15+B18 -> 0.0847 | H5: 副本天赋 | I5: 0.06 | K5: =$L5*VLOOKUP($R5,武学奇术!$A:$ZZ,31,FALSE) -> 83685.736 | L5: =($M5*$BO5+$N5*$BM5+$O5*$BP5+$P5*$BQ5) -> 139476.23 | M5: =((($AO5+$AP5)/2*$AI5+$AJ5)*(1+$AQ5)*(1+$AR5)+(($AT5+$AU5)/2*IF($G$1="鸣金",$AK5,$AI5)+IF($G$1="鸣金",$AL5*1.5,0))*(1+$AV5)*(1+$AW5)+(($AX5+$AY5)/2*IF($G$1="裂石",$AK5,$AI5)+IF($G$1="裂石",$AL5*1.5,0))*(1+$AZ5)*(1+$BA5)+(($BB5+$BC5)/2*IF($G$1="牵丝",$AK5,$AI5)+IF($G$1="牵丝",$AL5*1.5,0))*(1+$BD5)*(1+$BE5)+(($BF5+$BG5)/2*IF($G$1="破竹",$AK5,$AI5)+IF($G$1="破竹",$AL5*1.5,0))*(1+$BH5)*(1+$BI5))*(1+$AM5)*$BL5*$Q5*(1+IF(VLOOKUP($R5,武学奇术!$A:$ZZ,30,FALSE)="流血",$B$21,0))*(1+$BR5) -> 117759.87 | N5: =(($AP5*$AI5+$AJ5)*(1+$AQ5)*(1+$AR5)+($AU5*IF($G$1="鸣金",$AK5,$AI5)+IF($G$1="鸣金",$AL5*1.5,0))*(1+$AV5)*(1+$AW5)+($AY5*IF($G$1="裂石",$AK5,$AI5)+IF($G$1="裂石",$AL5*1.5,0))*(1+$AZ5)*(1+$BA5)+($BC5*IF($G$1="牵丝",$AK5,$AI5)+IF($G$1="牵丝",$AL5*1.5,0))*(1+$BD5)*(1+$BE5)+($BG5*IF($G$1="破竹",$AK5,$AI5)+IF($G$1="破竹",$AL5*1.5,0))*(1+$BH5)*(1+$BI5))*(1+$AM5)*$BN5*$Q5*(1+IF(VLOOKUP($R5,武学奇术!$A:$ZZ,30,FALSE)="流血",$B$21,0))*(1+$BR5) -> 207087.69 | O5: =((($AO5+$AP5)/2*$AI5+$AJ5)*(1+$AQ5)*(1+$AR5)+(($AT5+$AU5)/2*IF($G$1="鸣金",$AK5,$AI5)+IF($G$1="鸣金",$AL5*1.5,0))*(1+$AV5)*(1+$AW5)+(($AX5+$AY5)/2*IF($G$1="裂石",$AK5,$AI5)+IF($G$1="裂石",$AL5*1.5,0))*(1+$AZ5)*(1+$BA5)+(($BB5+$BC5)/2*IF($G$1="牵丝",$AK5,$AI5)+IF($G$1="牵丝",$AL5*1.5,0))*(1+$BD5)*(1+$BE5)+(($BF5+$BG5)/2*IF($G$1="破竹",$AK5,$AI5)+IF($G$1="破竹",$AL5*1.5,0))*(1+$BH5)*(1+$BI5))*(1+$AM5)*$Q5*(1+IF(VLOOKUP($R5,武学奇术!$A:$ZZ,30,FALSE)="流血",$B$21,0))*(1+$BR5) -> 78506.581 | P5: =((($AO5*$AI5+$AJ5)*(1+$AQ5)*(1+$AR5)+($AT5*IF($G$1="鸣金",$AK5,$AI5)+IF($G$1="鸣金",$AL5*1.5,0))*(1+$AV5)*(1+$AW5)+($AX5*IF($G$1="裂石",$AK5,$AI5)+IF($G$1="裂石",$AL5*1.5,0))*(1+$AZ5)*(1+$BA5)+($BB5*IF($G$1="牵丝",$AK5,$AI5)+IF($G$1="牵丝",$AL5*1.5,0))*(1+$BD5)*(1+$BE5)+($BF5*IF($G$1="破竹",$AK5,$AI5)+IF($G$1="破竹",$AL5*1.5,0))*(1+$BH5)*(1+$BI5))*(1+$AM5))*$Q5*(1+IF(VLOOKUP($R5,武学奇术!$A:$ZZ,30,FALSE)="流血",$B$21,0))*(1+$BR5) -> 35340.022 | Q5: 1 | R5: 爆血(剑) | S5: 强效江流 | T5: 看破(持续) | U5: 惊神5 | V5: 纵横剑意 | W5: N/a | X5: 易水歌2层 | Y5: N/a | Z5: N/a | AA5: 惧刃(拐) | AB5: 裁云(拐) | AC5: 烁鼓(拐) | AD5: 离猎(拐) | AE5: 伞增(拐) | AF5: 近战笛 | AG5: 秋瞑帖2层 | AH5: =VLOOKUP($R5,武学奇术!$A:$ZZ,25,FALSE) -> 剑 | AI5: =VLOOKUP($R5,武学奇术!$A:$ZZ,26,FALSE) -> 2.52 | AJ5: =VLOOKUP($R5,武学奇术!$A:$ZZ,27,FALSE)*(1+IF(OR($AH5=$F$4,$AH5=$F$5),$B$22,0)) -> 0 | AK5: =VLOOKUP($R5,武学奇术!$A:$ZZ,28,FALSE) -> 3.78 | AL5: =VLOOKUP($R5,武学奇术!$A:$ZZ,29,FALSE)*(1+IF(OR($AH5=$F$4,$AH5=$F$5),$B$22,0)) -> 0 | AM5: {=$G$3+IFERROR(VLOOKUP($AH5,$F$4:$G$7,2,FALSE),0)+VLOOKUP($R5,武学奇术!$A:$ZZ,2,FALSE)+SUM(_xlfn.XLOOKUP($S5:$AG5,增益!$A:$A,增益!$B:$B,0))} -> 1.6991 | AN5: {=VLOOKUP($R5,武学奇术!$A:$ZZ,5,FALSE)+SUM(_xlfn.XLOOKUP($S5:$AG5,增益!$A:$A,增益!$E:$E,0))} -> 0 | AO5: {=$D$10*(1+$AN5)+VLOOKUP($R5,武学奇术!$A:$ZZ,3,FALSE)+SUM(_xlfn.XLOOKUP($S5:$AG5,增益!$A:$A,增益!$C:$C,0))-$I$2} -> 1831.48 | AP5: {=$E$10*(1+$AN5)+VLOOKUP($R5,武学奇术!$A:$ZZ,4,FALSE)+SUM(_xlfn.XLOOKUP($S5:$AG5,增益!$A:$A,增益!$D:$D,0))-$I$2} -> 7763.56 | AQ5: {=IF($F$10-$I$3+VLOOKUP($R5,武学奇术!$A:$ZZ,6,FALSE)+SUM(_xlfn.XLOOKUP(S5:AG5,增益!$A:$A,增益!$F:$F,0))>0,($F$10-$I$3+VLOOKUP($R5,武学奇术!$A:$ZZ,6,FALSE)+SUM(_xlfn.XLOOKUP(S5:AG5,增益!$A:$A,增益!$F:$F,0)))/200,($F$10-$I$3+VLOOKUP($R5,武学奇术!$A:$ZZ,6,FALSE)+SUM(_xlfn.XLOOKUP(S5:AG5,增益!$A:$A,增益!$F:$F,0)))/100)} -> 0.339 | AR5: {=$G$10+VLOOKUP($R5,武学奇术!$A:$ZZ,7,FALSE)+SUM(_xlfn.XLOOKUP(S5:AG5,增益!$A:$A,增益!$G:$G,0))} -> 0 | AS5: {=VLOOKUP($R5,武学奇术!$A:$ZZ,8,FALSE)+SUM(_xlfn.XLOOKUP(S5:AG5,增益!$A:$A,增益!$H:$H,0))} -> 0 | AT5: =$D$11*(1+$AS5) -> 680.02 | AU5: =$E$11*(1+$AS5) -> 1288.54 | AV5: {=IF($F$11-$I$4+VLOOKUP($R5,武学奇术!$A:$ZZ,9,FALSE)+SUM(_xlfn.XLOOKUP(S5:AG5,增益!$A:$A,增益!$I:$I,0))>0,($F$11-$I$4+VLOOKUP($R5,武学奇术!$A:$ZZ,9,FALSE)+SUM(_xlfn.XLOOKUP(S5:AG5,增益!$A:$A,增益!$I:$I,0)))/200,($F$11-$I$4+VLOOKUP($R5,武学奇术!$A:$ZZ,9,FALSE)+SUM(_xlfn.XLOOKUP(S5:AG5,增益!$A:$A,增益!$I:$I,0)))/100)} -> 0.075 | AW5: {=$G$11+VLOOKUP($R5,武学奇术!$A:$ZZ,10,FALSE)+SUM(_xlfn.XLOOKUP(S5:AG5,增益!$A:$A,增益!$J:$J,0))} -> 0.15 | AX5: =$D$12*(1+$AS5) -> 0 | AY5: =$E$12*(1+$AS5) -> 0 | AZ5: {=IF($F$12-$I$4+VLOOKUP($R5,武学奇术!$A:$ZZ,11,FALSE)+SUM(_xlfn.XLOOKUP(S5:AG5,增益!$A:$A,增益!$K:$K,0))>0,($F$12-$I$4+VLOOKUP($R5,武学奇术!$A:$ZZ,11,FALSE)+SUM(_xlfn.XLOOKUP(S5:AG5,增益!$A:$A,增益!$K:$K,0)))/200,($F$12-$I$4+VLOOKUP($R5,武学奇术!$A:$ZZ,11,FALSE)+SUM(_xlfn.XLOOKUP(S5:AG5,增益!$A:$A,增益!$K:$K,0)))/100)} -> -0.3 | BA5: {=$G$12+VLOOKUP($R5,武学奇术!$A:$ZZ,12,FALSE)+SUM(_xlfn.XLOOKUP(S5:AG5,增益!$A:$A,增益!$L:$L,0))} -> 0 | BB5: =$D$13*(1+$AS5) -> 0 | BC5: =$E$13*(1+$AS5) -> 0 | BD5: {=IF($F$13-$I$4+VLOOKUP($R5,武学奇术!$A:$ZZ,13,FALSE)+SUM(_xlfn.XLOOKUP(S5:AG5,增益!$A:$A,增益!$M:$M,0))>0,($F$13-$I$4+VLOOKUP($R5,武学奇术!$A:$ZZ,13,FALSE)+SUM(_xlfn.XLOOKUP(S5:AG5,增益!$A:$A,增益!$K:$K,0)))/200,($F$13-$I$4+VLOOKUP($R5,武学奇术!$A:$ZZ,13,FALSE)+SUM(_xlfn.XLOOKUP(S5:AG5,增益!$A:$A,增益!$M:$M,0)))/100)} -> -0.3 | BE5: {=$G$13+VLOOKUP($R5,武学奇术!$A:$ZZ,14,FALSE)+SUM(_xlfn.XLOOKUP(S5:AG5,增益!$A:$A,增益!$N:$N,0))} -> 0 | BF5: =$D$14*(1+$AS5) -> 0 | BG5: =$E$14*(1+$AS5) -> 0 | BH5: {=IF($F$14-$I$4+VLOOKUP($R5,武学奇术!$A:$ZZ,15,FALSE)+SUM(_xlfn.XLOOKUP(S5:AG5,增益!$A:$A,增益!$O:$O,0))>0,($F$14-$I$4+VLOOKUP($R5,武学奇术!$A:$ZZ,15,FALSE)+SUM(_xlfn.XLOOKUP(S5:AG5,增益!$A:$A,增益!$O:$O,0)))/200,($F$14-$I$4+VLOOKUP($R5,武学奇术!$A:$ZZ,15,FALSE)+SUM(_xlfn.XLOOKUP(S5:AG5,增益!$A:$A,增益!$O:$O,0)))/100)} -> -0.3 | BI5: {=$G$14+VLOOKUP($R5,武学奇术!$A:$ZZ,16,FALSE)+SUM(_xlfn.XLOOKUP(S5:AG5,增益!$A:$A,增益!$P:$P,0))} -> 0 | BJ5: =MIN(IF(VLOOKUP($R5,武学奇术!$A:$ZZ,23,FALSE)=1,100%,$B$8),100%) -> 0.8229 | BK5: {=IF(VLOOKUP($R5,武学奇术!$A:$ZZ,23,FALSE)=1,100%,MIN(80%,$B$9+VLOOKUP($R5,武学奇术!$A:$ZZ,17,FALSE)+SUM(_xlfn.XLOOKUP(S5:AG5,增益!$A:$A,增益!$Q:$Q,0)))+$B$11+SUM(_xlfn.XLOOKUP(S5:AG5,增益!$A:$A,增益!$U:$U,0)))*IF(VLOOKUP($R5,武学奇术!$A:$ZZ,24,FALSE)=1,0,1)} -> 0.2285 | BL5: {=1+$B$13+VLOOKUP($R5,武学奇术!$A:$ZZ,18,FALSE)+SUM(_xlfn.XLOOKUP(S5:AG5,增益!$A:$A,增益!$R:$R,0))} -> 1.5 | BM5: {=IF(VLOOKUP($R5,武学奇术!$A:$ZZ,24,FALSE)=1,100%,MIN(40%,$B$10+VLOOKUP($R5,武学奇术!$A:$ZZ,19,FALSE)+SUM(_xlfn.XLOOKUP(S5:AG5,增益!$A:$A,增益!$S:$S,0)))+$B$12+SUM(_xlfn.XLOOKUP(S5:AG5,增益!$A:$A,增益!$V:$V,0)))*IF(VLOOKUP($R5,武学奇术!$A:$ZZ,23,FALSE)=1,0,1)} -> 0.4495 | BN5: {=1+$B$14+VLOOKUP($R5,武学奇术!$A:$ZZ,20,FALSE)+SUM(_xlfn.XLOOKUP(S5:AG5,增益!$A:$A,增益!$T:$T,0))} -> 1.702 | BO5: =MIN((1-BM5)*BJ5,BJ5*BK5) -> 0.18803265 | BP5: =1-BM5-BO5-BQ5 -> 0.2649738 | BQ5: =IF(VLOOKUP($R5,武学奇术!$A:$ZZ,22,FALSE)=1,0,(1-$BJ5))*(1-$BM5) -> 0.09749355 | BR5: {=SUM(_xlfn.XLOOKUP(S5:AG5,增益!$A:$A,增益!$W:$W,0))+$I$5} -> 0.06
A6: 破竹 | F6: 单体奇术 | G6: =B19 -> 0.1338 | K6: =$L6*VLOOKUP($R6,武学奇术!$A:$ZZ,31,FALSE) -> 83685.736 | L6: =($M6*$BO6+$N6*$BM6+$O6*$BP6+$P6*$BQ6) -> 139476.23 | M6: =((($AO6+$AP6)/2*$AI6+$AJ6)*(1+$AQ6)*(1+$AR6)+(($AT6+$AU6)/2*IF($G$1="鸣金",$AK6,$AI6)+IF($G$1="鸣金",$AL6*1.5,0))*(1+$AV6)*(1+$AW6)+(($AX6+$AY6)/2*IF($G$1="裂石",$AK6,$AI6)+IF($G$1="裂石",$AL6*1.5,0))*(1+$AZ6)*(1+$BA6)+(($BB6+$BC6)/2*IF($G$1="牵丝",$AK6,$AI6)+IF($G$1="牵丝",$AL6*1.5,0))*(1+$BD6)*(1+$BE6)+(($BF6+$BG6)/2*IF($G$1="破竹",$AK6,$AI6)+IF($G$1="破竹",$AL6*1.5,0))*(1+$BH6)*(1+$BI6))*(1+$AM6)*$BL6*$Q6*(1+IF(VLOOKUP($R6,武学奇术!$A:$ZZ,30,FALSE)="流血",$B$21,0))*(1+$BR6) -> 117759.87 | N6: =(($AP6*$AI6+$AJ6)*(1+$AQ6)*(1+$AR6)+($AU6*IF($G$1="鸣金",$AK6,$AI6)+IF($G$1="鸣金",$AL6*1.5,0))*(1+$AV6)*(1+$AW6)+($AY6*IF($G$1="裂石",$AK6,$AI6)+IF($G$1="裂石",$AL6*1.5,0))*(1+$AZ6)*(1+$BA6)+($BC6*IF($G$1="牵丝",$AK6,$AI6)+IF($G$1="牵丝",$AL6*1.5,0))*(1+$BD6)*(1+$BE6)+($BG6*IF($G$1="破竹",$AK6,$AI6)+IF($G$1="破竹",$AL6*1.5,0))*(1+$BH6)*(1+$BI6))*(1+$AM6)*$BN6*$Q6*(1+IF(VLOOKUP($R6,武学奇术!$A:$ZZ,30,FALSE)="流血",$B$21,0))*(1+$BR6) -> 207087.69 | O6: =((($AO6+$AP6)/2*$AI6+$AJ6)*(1+$AQ6)*(1+$AR6)+(($AT6+$AU6)/2*IF($G$1="鸣金",$AK6,$AI6)+IF($G$1="鸣金",$AL6*1.5,0))*(1+$AV6)*(1+$AW6)+(($AX6+$AY6)/2*IF($G$1="裂石",$AK6,$AI6)+IF($G$1="裂石",$AL6*1.5,0))*(1+$AZ6)*(1+$BA6)+(($BB6+$BC6)/2*IF($G$1="牵丝",$AK6,$AI6)+IF($G$1="牵丝",$AL6*1.5,0))*(1+$BD6)*(1+$BE6)+(($BF6+$BG6)/2*IF($G$1="破竹",$AK6,$AI6)+IF($G$1="破竹",$AL6*1.5,0))*(1+$BH6)*(1+$BI6))*(1+$AM6)*$Q6*(1+IF(VLOOKUP($R6,武学奇术!$A:$ZZ,30,FALSE)="流血",$B$21,0))*(1+$BR6) -> 78506.581 | P6: =((($AO6*$AI6+$AJ6)*(1+$AQ6)*(1+$AR6)+($AT6*IF($G$1="鸣金",$AK6,$AI6)+IF($G$1="鸣金",$AL6*1.5,0))*(1+$AV6)*(1+$AW6)+($AX6*IF($G$1="裂石",$AK6,$AI6)+IF($G$1="裂石",$AL6*1.5,0))*(1+$AZ6)*(1+$BA6)+($BB6*IF($G$1="牵丝",$AK6,$AI6)+IF($G$1="牵丝",$AL6*1.5,0))*(1+$BD6)*(1+$BE6)+($BF6*IF($G$1="破竹",$AK6,$AI6)+IF($G$1="破竹",$AL6*1.5,0))*(1+$BH6)*(1+$BI6))*(1+$AM6))*$Q6*(1+IF(VLOOKUP($R6,武学奇术!$A:$ZZ,30,FALSE)="流血",$B$21,0))*(1+$BR6) -> 35340.022 | Q6: 1 | R6: 爆血(剑) | S6: 强效江流 | T6: 看破(持续) | U6: 惊神5 | V6: 纵横剑意 | W6: N/a | X6: 易水歌2层 | Y6: N/a | Z6: N/a | AA6: 惧刃(拐) | AB6: 裁云(拐) | AC6: 烁鼓(拐) | AD6: 离猎(拐) | AE6: 伞增(拐) | AF6: 近战笛 | AG6: 秋瞑帖2层 | AH6: =VLOOKUP($R6,武学奇术!$A:$ZZ,25,FALSE) -> 剑 | AI6: =VLOOKUP($R6,武学奇术!$A:$ZZ,26,FALSE) -> 2.52 | AJ6: =VLOOKUP($R6,武学奇术!$A:$ZZ,27,FALSE)*(1+IF(OR($AH6=$F$4,$AH6=$F$5),$B$22,0)) -> 0 | AK6: =VLOOKUP($R6,武学奇术!$A:$ZZ,28,FALSE) -> 3.78 | AL6: =VLOOKUP($R6,武学奇术!$A:$ZZ,29,FALSE)*(1+IF(OR($AH6=$F$4,$AH6=$F$5),$B$22,0)) -> 0 | AM6: {=$G$3+IFERROR(VLOOKUP($AH6,$F$4:$G$7,2,FALSE),0)+VLOOKUP($R6,武学奇术!$A:$ZZ,2,FALSE)+SUM(_xlfn.XLOOKUP($S6:$AG6,增益!$A:$A,增益!$B:$B,0))} -> 1.6991 | AN6: {=VLOOKUP($R6,武学奇术!$A:$ZZ,5,FALSE)+SUM(_xlfn.XLOOKUP($S6:$AG6,增益!$A:$A,增益!$E:$E,0))} -> 0 | AO6: {=$D$10*(1+$AN6)+VLOOKUP($R6,武学奇术!$A:$ZZ,3,FALSE)+SUM(_xlfn.XLOOKUP($S6:$AG6,增益!$A:$A,增益!$C:$C,0))-$I$2} -> 1831.48 | AP6: {=$E$10*(1+$AN6)+VLOOKUP($R6,武学奇术!$A:$ZZ,4,FALSE)+SUM(_xlfn.XLOOKUP($S6:$AG6,增益!$A:$A,增益!$D:$D,0))-$I$2} -> 7763.56 | AQ6: {=IF($F$10-$I$3+VLOOKUP($R6,武学奇术!$A:$ZZ,6,FALSE)+SUM(_xlfn.XLOOKUP(S6:AG6,增益!$A:$A,增益!$F:$F,0))>0,($F$10-$I$3+VLOOKUP($R6,武学奇术!$A:$ZZ,6,FALSE)+SUM(_xlfn.XLOOKUP(S6:AG6,增益!$A:$A,增益!$F:$F,0)))/200,($F$10-$I$3+VLOOKUP($R6,武学奇术!$A:$ZZ,6,FALSE)+SUM(_xlfn.XLOOKUP(S6:AG6,增益!$A:$A,增益!$F:$F,0)))/100)} -> 0.339 | AR6: {=$G$10+VLOOKUP($R6,武学奇术!$A:$ZZ,7,FALSE)+SUM(_xlfn.XLOOKUP(S6:AG6,增益!$A:$A,增益!$G:$G,0))} -> 0 | AS6: {=VLOOKUP($R6,武学奇术!$A:$ZZ,8,FALSE)+SUM(_xlfn.XLOOKUP(S6:AG6,增益!$A:$A,增益!$H:$H,0))} -> 0 | AT6: =$D$11*(1+$AS6) -> 680.02 | AU6: =$E$11*(1+$AS6) -> 1288.54 | AV6: {=IF($F$11-$I$4+VLOOKUP($R6,武学奇术!$A:$ZZ,9,FALSE)+SUM(_xlfn.XLOOKUP(S6:AG6,增益!$A:$A,增益!$I:$I,0))>0,($F$11-$I$4+VLOOKUP($R6,武学奇术!$A:$ZZ,9,FALSE)+SUM(_xlfn.XLOOKUP(S6:AG6,增益!$A:$A,增益!$I:$I,0)))/200,($F$11-$I$4+VLOOKUP($R6,武学奇术!$A:$ZZ,9,FALSE)+SUM(_xlfn.XLOOKUP(S6:AG6,增益!$A:$A,增益!$I:$I,0)))/100)} -> 0.075 | AW6: {=$G$11+VLOOKUP($R6,武学奇术!$A:$ZZ,10,FALSE)+SUM(_xlfn.XLOOKUP(S6:AG6,增益!$A:$A,增益!$J:$J,0))} -> 0.15 | AX6: =$D$12*(1+$AS6) -> 0 | AY6: =$E$12*(1+$AS6) -> 0 | AZ6: {=IF($F$12-$I$4+VLOOKUP($R6,武学奇术!$A:$ZZ,11,FALSE)+SUM(_xlfn.XLOOKUP(S6:AG6,增益!$A:$A,增益!$K:$K,0))>0,($F$12-$I$4+VLOOKUP($R6,武学奇术!$A:$ZZ,11,FALSE)+SUM(_xlfn.XLOOKUP(S6:AG6,增益!$A:$A,增益!$K:$K,0)))/200,($F$12-$I$4+VLOOKUP($R6,武学奇术!$A:$ZZ,11,FALSE)+SUM(_xlfn.XLOOKUP(S6:AG6,增益!$A:$A,增益!$K:$K,0)))/100)} -> -0.3 | BA6: {=$G$12+VLOOKUP($R6,武学奇术!$A:$ZZ,12,FALSE)+SUM(_xlfn.XLOOKUP(S6:AG6,增益!$A:$A,增益!$L:$L,0))} -> 0 | BB6: =$D$13*(1+$AS6) -> 0 | BC6: =$E$13*(1+$AS6) -> 0 | BD6: {=IF($F$13-$I$4+VLOOKUP($R6,武学奇术!$A:$ZZ,13,FALSE)+SUM(_xlfn.XLOOKUP(S6:AG6,增益!$A:$A,增益!$M:$M,0))>0,($F$13-$I$4+VLOOKUP($R6,武学奇术!$A:$ZZ,13,FALSE)+SUM(_xlfn.XLOOKUP(S6:AG6,增益!$A:$A,增益!$K:$K,0)))/200,($F$13-$I$4+VLOOKUP($R6,武学奇术!$A:$ZZ,13,FALSE)+SUM(_xlfn.XLOOKUP(S6:AG6,增益!$A:$A,增益!$M:$M,0)))/100)} -> -0.3 | BE6: {=$G$13+VLOOKUP($R6,武学奇术!$A:$ZZ,14,FALSE)+SUM(_xlfn.XLOOKUP(S6:AG6,增益!$A:$A,增益!$N:$N,0))} -> 0 | BF6: =$D$14*(1+$AS6) -> 0 | BG6: =$E$14*(1+$AS6) -> 0 | BH6: {=IF($F$14-$I$4+VLOOKUP($R6,武学奇术!$A:$ZZ,15,FALSE)+SUM(_xlfn.XLOOKUP(S6:AG6,增益!$A:$A,增益!$O:$O,0))>0,($F$14-$I$4+VLOOKUP($R6,武学奇术!$A:$ZZ,15,FALSE)+SUM(_xlfn.XLOOKUP(S6:AG6,增益!$A:$A,增益!$O:$O,0)))/200,($F$14-$I$4+VLOOKUP($R6,武学奇术!$A:$ZZ,15,FALSE)+SUM(_xlfn.XLOOKUP(S6:AG6,增益!$A:$A,增益!$O:$O,0)))/100)} -> -0.3 | BI6: {=$G$14+VLOOKUP($R6,武学奇术!$A:$ZZ,16,FALSE)+SUM(_xlfn.XLOOKUP(S6:AG6,增益!$A:$A,增益!$P:$P,0))} -> 0 | BJ6: =MIN(IF(VLOOKUP($R6,武学奇术!$A:$ZZ,23,FALSE)=1,100%,$B$8),100%) -> 0.8229 | BK6: {=IF(VLOOKUP($R6,武学奇术!$A:$ZZ,23,FALSE)=1,100%,MIN(80%,$B$9+VLOOKUP($R6,武学奇术!$A:$ZZ,17,FALSE)+SUM(_xlfn.XLOOKUP(S6:AG6,增益!$A:$A,增益!$Q:$Q,0)))+$B$11+SUM(_xlfn.XLOOKUP(S6:AG6,增益!$A:$A,增益!$U:$U,0)))*IF(VLOOKUP($R6,武学奇术!$A:$ZZ,24,FALSE)=1,0,1)} -> 0.2285 | BL6: {=1+$B$13+VLOOKUP($R6,武学奇术!$A:$ZZ,18,FALSE)+SUM(_xlfn.XLOOKUP(S6:AG6,增益!$A:$A,增益!$R:$R,0))} -> 1.5 | BM6: {=IF(VLOOKUP($R6,武学奇术!$A:$ZZ,24,FALSE)=1,100%,MIN(40%,$B$10+VLOOKUP($R6,武学奇术!$A:$ZZ,19,FALSE)+SUM(_xlfn.XLOOKUP(S6:AG6,增益!$A:$A,增益!$S:$S,0)))+$B$12+SUM(_xlfn.XLOOKUP(S6:AG6,增益!$A:$A,增益!$V:$V,0)))*IF(VLOOKUP($R6,武学奇术!$A:$ZZ,23,FALSE)=1,0,1)} -> 0.4495 | BN6: {=1+$B$14+VLOOKUP($R6,武学奇术!$A:$ZZ,20,FALSE)+SUM(_xlfn.XLOOKUP(S6:AG6,增益!$A:$A,增益!$T:$T,0))} -> 1.702 | BO6: =MIN((1-BM6)*BJ6,BJ6*BK6) -> 0.18803265 | BP6: =1-BM6-BO6-BQ6 -> 0.2649738 | BQ6: =IF(VLOOKUP($R6,武学奇术!$A:$ZZ,22,FALSE)=1,0,(1-$BJ6))*(1-$BM6) -> 0.09749355 | BR6: {=SUM(_xlfn.XLOOKUP(S6:AG6,增益!$A:$A,增益!$W:$W,0))+$I$5} -> 0.06
A7: 无相 | B7: 79.2 | C7: 92.4 | F7: 群体奇术 | G7: =B20 -> 0 | K7: =$L7*VLOOKUP($R7,武学奇术!$A:$ZZ,31,FALSE) -> 16554.492 | L7: =($M7*$BO7+$N7*$BM7+$O7*$BP7+$P7*$BQ7) -> 16554.492 | M7: =((($AO7+$AP7)/2*$AI7+$AJ7)*(1+$AQ7)*(1+$AR7)+(($AT7+$AU7)/2*IF($G$1="鸣金",$AK7,$AI7)+IF($G$1="鸣金",$AL7*1.5,0))*(1+$AV7)*(1+$AW7)+(($AX7+$AY7)/2*IF($G$1="裂石",$AK7,$AI7)+IF($G$1="裂石",$AL7*1.5,0))*(1+$AZ7)*(1+$BA7)+(($BB7+$BC7)/2*IF($G$1="牵丝",$AK7,$AI7)+IF($G$1="牵丝",$AL7*1.5,0))*(1+$BD7)*(1+$BE7)+(($BF7+$BG7)/2*IF($G$1="破竹",$AK7,$AI7)+IF($G$1="破竹",$AL7*1.5,0))*(1+$BH7)*(1+$BI7))*(1+$AM7)*$BL7*$Q7*(1+IF(VLOOKUP($R7,武学奇术!$A:$ZZ,30,FALSE)="流血",$B$21,0))*(1+$BR7) -> 15034.258 | N7: =(($AP7*$AI7+$AJ7)*(1+$AQ7)*(1+$AR7)+($AU7*IF($G$1="鸣金",$AK7,$AI7)+IF($G$1="鸣金",$AL7*1.5,0))*(1+$AV7)*(1+$AW7)+($AY7*IF($G$1="裂石",$AK7,$AI7)+IF($G$1="裂石",$AL7*1.5,0))*(1+$AZ7)*(1+$BA7)+($BC7*IF($G$1="牵丝",$AK7,$AI7)+IF($G$1="牵丝",$AL7*1.5,0))*(1+$BD7)*(1+$BE7)+($BG7*IF($G$1="破竹",$AK7,$AI7)+IF($G$1="破竹",$AL7*1.5,0))*(1+$BH7)*(1+$BI7))*(1+$AM7)*$BN7*$Q7*(1+IF(VLOOKUP($R7,武学奇术!$A:$ZZ,30,FALSE)="流血",$B$21,0))*(1+$BR7) -> 23654.414 | O7: =((($AO7+$AP7)/2*$AI7+$AJ7)*(1+$AQ7)*(1+$AR7)+(($AT7+$AU7)/2*IF($G$1="鸣金",$AK7,$AI7)+IF($G$1="鸣金",$AL7*1.5,0))*(1+$AV7)*(1+$AW7)+(($AX7+$AY7)/2*IF($G$1="裂石",$AK7,$AI7)+IF($G$1="裂石",$AL7*1.5,0))*(1+$AZ7)*(1+$BA7)+(($BB7+$BC7)/2*IF($G$1="牵丝",$AK7,$AI7)+IF($G$1="牵丝",$AL7*1.5,0))*(1+$BD7)*(1+$BE7)+(($BF7+$BG7)/2*IF($G$1="破竹",$AK7,$AI7)+IF($G$1="破竹",$AL7*1.5,0))*(1+$BH7)*(1+$BI7))*(1+$AM7)*$Q7*(1+IF(VLOOKUP($R7,武学奇术!$A:$ZZ,30,FALSE)="流血",$B$21,0))*(1+$BR7) -> 10022.839 | P7: =((($AO7*$AI7+$AJ7)*(1+$AQ7)*(1+$AR7)+($AT7*IF($G$1="鸣金",$AK7,$AI7)+IF($G$1="鸣金",$AL7*1.5,0))*(1+$AV7)*(1+$AW7)+($AX7*IF($G$1="裂石",$AK7,$AI7)+IF($G$1="裂石",$AL7*1.5,0))*(1+$AZ7)*(1+$BA7)+($BB7*IF($G$1="牵丝",$AK7,$AI7)+IF($G$1="牵丝",$AL7*1.5,0))*(1+$BD7)*(1+$BE7)+($BF7*IF($G$1="破竹",$AK7,$AI7)+IF($G$1="破竹",$AL7*1.5,0))*(1+$BH7)*(1+$BI7))*(1+$AM7))*$Q7*(1+IF(VLOOKUP($R7,武学奇术!$A:$ZZ,30,FALSE)="流血",$B$21,0))*(1+$BR7) -> 4504.0128 | Q7: 1 | R7: 纵横剑(剑～) | S7: 强效江流 | T7: 看破 | U7: N/a | V7: N/a | W7: N/a | X7: 易水歌2层 | Y7: N/a | Z7: N/a | AA7: 惧刃(拐) | AB7: 裁云(拐) | AC7: 烁鼓(拐) | AD7: 离猎(拐) | AE7: 伞增(拐) | AF7: 近战笛 | AG7: 秋瞑帖2层 | AH7: =VLOOKUP($R7,武学奇术!$A:$ZZ,25,FALSE) -> 剑 | AI7: =VLOOKUP($R7,武学奇术!$A:$ZZ,26,FALSE) -> 0.625 | AJ7: =VLOOKUP($R7,武学奇术!$A:$ZZ,27,FALSE)*(1+IF(OR($AH7=$F$4,$AH7=$F$5),$B$22,0)) -> 0 | AK7: =VLOOKUP($R7,武学奇术!$A:$ZZ,28,FALSE) -> 0.9375 | AL7: =VLOOKUP($R7,武学奇术!$A:$ZZ,29,FALSE)*(1+IF(OR($AH7=$F$4,$AH7=$F$5),$B$22,0)) -> 0 | AM7: {=$G$3+IFERROR(VLOOKUP($AH7,$F$4:$G$7,2,FALSE),0)+VLOOKUP($R7,武学奇术!$A:$ZZ,2,FALSE)+SUM(_xlfn.XLOOKUP($S7:$AG7,增益!$A:$A,增益!$B:$B,0))} -> 0.9491 | AN7: {=VLOOKUP($R7,武学奇术!$A:$ZZ,5,FALSE)+SUM(_xlfn.XLOOKUP($S7:$AG7,增益!$A:$A,增益!$E:$E,0))} -> 0 | AO7: {=$D$10*(1+$AN7)+VLOOKUP($R7,武学奇术!$A:$ZZ,3,FALSE)+SUM(_xlfn.XLOOKUP($S7:$AG7,增益!$A:$A,增益!$C:$C,0))-$I$2} -> 1831.48 | AP7: {=$E$10*(1+$AN7)+VLOOKUP($R7,武学奇术!$A:$ZZ,4,FALSE)+SUM(_xlfn.XLOOKUP($S7:$AG7,增益!$A:$A,增益!$D:$D,0))-$I$2} -> 7763.56 | AQ7: {=IF($F$10-$I$3+VLOOKUP($R7,武学奇术!$A:$ZZ,6,FALSE)+SUM(_xlfn.XLOOKUP(S7:AG7,增益!$A:$A,增益!$F:$F,0))>0,($F$10-$I$3+VLOOKUP($R7,武学奇术!$A:$ZZ,6,FALSE)+SUM(_xlfn.XLOOKUP(S7:AG7,增益!$A:$A,增益!$F:$F,0)))/200,($F$10-$I$3+VLOOKUP($R7,武学奇术!$A:$ZZ,6,FALSE)+SUM(_xlfn.XLOOKUP(S7:AG7,增益!$A:$A,增益!$F:$F,0)))/100)} -> 0.264 | AR7: {=$G$10+VLOOKUP($R7,武学奇术!$A:$ZZ,7,FALSE)+SUM(_xlfn.XLOOKUP(S7:AG7,增益!$A:$A,增益!$G:$G,0))} -> 0 | AS7: {=VLOOKUP($R7,武学奇术!$A:$ZZ,8,FALSE)+SUM(_xlfn.XLOOKUP(S7:AG7,增益!$A:$A,增益!$H:$H,0))} -> 0 | AT7: =$D$11*(1+$AS7) -> 680.02 | AU7: =$E$11*(1+$AS7) -> 1288.54 | AV7: {=IF($F$11-$I$4+VLOOKUP($R7,武学奇术!$A:$ZZ,9,FALSE)+SUM(_xlfn.XLOOKUP(S7:AG7,增益!$A:$A,增益!$I:$I,0))>0,($F$11-$I$4+VLOOKUP($R7,武学奇术!$A:$ZZ,9,FALSE)+SUM(_xlfn.XLOOKUP(S7:AG7,增益!$A:$A,增益!$I:$I,0)))/200,($F$11-$I$4+VLOOKUP($R7,武学奇术!$A:$ZZ,9,FALSE)+SUM(_xlfn.XLOOKUP(S7:AG7,增益!$A:$A,增益!$I:$I,0)))/100)} -> 0 | AW7: {=$G$11+VLOOKUP($R7,武学奇术!$A:$ZZ,10,FALSE)+SUM(_xlfn.XLOOKUP(S7:AG7,增益!$A:$A,增益!$J:$J,0))} -> 0.15 | AX7: =$D$12*(1+$AS7) -> 0 | AY7: =$E$12*(1+$AS7) -> 0 | AZ7: {=IF($F$12-$I$4+VLOOKUP($R7,武学奇术!$A:$ZZ,11,FALSE)+SUM(_xlfn.XLOOKUP(S7:AG7,增益!$A:$A,增益!$K:$K,0))>0,($F$12-$I$4+VLOOKUP($R7,武学奇术!$A:$ZZ,11,FALSE)+SUM(_xlfn.XLOOKUP(S7:AG7,增益!$A:$A,增益!$K:$K,0)))/200,($F$12-$I$4+VLOOKUP($R7,武学奇术!$A:$ZZ,11,FALSE)+SUM(_xlfn.XLOOKUP(S7:AG7,增益!$A:$A,增益!$K:$K,0)))/100)} -> -0.3 | BA7: {=$G$12+VLOOKUP($R7,武学奇术!$A:$ZZ,12,FALSE)+SUM(_xlfn.XLOOKUP(S7:AG7,增益!$A:$A,增益!$L:$L,0))} -> 0 | BB7: =$D$13*(1+$AS7) -> 0 | BC7: =$E$13*(1+$AS7) -> 0 | BD7: {=IF($F$13-$I$4+VLOOKUP($R7,武学奇术!$A:$ZZ,13,FALSE)+SUM(_xlfn.XLOOKUP(S7:AG7,增益!$A:$A,增益!$M:$M,0))>0,($F$13-$I$4+VLOOKUP($R7,武学奇术!$A:$ZZ,13,FALSE)+SUM(_xlfn.XLOOKUP(S7:AG7,增益!$A:$A,增益!$K:$K,0)))/200,($F$13-$I$4+VLOOKUP($R7,武学奇术!$A:$ZZ,13,FALSE)+SUM(_xlfn.XLOOKUP(S7:AG7,增益!$A:$A,增益!$M:$M,0)))/100)} -> -0.3 | BE7: {=$G$13+VLOOKUP($R7,武学奇术!$A:$ZZ,14,FALSE)+SUM(_xlfn.XLOOKUP(S7:AG7,增益!$A:$A,增益!$N:$N,0))} -> 0 | BF7: =$D$14*(1+$AS7) -> 0 | BG7: =$E$14*(1+$AS7) -> 0 | BH7: {=IF($F$14-$I$4+VLOOKUP($R7,武学奇术!$A:$ZZ,15,FALSE)+SUM(_xlfn.XLOOKUP(S7:AG7,增益!$A:$A,增益!$O:$O,0))>0,($F$14-$I$4+VLOOKUP($R7,武学奇术!$A:$ZZ,15,FALSE)+SUM(_xlfn.XLOOKUP(S7:AG7,增益!$A:$A,增益!$O:$O,0)))/200,($F$14-$I$4+VLOOKUP($R7,武学奇术!$A:$ZZ,15,FALSE)+SUM(_xlfn.XLOOKUP(S7:AG7,增益!$A:$A,增益!$O:$O,0)))/100)} -> -0.3 | BI7: {=$G$14+VLOOKUP($R7,武学奇术!$A:$ZZ,16,FALSE)+SUM(_xlfn.XLOOKUP(S7:AG7,增益!$A:$A,增益!$P:$P,0))} -> 0 | BJ7: =MIN(IF(VLOOKUP($R7,武学奇术!$A:$ZZ,23,FALSE)=1,100%,$B$8),100%) -> 0.8229 | BK7: {=IF(VLOOKUP($R7,武学奇术!$A:$ZZ,23,FALSE)=1,100%,MIN(80%,$B$9+VLOOKUP($R7,武学奇术!$A:$ZZ,17,FALSE)+SUM(_xlfn.XLOOKUP(S7:AG7,增益!$A:$A,增益!$Q:$Q,0)))+$B$11+SUM(_xlfn.XLOOKUP(S7:AG7,增益!$A:$A,增益!$U:$U,0)))*IF(VLOOKUP($R7,武学奇术!$A:$ZZ,24,FALSE)=1,0,1)} -> 0.2285 | BL7: {=1+$B$13+VLOOKUP($R7,武学奇术!$A:$ZZ,18,FALSE)+SUM(_xlfn.XLOOKUP(S7:AG7,增益!$A:$A,增益!$R:$R,0))} -> 1.5 | BM7: {=IF(VLOOKUP($R7,武学奇术!$A:$ZZ,24,FALSE)=1,100%,MIN(40%,$B$10+VLOOKUP($R7,武学奇术!$A:$ZZ,19,FALSE)+SUM(_xlfn.XLOOKUP(S7:AG7,增益!$A:$A,增益!$S:$S,0)))+$B$12+SUM(_xlfn.XLOOKUP(S7:AG7,增益!$A:$A,增益!$V:$V,0)))*IF(VLOOKUP($R7,武学奇术!$A:$ZZ,23,FALSE)=1,0,1)} -> 0.4495 | BN7: {=1+$B$14+VLOOKUP($R7,武学奇术!$A:$ZZ,20,FALSE)+SUM(_xlfn.XLOOKUP(S7:AG7,增益!$A:$A,增益!$T:$T,0))} -> 1.522 | BO7: =MIN((1-BM7)*BJ7,BJ7*BK7) -> 0.18803265 | BP7: =1-BM7-BO7-BQ7 -> 0.2649738 | BQ7: =IF(VLOOKUP($R7,武学奇术!$A:$ZZ,22,FALSE)=1,0,(1-$BJ7))*(1-$BM7) -> 0.09749355 | BR7: {=SUM(_xlfn.XLOOKUP(S7:AG7,增益!$A:$A,增益!$W:$W,0))+$I$5} -> 0.06
A8: 精准率 | B8: 0.8229 | C8: 实际属性 | H8: 战斗时间 | I8: 91.5 | K8: =$L8*VLOOKUP($R8,武学奇术!$A:$ZZ,31,FALSE) -> 28817.933 | L8: =($M8*$BO8+$N8*$BM8+$O8*$BP8+$P8*$BQ8) -> 28817.933 | M8: =((($AO8+$AP8)/2*$AI8+$AJ8)*(1+$AQ8)*(1+$AR8)+(($AT8+$AU8)/2*IF($G$1="鸣金",$AK8,$AI8)+IF($G$1="鸣金",$AL8*1.5,0))*(1+$AV8)*(1+$AW8)+(($AX8+$AY8)/2*IF($G$1="裂石",$AK8,$AI8)+IF($G$1="裂石",$AL8*1.5,0))*(1+$AZ8)*(1+$BA8)+(($BB8+$BC8)/2*IF($G$1="牵丝",$AK8,$AI8)+IF($G$1="牵丝",$AL8*1.5,0))*(1+$BD8)*(1+$BE8)+(($BF8+$BG8)/2*IF($G$1="破竹",$AK8,$AI8)+IF($G$1="破竹",$AL8*1.5,0))*(1+$BH8)*(1+$BI8))*(1+$AM8)*$BL8*$Q8*(1+IF(VLOOKUP($R8,武学奇术!$A:$ZZ,30,FALSE)="流血",$B$21,0))*(1+$BR8) -> 26718.083 | N8: =(($AP8*$AI8+$AJ8)*(1+$AQ8)*(1+$AR8)+($AU8*IF($G$1="鸣金",$AK8,$AI8)+IF($G$1="鸣金",$AL8*1.5,0))*(1+$AV8)*(1+$AW8)+($AY8*IF($G$1="裂石",$AK8,$AI8)+IF($G$1="裂石",$AL8*1.5,0))*(1+$AZ8)*(1+$BA8)+($BC8*IF($G$1="牵丝",$AK8,$AI8)+IF($G$1="牵丝",$AL8*1.5,0))*(1+$BD8)*(1+$BE8)+($BG8*IF($G$1="破竹",$AK8,$AI8)+IF($G$1="破竹",$AL8*1.5,0))*(1+$BH8)*(1+$BI8))*(1+$AM8)*$BN8*$Q8*(1+IF(VLOOKUP($R8,武学奇术!$A:$ZZ,30,FALSE)="流血",$B$21,0))*(1+$BR8) -> 40475.972 | O8: =((($AO8+$AP8)/2*$AI8+$AJ8)*(1+$AQ8)*(1+$AR8)+(($AT8+$AU8)/2*IF($G$1="鸣金",$AK8,$AI8)+IF($G$1="鸣金",$AL8*1.5,0))*(1+$AV8)*(1+$AW8)+(($AX8+$AY8)/2*IF($G$1="裂石",$AK8,$AI8)+IF($G$1="裂石",$AL8*1.5,0))*(1+$AZ8)*(1+$BA8)+(($BB8+$BC8)/2*IF($G$1="牵丝",$AK8,$AI8)+IF($G$1="牵丝",$AL8*1.5,0))*(1+$BD8)*(1+$BE8)+(($BF8+$BG8)/2*IF($G$1="破竹",$AK8,$AI8)+IF($G$1="破竹",$AL8*1.5,0))*(1+$BH8)*(1+$BI8))*(1+$AM8)*$Q8*(1+IF(VLOOKUP($R8,武学奇术!$A:$ZZ,30,FALSE)="流血",$B$21,0))*(1+$BR8) -> 17812.056 | P8: =((($AO8*$AI8+$AJ8)*(1+$AQ8)*(1+$AR8)+($AT8*IF($G$1="鸣金",$AK8,$AI8)+IF($G$1="鸣金",$AL8*1.5,0))*(1+$AV8)*(1+$AW8)+($AX8*IF($G$1="裂石",$AK8,$AI8)+IF($G$1="裂石",$AL8*1.5,0))*(1+$AZ8)*(1+$BA8)+($BB8*IF($G$1="牵丝",$AK8,$AI8)+IF($G$1="牵丝",$AL8*1.5,0))*(1+$BD8)*(1+$BE8)+($BF8*IF($G$1="破竹",$AK8,$AI8)+IF($G$1="破竹",$AL8*1.5,0))*(1+$BH8)*(1+$BI8))*(1+$AM8))*$Q8*(1+IF(VLOOKUP($R8,武学奇术!$A:$ZZ,30,FALSE)="流血",$B$21,0))*(1+$BR8) -> 9030.1743 | Q8: 1 | R8: 枪～一段(江流) | S8: 强效江流 | T8: 看破 | U8: N/a | V8: N/a | W8: N/a | X8: 易水歌3层 | Y8: N/a | Z8: N/a | AA8: 惧刃(拐) | AB8: 裁云(拐) | AC8: 烁鼓(拐) | AD8: 离猎(拐) | AE8: 伞增(拐) | AF8: 近战笛 | AG8: 秋瞑帖2层 | AH8: =VLOOKUP($R8,武学奇术!$A:$ZZ,25,FALSE) -> 枪 | AI8: =VLOOKUP($R8,武学奇术!$A:$ZZ,26,FALSE) -> 1.02732 | AJ8: =VLOOKUP($R8,武学奇术!$A:$ZZ,27,FALSE)*(1+IF(OR($AH8=$F$4,$AH8=$F$5),$B$22,0)) -> 426.6 | AK8: =VLOOKUP($R8,武学奇术!$A:$ZZ,28,FALSE) -> 1.54096 | AL8: =VLOOKUP($R8,武学奇术!$A:$ZZ,29,FALSE)*(1+IF(OR($AH8=$F$4,$AH8=$F$5),$B$22,0)) -> 232.2 | AM8: {=$G$3+IFERROR(VLOOKUP($AH8,$F$4:$G$7,2,FALSE),0)+VLOOKUP($R8,武学奇术!$A:$ZZ,2,FALSE)+SUM(_xlfn.XLOOKUP($S8:$AG8,增益!$A:$A,增益!$B:$B,0))} -> 0.8739 | AN8: {=VLOOKUP($R8,武学奇术!$A:$ZZ,5,FALSE)+SUM(_xlfn.XLOOKUP($S8:$AG8,增益!$A:$A,增益!$E:$E,0))} -> 0 | AO8: {=$D$10*(1+$AN8)+VLOOKUP($R8,武学奇术!$A:$ZZ,3,FALSE)+SUM(_xlfn.XLOOKUP($S8:$AG8,增益!$A:$A,增益!$C:$C,0))-$I$2} -> 1831.48 | AP8: {=$E$10*(1+$AN8)+VLOOKUP($R8,武学奇术!$A:$ZZ,4,FALSE)+SUM(_xlfn.XLOOKUP($S8:$AG8,增益!$A:$A,增益!$D:$D,0))-$I$2} -> 7763.56 | AQ8: {=IF($F$10-$I$3+VLOOKUP($R8,武学奇术!$A:$ZZ,6,FALSE)+SUM(_xlfn.XLOOKUP(S8:AG8,增益!$A:$A,增益!$F:$F,0))>0,($F$10-$I$3+VLOOKUP($R8,武学奇术!$A:$ZZ,6,FALSE)+SUM(_xlfn.XLOOKUP(S8:AG8,增益!$A:$A,增益!$F:$F,0)))/200,($F$10-$I$3+VLOOKUP($R8,武学奇术!$A:$ZZ,6,FALSE)+SUM(_xlfn.XLOOKUP(S8:AG8,增益!$A:$A,增益!$F:$F,0)))/100)} -> 0.274 | AR8: {=$G$10+VLOOKUP($R8,武学奇术!$A:$ZZ,7,FALSE)+SUM(_xlfn.XLOOKUP(S8:AG8,增益!$A:$A,增益!$G:$G,0))} -> 0 | AS8: {=VLOOKUP($R8,武学奇术!$A:$ZZ,8,FALSE)+SUM(_xlfn.XLOOKUP(S8:AG8,增益!$A:$A,增益!$H:$H,0))} -> 0 | AT8: =$D$11*(1+$AS8) -> 680.02 | AU8: =$E$11*(1+$AS8) -> 1288.54 | AV8: {=IF($F$11-$I$4+VLOOKUP($R8,武学奇术!$A:$ZZ,9,FALSE)+SUM(_xlfn.XLOOKUP(S8:AG8,增益!$A:$A,增益!$I:$I,0))>0,($F$11-$I$4+VLOOKUP($R8,武学奇术!$A:$ZZ,9,FALSE)+SUM(_xlfn.XLOOKUP(S8:AG8,增益!$A:$A,增益!$I:$I,0)))/200,($F$11-$I$4+VLOOKUP($R8,武学奇术!$A:$ZZ,9,FALSE)+SUM(_xlfn.XLOOKUP(S8:AG8,增益!$A:$A,增益!$I:$I,0)))/100)} -> 0 | AW8: {=$G$11+VLOOKUP($R8,武学奇术!$A:$ZZ,10,FALSE)+SUM(_xlfn.XLOOKUP(S8:AG8,增益!$A:$A,增益!$J:$J,0))} -> 0.15 | AX8: =$D$12*(1+$AS8) -> 0 | AY8: =$E$12*(1+$AS8) -> 0 | AZ8: {=IF($F$12-$I$4+VLOOKUP($R8,武学奇术!$A:$ZZ,11,FALSE)+SUM(_xlfn.XLOOKUP(S8:AG8,增益!$A:$A,增益!$K:$K,0))>0,($F$12-$I$4+VLOOKUP($R8,武学奇术!$A:$ZZ,11,FALSE)+SUM(_xlfn.XLOOKUP(S8:AG8,增益!$A:$A,增益!$K:$K,0)))/200,($F$12-$I$4+VLOOKUP($R8,武学奇术!$A:$ZZ,11,FALSE)+SUM(_xlfn.XLOOKUP(S8:AG8,增益!$A:$A,增益!$K:$K,0)))/100)} -> -0.3 | BA8: {=$G$12+VLOOKUP($R8,武学奇术!$A:$ZZ,12,FALSE)+SUM(_xlfn.XLOOKUP(S8:AG8,增益!$A:$A,增益!$L:$L,0))} -> 0 | BB8: =$D$13*(1+$AS8) -> 0 | BC8: =$E$13*(1+$AS8) -> 0 | BD8: {=IF($F$13-$I$4+VLOOKUP($R8,武学奇术!$A:$ZZ,13,FALSE)+SUM(_xlfn.XLOOKUP(S8:AG8,增益!$A:$A,增益!$M:$M,0))>0,($F$13-$I$4+VLOOKUP($R8,武学奇术!$A:$ZZ,13,FALSE)+SUM(_xlfn.XLOOKUP(S8:AG8,增益!$A:$A,增益!$K:$K,0)))/200,($F$13-$I$4+VLOOKUP($R8,武学奇术!$A:$ZZ,13,FALSE)+SUM(_xlfn.XLOOKUP(S8:AG8,增益!$A:$A,增益!$M:$M,0)))/100)} -> -0.3 | BE8: {=$G$13+VLOOKUP($R8,武学奇术!$A:$ZZ,14,FALSE)+SUM(_xlfn.XLOOKUP(S8:AG8,增益!$A:$A,增益!$N:$N,0))} -> 0 | BF8: =$D$14*(1+$AS8) -> 0 | BG8: =$E$14*(1+$AS8) -> 0 | BH8: {=IF($F$14-$I$4+VLOOKUP($R8,武学奇术!$A:$ZZ,15,FALSE)+SUM(_xlfn.XLOOKUP(S8:AG8,增益!$A:$A,增益!$O:$O,0))>0,($F$14-$I$4+VLOOKUP($R8,武学奇术!$A:$ZZ,15,FALSE)+SUM(_xlfn.XLOOKUP(S8:AG8,增益!$A:$A,增益!$O:$O,0)))/200,($F$14-$I$4+VLOOKUP($R8,武学奇术!$A:$ZZ,15,FALSE)+SUM(_xlfn.XLOOKUP(S8:AG8,增益!$A:$A,增益!$O:$O,0)))/100)} -> -0.3 | BI8: {=$G$14+VLOOKUP($R8,武学奇术!$A:$ZZ,16,FALSE)+SUM(_xlfn.XLOOKUP(S8:AG8,增益!$A:$A,增益!$P:$P,0))} -> 0 | BJ8: =MIN(IF(VLOOKUP($R8,武学奇术!$A:$ZZ,23,FALSE)=1,100%,$B$8),100%) -> 0.8229 | BK8: {=IF(VLOOKUP($R8,武学奇术!$A:$ZZ,23,FALSE)=1,100%,MIN(80%,$B$9+VLOOKUP($R8,武学奇术!$A:$ZZ,17,FALSE)+SUM(_xlfn.XLOOKUP(S8:AG8,增益!$A:$A,增益!$Q:$Q,0)))+$B$11+SUM(_xlfn.XLOOKUP(S8:AG8,增益!$A:$A,增益!$U:$U,0)))*IF(VLOOKUP($R8,武学奇术!$A:$ZZ,24,FALSE)=1,0,1)} -> 0.2285 | BL8: {=1+$B$13+VLOOKUP($R8,武学奇术!$A:$ZZ,18,FALSE)+SUM(_xlfn.XLOOKUP(S8:AG8,增益!$A:$A,增益!$R:$R,0))} -> 1.5 | BM8: {=IF(VLOOKUP($R8,武学奇术!$A:$ZZ,24,FALSE)=1,100%,MIN(40%,$B$10+VLOOKUP($R8,武学奇术!$A:$ZZ,19,FALSE)+SUM(_xlfn.XLOOKUP(S8:AG8,增益!$A:$A,增益!$S:$S,0)))+$B$12+SUM(_xlfn.XLOOKUP(S8:AG8,增益!$A:$A,增益!$V:$V,0)))*IF(VLOOKUP($R8,武学奇术!$A:$ZZ,23,FALSE)=1,0,1)} -> 0.4495 | BN8: {=1+$B$14+VLOOKUP($R8,武学奇术!$A:$ZZ,20,FALSE)+SUM(_xlfn.XLOOKUP(S8:AG8,增益!$A:$A,增益!$T:$T,0))} -> 1.522 | BO8: =MIN((1-BM8)*BJ8,BJ8*BK8) -> 0.18803265 | BP8: =1-BM8-BO8-BQ8 -> 0.2649738 | BQ8: =IF(VLOOKUP($R8,武学奇术!$A:$ZZ,22,FALSE)=1,0,(1-$BJ8))*(1-$BM8) -> 0.09749355 | BR8: {=SUM(_xlfn.XLOOKUP(S8:AG8,增益!$A:$A,增益!$W:$W,0))+$I$5} -> 0.06
A9: 会心率 | B9: 0.1825 | D9: 最小攻击 | E9: 最大攻击 | F9: 穿透 | G9: 伤害加成 | K9: =$L9*VLOOKUP($R9,武学奇术!$A:$ZZ,31,FALSE) -> 84834.688 | L9: =($M9*$BO9+$N9*$BM9+$O9*$BP9+$P9*$BQ9) -> 141391.15 | M9: =((($AO9+$AP9)/2*$AI9+$AJ9)*(1+$AQ9)*(1+$AR9)+(($AT9+$AU9)/2*IF($G$1="鸣金",$AK9,$AI9)+IF($G$1="鸣金",$AL9*1.5,0))*(1+$AV9)*(1+$AW9)+(($AX9+$AY9)/2*IF($G$1="裂石",$AK9,$AI9)+IF($G$1="裂石",$AL9*1.5,0))*(1+$AZ9)*(1+$BA9)+(($BB9+$BC9)/2*IF($G$1="牵丝",$AK9,$AI9)+IF($G$1="牵丝",$AL9*1.5,0))*(1+$BD9)*(1+$BE9)+(($BF9+$BG9)/2*IF($G$1="破竹",$AK9,$AI9)+IF($G$1="破竹",$AL9*1.5,0))*(1+$BH9)*(1+$BI9))*(1+$AM9)*$BL9*$Q9*(1+IF(VLOOKUP($R9,武学奇术!$A:$ZZ,30,FALSE)="流血",$B$21,0))*(1+$BR9) -> 119482.77 | N9: =(($AP9*$AI9+$AJ9)*(1+$AQ9)*(1+$AR9)+($AU9*IF($G$1="鸣金",$AK9,$AI9)+IF($G$1="鸣金",$AL9*1.5,0))*(1+$AV9)*(1+$AW9)+($AY9*IF($G$1="裂石",$AK9,$AI9)+IF($G$1="裂石",$AL9*1.5,0))*(1+$AZ9)*(1+$BA9)+($BC9*IF($G$1="牵丝",$AK9,$AI9)+IF($G$1="牵丝",$AL9*1.5,0))*(1+$BD9)*(1+$BE9)+($BG9*IF($G$1="破竹",$AK9,$AI9)+IF($G$1="破竹",$AL9*1.5,0))*(1+$BH9)*(1+$BI9))*(1+$AM9)*$BN9*$Q9*(1+IF(VLOOKUP($R9,武学奇术!$A:$ZZ,30,FALSE)="流血",$B$21,0))*(1+$BR9) -> 209797.02 | O9: =((($AO9+$AP9)/2*$AI9+$AJ9)*(1+$AQ9)*(1+$AR9)+(($AT9+$AU9)/2*IF($G$1="鸣金",$AK9,$AI9)+IF($G$1="鸣金",$AL9*1.5,0))*(1+$AV9)*(1+$AW9)+(($AX9+$AY9)/2*IF($G$1="裂石",$AK9,$AI9)+IF($G$1="裂石",$AL9*1.5,0))*(1+$AZ9)*(1+$BA9)+(($BB9+$BC9)/2*IF($G$1="牵丝",$AK9,$AI9)+IF($G$1="牵丝",$AL9*1.5,0))*(1+$BD9)*(1+$BE9)+(($BF9+$BG9)/2*IF($G$1="破竹",$AK9,$AI9)+IF($G$1="破竹",$AL9*1.5,0))*(1+$BH9)*(1+$BI9))*(1+$AM9)*$Q9*(1+IF(VLOOKUP($R9,武学奇术!$A:$ZZ,30,FALSE)="流血",$B$21,0))*(1+$BR9) -> 79655.179 | P9: =((($AO9*$AI9+$AJ9)*(1+$AQ9)*(1+$AR9)+($AT9*IF($G$1="鸣金",$AK9,$AI9)+IF($G$1="鸣金",$AL9*1.5,0))*(1+$AV9)*(1+$AW9)+($AX9*IF($G$1="裂石",$AK9,$AI9)+IF($G$1="裂石",$AL9*1.5,0))*(1+$AZ9)*(1+$BA9)+($BB9*IF($G$1="牵丝",$AK9,$AI9)+IF($G$1="牵丝",$AL9*1.5,0))*(1+$BD9)*(1+$BE9)+($BF9*IF($G$1="破竹",$AK9,$AI9)+IF($G$1="破竹",$AL9*1.5,0))*(1+$BH9)*(1+$BI9))*(1+$AM9))*$Q9*(1+IF(VLOOKUP($R9,武学奇术!$A:$ZZ,30,FALSE)="流血",$B$21,0))*(1+$BR9) -> 36045.367 | Q9: 1 | R9: 爆血(剑) | S9: 强效江流 | T9: 看破(持续) | U9: 惊神5 | V9: 纵横剑意 | W9: 特殊技减防 | X9: 易水歌3层 | Y9: N/a | Z9: N/a | AA9: 惧刃(拐) | AB9: 裁云(拐) | AC9: 烁鼓(拐) | AD9: 离猎(拐) | AE9: 伞增(拐) | AF9: 近战笛 | AG9: 秋瞑帖2层 | AH9: =VLOOKUP($R9,武学奇术!$A:$ZZ,25,FALSE) -> 剑 | AI9: =VLOOKUP($R9,武学奇术!$A:$ZZ,26,FALSE) -> 2.52 | AJ9: =VLOOKUP($R9,武学奇术!$A:$ZZ,27,FALSE)*(1+IF(OR($AH9=$F$4,$AH9=$F$5),$B$22,0)) -> 0 | AK9: =VLOOKUP($R9,武学奇术!$A:$ZZ,28,FALSE) -> 3.78 | AL9: =VLOOKUP($R9,武学奇术!$A:$ZZ,29,FALSE)*(1+IF(OR($AH9=$F$4,$AH9=$F$5),$B$22,0)) -> 0 | AM9: {=$G$3+IFERROR(VLOOKUP($AH9,$F$4:$G$7,2,FALSE),0)+VLOOKUP($R9,武学奇术!$A:$ZZ,2,FALSE)+SUM(_xlfn.XLOOKUP($S9:$AG9,增益!$A:$A,增益!$B:$B,0))} -> 1.7091 | AN9: {=VLOOKUP($R9,武学奇术!$A:$ZZ,5,FALSE)+SUM(_xlfn.XLOOKUP($S9:$AG9,增益!$A:$A,增益!$E:$E,0))} -> 0 | AO9: {=$D$10*(1+$AN9)+VLOOKUP($R9,武学奇术!$A:$ZZ,3,FALSE)+SUM(_xlfn.XLOOKUP($S9:$AG9,增益!$A:$A,增益!$C:$C,0))-$I$2} -> 1862.48 | AP9: {=$E$10*(1+$AN9)+VLOOKUP($R9,武学奇术!$A:$ZZ,4,FALSE)+SUM(_xlfn.XLOOKUP($S9:$AG9,增益!$A:$A,增益!$D:$D,0))-$I$2} -> 7794.56 | AQ9: {=IF($F$10-$I$3+VLOOKUP($R9,武学奇术!$A:$ZZ,6,FALSE)+SUM(_xlfn.XLOOKUP(S9:AG9,增益!$A:$A,增益!$F:$F,0))>0,($F$10-$I$3+VLOOKUP($R9,武学奇术!$A:$ZZ,6,FALSE)+SUM(_xlfn.XLOOKUP(S9:AG9,增益!$A:$A,增益!$F:$F,0)))/200,($F$10-$I$3+VLOOKUP($R9,武学奇术!$A:$ZZ,6,FALSE)+SUM(_xlfn.XLOOKUP(S9:AG9,增益!$A:$A,增益!$F:$F,0)))/100)} -> 0.349 | AR9: {=$G$10+VLOOKUP($R9,武学奇术!$A:$ZZ,7,FALSE)+SUM(_xlfn.XLOOKUP(S9:AG9,增益!$A:$A,增益!$G:$G,0))} -> 0 | AS9: {=VLOOKUP($R9,武学奇术!$A:$ZZ,8,FALSE)+SUM(_xlfn.XLOOKUP(S9:AG9,增益!$A:$A,增益!$H:$H,0))} -> 0 | AT9: =$D$11*(1+$AS9) -> 680.02 | AU9: =$E$11*(1+$AS9) -> 1288.54 | AV9: {=IF($F$11-$I$4+VLOOKUP($R9,武学奇术!$A:$ZZ,9,FALSE)+SUM(_xlfn.XLOOKUP(S9:AG9,增益!$A:$A,增益!$I:$I,0))>0,($F$11-$I$4+VLOOKUP($R9,武学奇术!$A:$ZZ,9,FALSE)+SUM(_xlfn.XLOOKUP(S9:AG9,增益!$A:$A,增益!$I:$I,0)))/200,($F$11-$I$4+VLOOKUP($R9,武学奇术!$A:$ZZ,9,FALSE)+SUM(_xlfn.XLOOKUP(S9:AG9,增益!$A:$A,增益!$I:$I,0)))/100)} -> 0.075 | AW9: {=$G$11+VLOOKUP($R9,武学奇术!$A:$ZZ,10,FALSE)+SUM(_xlfn.XLOOKUP(S9:AG9,增益!$A:$A,增益!$J:$J,0))} -> 0.15 | AX9: =$D$12*(1+$AS9) -> 0 | AY9: =$E$12*(1+$AS9) -> 0 | AZ9: {=IF($F$12-$I$4+VLOOKUP($R9,武学奇术!$A:$ZZ,11,FALSE)+SUM(_xlfn.XLOOKUP(S9:AG9,增益!$A:$A,增益!$K:$K,0))>0,($F$12-$I$4+VLOOKUP($R9,武学奇术!$A:$ZZ,11,FALSE)+SUM(_xlfn.XLOOKUP(S9:AG9,增益!$A:$A,增益!$K:$K,0)))/200,($F$12-$I$4+VLOOKUP($R9,武学奇术!$A:$ZZ,11,FALSE)+SUM(_xlfn.XLOOKUP(S9:AG9,增益!$A:$A,增益!$K:$K,0)))/100)} -> -0.3 | BA9: {=$G$12+VLOOKUP($R9,武学奇术!$A:$ZZ,12,FALSE)+SUM(_xlfn.XLOOKUP(S9:AG9,增益!$A:$A,增益!$L:$L,0))} -> 0 | BB9: =$D$13*(1+$AS9) -> 0 | BC9: =$E$13*(1+$AS9) -> 0 | BD9: {=IF($F$13-$I$4+VLOOKUP($R9,武学奇术!$A:$ZZ,13,FALSE)+SUM(_xlfn.XLOOKUP(S9:AG9,增益!$A:$A,增益!$M:$M,0))>0,($F$13-$I$4+VLOOKUP($R9,武学奇术!$A:$ZZ,13,FALSE)+SUM(_xlfn.XLOOKUP(S9:AG9,增益!$A:$A,增益!$K:$K,0)))/200,($F$13-$I$4+VLOOKUP($R9,武学奇术!$A:$ZZ,13,FALSE)+SUM(_xlfn.XLOOKUP(S9:AG9,增益!$A:$A,增益!$M:$M,0)))/100)} -> -0.3 | BE9: {=$G$13+VLOOKUP($R9,武学奇术!$A:$ZZ,14,FALSE)+SUM(_xlfn.XLOOKUP(S9:AG9,增益!$A:$A,增益!$N:$N,0))} -> 0 | BF9: =$D$14*(1+$AS9) -> 0 | BG9: =$E$14*(1+$AS9) -> 0 | BH9: {=IF($F$14-$I$4+VLOOKUP($R9,武学奇术!$A:$ZZ,15,FALSE)+SUM(_xlfn.XLOOKUP(S9:AG9,增益!$A:$A,增益!$O:$O,0))>0,($F$14-$I$4+VLOOKUP($R9,武学奇术!$A:$ZZ,15,FALSE)+SUM(_xlfn.XLOOKUP(S9:AG9,增益!$A:$A,增益!$O:$O,0)))/200,($F$14-$I$4+VLOOKUP($R9,武学奇术!$A:$ZZ,15,FALSE)+SUM(_xlfn.XLOOKUP(S9:AG9,增益!$A:$A,增益!$O:$O,0)))/100)} -> -0.3 | BI9: {=$G$14+VLOOKUP($R9,武学奇术!$A:$ZZ,16,FALSE)+SUM(_xlfn.XLOOKUP(S9:AG9,增益!$A:$A,增益!$P:$P,0))} -> 0 | BJ9: =MIN(IF(VLOOKUP($R9,武学奇术!$A:$ZZ,23,FALSE)=1,100%,$B$8),100%) -> 0.8229 | BK9: {=IF(VLOOKUP($R9,武学奇术!$A:$ZZ,23,FALSE)=1,100%,MIN(80%,$B$9+VLOOKUP($R9,武学奇术!$A:$ZZ,17,FALSE)+SUM(_xlfn.XLOOKUP(S9:AG9,增益!$A:$A,增益!$Q:$Q,0)))+$B$11+SUM(_xlfn.XLOOKUP(S9:AG9,增益!$A:$A,增益!$U:$U,0)))*IF(VLOOKUP($R9,武学奇术!$A:$ZZ,24,FALSE)=1,0,1)} -> 0.2285 | BL9: {=1+$B$13+VLOOKUP($R9,武学奇术!$A:$ZZ,18,FALSE)+SUM(_xlfn.XLOOKUP(S9:AG9,增益!$A:$A,增益!$R:$R,0))} -> 1.5 | BM9: {=IF(VLOOKUP($R9,武学奇术!$A:$ZZ,24,FALSE)=1,100%,MIN(40%,$B$10+VLOOKUP($R9,武学奇术!$A:$ZZ,19,FALSE)+SUM(_xlfn.XLOOKUP(S9:AG9,增益!$A:$A,增益!$S:$S,0)))+$B$12+SUM(_xlfn.XLOOKUP(S9:AG9,增益!$A:$A,增益!$V:$V,0)))*IF(VLOOKUP($R9,武学奇术!$A:$ZZ,23,FALSE)=1,0,1)} -> 0.4495 | BN9: {=1+$B$14+VLOOKUP($R9,武学奇术!$A:$ZZ,20,FALSE)+SUM(_xlfn.XLOOKUP(S9:AG9,增益!$A:$A,增益!$T:$T,0))} -> 1.702 | BO9: =MIN((1-BM9)*BJ9,BJ9*BK9) -> 0.18803265 | BP9: =1-BM9-BO9-BQ9 -> 0.2649738 | BQ9: =IF(VLOOKUP($R9,武学奇术!$A:$ZZ,22,FALSE)=1,0,(1-$BJ9))*(1-$BM9) -> 0.09749355 | BR9: {=SUM(_xlfn.XLOOKUP(S9:AG9,增益!$A:$A,增益!$W:$W,0))+$I$5} -> 0.06
A10: 会意率 | B10: 0.3965 | C10: 外功 | D10: =(B2+B23)*IF($G$2="飞隼",1.1,1) -> 2414.28 | E10: =MAX(B2+B23,C2+B24)*IF($G$2="飞隼",1.1,1) -> 8346.36 | F10: =D2 -> 63.8 | G10: =E2 -> 0 | H10: 总伤 | I10: =SUM(L:L) -> 15884397 | K10: =$L10*VLOOKUP($R10,武学奇术!$A:$ZZ,31,FALSE) -> 34797.617 | L10: =($M10*$BO10+$N10*$BM10+$O10*$BP10+$P10*$BQ10) -> 34797.617 | M10: =((($AO10+$AP10)/2*$AI10+$AJ10)*(1+$AQ10)*(1+$AR10)+(($AT10+$AU10)/2*IF($G$1="鸣金",$AK10,$AI10)+IF($G$1="鸣金",$AL10*1.5,0))*(1+$AV10)*(1+$AW10)+(($AX10+$AY10)/2*IF($G$1="裂石",$AK10,$AI10)+IF($G$1="裂石",$AL10*1.5,0))*(1+$AZ10)*(1+$BA10)+(($BB10+$BC10)/2*IF($G$1="牵丝",$AK10,$AI10)+IF($G$1="牵丝",$AL10*1.5,0))*(1+$BD10)*(1+$BE10)+(($BF10+$BG10)/2*IF($G$1="破竹",$AK10,$AI10)+IF($G$1="破竹",$AL10*1.5,0))*(1+$BH10)*(1+$BI10))*(1+$AM10)*$BL10*$Q10*(1+IF(VLOOKUP($R10,武学奇术!$A:$ZZ,30,FALSE)="流血",$B$21,0))*(1+$BR10) -> 31819.116 | N10: =(($AP10*$AI10+$AJ10)*(1+$AQ10)*(1+$AR10)+($AU10*IF($G$1="鸣金",$AK10,$AI10)+IF($G$1="鸣金",$AL10*1.5,0))*(1+$AV10)*(1+$AW10)+($AY10*IF($G$1="裂石",$AK10,$AI10)+IF($G$1="裂石",$AL10*1.5,0))*(1+$AZ10)*(1+$BA10)+($BC10*IF($G$1="牵丝",$AK10,$AI10)+IF($G$1="牵丝",$AL10*1.5,0))*(1+$BD10)*(1+$BE10)+($BG10*IF($G$1="破竹",$AK10,$AI10)+IF($G$1="破竹",$AL10*1.5,0))*(1+$BH10)*(1+$BI10))*(1+$AM10)*$BN10*$Q10*(1+IF(VLOOKUP($R10,武学奇术!$A:$ZZ,30,FALSE)="流血",$B$21,0))*(1+$BR10) -> 49443.14 | O10: =((($AO10+$AP10)/2*$AI10+$AJ10)*(1+$AQ10)*(1+$AR10)+(($AT10+$AU10)/2*IF($G$1="鸣金",$AK10,$AI10)+IF($G$1="鸣金",$AL10*1.5,0))*(1+$AV10)*(1+$AW10)+(($AX10+$AY10)/2*IF($G$1="裂石",$AK10,$AI10)+IF($G$1="裂石",$AL10*1.5,0))*(1+$AZ10)*(1+$BA10)+(($BB10+$BC10)/2*IF($G$1="牵丝",$AK10,$AI10)+IF($G$1="牵丝",$AL10*1.5,0))*(1+$BD10)*(1+$BE10)+(($BF10+$BG10)/2*IF($G$1="破竹",$AK10,$AI10)+IF($G$1="破竹",$AL10*1.5,0))*(1+$BH10)*(1+$BI10))*(1+$AM10)*$Q10*(1+IF(VLOOKUP($R10,武学奇术!$A:$ZZ,30,FALSE)="流血",$B$21,0))*(1+$BR10) -> 21212.744 | P10: =((($AO10*$AI10+$AJ10)*(1+$AQ10)*(1+$AR10)+($AT10*IF($G$1="鸣金",$AK10,$AI10)+IF($G$1="鸣金",$AL10*1.5,0))*(1+$AV10)*(1+$AW10)+($AX10*IF($G$1="裂石",$AK10,$AI10)+IF($G$1="裂石",$AL10*1.5,0))*(1+$AZ10)*(1+$BA10)+($BB10*IF($G$1="牵丝",$AK10,$AI10)+IF($G$1="牵丝",$AL10*1.5,0))*(1+$BD10)*(1+$BE10)+($BF10*IF($G$1="破竹",$AK10,$AI10)+IF($G$1="破竹",$AL10*1.5,0))*(1+$BH10)*(1+$BI10))*(1+$AM10))*$Q10*(1+IF(VLOOKUP($R10,武学奇术!$A:$ZZ,30,FALSE)="流血",$B$21,0))*(1+$BR10) -> 9939.8503 | Q10: 1 | R10: 神龙吐火暗灼1hit | S10: 强效江流 | T10: 看破 | U10: N/a | V10: N/a | W10: 特殊技减防 | X10: 易水歌3层 | Y10: N/a | Z10: N/a | AA10: 惧刃(拐) | AB10: 裁云(拐) | AC10: 烁鼓(拐) | AD10: 离猎(拐) | AE10: 伞增(拐) | AF10: 近战笛 | AG10: 秋瞑帖2层 | AH10: =VLOOKUP($R10,武学奇术!$A:$ZZ,25,FALSE) -> 单体奇术 | AI10: =VLOOKUP($R10,武学奇术!$A:$ZZ,26,FALSE) -> 1.28505 | AJ10: =VLOOKUP($R10,武学奇术!$A:$ZZ,27,FALSE)*(1+IF(OR($AH10=$F$4,$AH10=$F$5),$B$22,0)) -> 251 | AK10: =VLOOKUP($R10,武学奇术!$A:$ZZ,28,FALSE) -> 1.927575 | AL10: =VLOOKUP($R10,武学奇术!$A:$ZZ,29,FALSE)*(1+IF(OR($AH10=$F$4,$AH10=$F$5),$B$22,0)) -> 0 | AM10: {=$G$3+IFERROR(VLOOKUP($AH10,$F$4:$G$7,2,FALSE),0)+VLOOKUP($R10,武学奇术!$A:$ZZ,2,FALSE)+SUM(_xlfn.XLOOKUP($S10:$AG10,增益!$A:$A,增益!$B:$B,0))} -> 0.923 | AN10: {=VLOOKUP($R10,武学奇术!$A:$ZZ,5,FALSE)+SUM(_xlfn.XLOOKUP($S10:$AG10,增益!$A:$A,增益!$E:$E,0))} -> 0 | AO10: {=$D$10*(1+$AN10)+VLOOKUP($R10,武学奇术!$A:$ZZ,3,FALSE)+SUM(_xlfn.XLOOKUP($S10:$AG10,增益!$A:$A,增益!$C:$C,0))-$I$2} -> 1862.48 | AP10: {=$E$10*(1+$AN10)+VLOOKUP($R10,武学奇术!$A:$ZZ,4,FALSE)+SUM(_xlfn.XLOOKUP($S10:$AG10,增益!$A:$A,增益!$D:$D,0))-$I$2} -> 7794.56 | AQ10: {=IF($F$10-$I$3+VLOOKUP($R10,武学奇术!$A:$ZZ,6,FALSE)+SUM(_xlfn.XLOOKUP(S10:AG10,增益!$A:$A,增益!$F:$F,0))>0,($F$10-$I$3+VLOOKUP($R10,武学奇术!$A:$ZZ,6,FALSE)+SUM(_xlfn.XLOOKUP(S10:AG10,增益!$A:$A,增益!$F:$F,0)))/200,($F$10-$I$3+VLOOKUP($R10,武学奇术!$A:$ZZ,6,FALSE)+SUM(_xlfn.XLOOKUP(S10:AG10,增益!$A:$A,增益!$F:$F,0)))/100)} -> 0.274 | AR10: {=$G$10+VLOOKUP($R10,武学奇术!$A:$ZZ,7,FALSE)+SUM(_xlfn.XLOOKUP(S10:AG10,增益!$A:$A,增益!$G:$G,0))} -> 0 | AS10: {=VLOOKUP($R10,武学奇术!$A:$ZZ,8,FALSE)+SUM(_xlfn.XLOOKUP(S10:AG10,增益!$A:$A,增益!$H:$H,0))} -> 0 | AT10: =$D$11*(1+$AS10) -> 680.02 | AU10: =$E$11*(1+$AS10) -> 1288.54 | AV10: {=IF($F$11-$I$4+VLOOKUP($R10,武学奇术!$A:$ZZ,9,FALSE)+SUM(_xlfn.XLOOKUP(S10:AG10,增益!$A:$A,增益!$I:$I,0))>0,($F$11-$I$4+VLOOKUP($R10,武学奇术!$A:$ZZ,9,FALSE)+SUM(_xlfn.XLOOKUP(S10:AG10,增益!$A:$A,增益!$I:$I,0)))/200,($F$11-$I$4+VLOOKUP($R10,武学奇术!$A:$ZZ,9,FALSE)+SUM(_xlfn.XLOOKUP(S10:AG10,增益!$A:$A,增益!$I:$I,0)))/100)} -> 0 | AW10: {=$G$11+VLOOKUP($R10,武学奇术!$A:$ZZ,10,FALSE)+SUM(_xlfn.XLOOKUP(S10:AG10,增益!$A:$A,增益!$J:$J,0))} -> 0.15 | AX10: =$D$12*(1+$AS10) -> 0 | AY10: =$E$12*(1+$AS10) -> 0 | AZ10: {=IF($F$12-$I$4+VLOOKUP($R10,武学奇术!$A:$ZZ,11,FALSE)+SUM(_xlfn.XLOOKUP(S10:AG10,增益!$A:$A,增益!$K:$K,0))>0,($F$12-$I$4+VLOOKUP($R10,武学奇术!$A:$ZZ,11,FALSE)+SUM(_xlfn.XLOOKUP(S10:AG10,增益!$A:$A,增益!$K:$K,0)))/200,($F$12-$I$4+VLOOKUP($R10,武学奇术!$A:$ZZ,11,FALSE)+SUM(_xlfn.XLOOKUP(S10:AG10,增益!$A:$A,增益!$K:$K,0)))/100)} -> -0.3 | BA10: {=$G$12+VLOOKUP($R10,武学奇术!$A:$ZZ,12,FALSE)+SUM(_xlfn.XLOOKUP(S10:AG10,增益!$A:$A,增益!$L:$L,0))} -> 0 | BB10: =$D$13*(1+$AS10) -> 0 | BC10: =$E$13*(1+$AS10) -> 0 | BD10: {=IF($F$13-$I$4+VLOOKUP($R10,武学奇术!$A:$ZZ,13,FALSE)+SUM(_xlfn.XLOOKUP(S10:AG10,增益!$A:$A,增益!$M:$M,0))>0,($F$13-$I$4+VLOOKUP($R10,武学奇术!$A:$ZZ,13,FALSE)+SUM(_xlfn.XLOOKUP(S10:AG10,增益!$A:$A,增益!$K:$K,0)))/200,($F$13-$I$4+VLOOKUP($R10,武学奇术!$A:$ZZ,13,FALSE)+SUM(_xlfn.XLOOKUP(S10:AG10,增益!$A:$A,增益!$M:$M,0)))/100)} -> -0.3 | BE10: {=$G$13+VLOOKUP($R10,武学奇术!$A:$ZZ,14,FALSE)+SUM(_xlfn.XLOOKUP(S10:AG10,增益!$A:$A,增益!$N:$N,0))} -> 0 | BF10: =$D$14*(1+$AS10) -> 0 | BG10: =$E$14*(1+$AS10) -> 0 | BH10: {=IF($F$14-$I$4+VLOOKUP($R10,武学奇术!$A:$ZZ,15,FALSE)+SUM(_xlfn.XLOOKUP(S10:AG10,增益!$A:$A,增益!$O:$O,0))>0,($F$14-$I$4+VLOOKUP($R10,武学奇术!$A:$ZZ,15,FALSE)+SUM(_xlfn.XLOOKUP(S10:AG10,增益!$A:$A,增益!$O:$O,0)))/200,($F$14-$I$4+VLOOKUP($R10,武学奇术!$A:$ZZ,15,FALSE)+SUM(_xlfn.XLOOKUP(S10:AG10,增益!$A:$A,增益!$O:$O,0)))/100)} -> -0.3 | BI10: {=$G$14+VLOOKUP($R10,武学奇术!$A:$ZZ,16,FALSE)+SUM(_xlfn.XLOOKUP(S10:AG10,增益!$A:$A,增益!$P:$P,0))} -> 0 | BJ10: =MIN(IF(VLOOKUP($R10,武学奇术!$A:$ZZ,23,FALSE)=1,100%,$B$8),100%) -> 0.8229 | BK10: {=IF(VLOOKUP($R10,武学奇术!$A:$ZZ,23,FALSE)=1,100%,MIN(80%,$B$9+VLOOKUP($R10,武学奇术!$A:$ZZ,17,FALSE)+SUM(_xlfn.XLOOKUP(S10:AG10,增益!$A:$A,增益!$Q:$Q,0)))+$B$11+SUM(_xlfn.XLOOKUP(S10:AG10,增益!$A:$A,增益!$U:$U,0)))*IF(VLOOKUP($R10,武学奇术!$A:$ZZ,24,FALSE)=1,0,1)} -> 0.2285 | BL10: {=1+$B$13+VLOOKUP($R10,武学奇术!$A:$ZZ,18,FALSE)+SUM(_xlfn.XLOOKUP(S10:AG10,增益!$A:$A,增益!$R:$R,0))} -> 1.5 | BM10: {=IF(VLOOKUP($R10,武学奇术!$A:$ZZ,24,FALSE)=1,100%,MIN(40%,$B$10+VLOOKUP($R10,武学奇术!$A:$ZZ,19,FALSE)+SUM(_xlfn.XLOOKUP(S10:AG10,增益!$A:$A,增益!$S:$S,0)))+$B$12+SUM(_xlfn.XLOOKUP(S10:AG10,增益!$A:$A,增益!$V:$V,0)))*IF(VLOOKUP($R10,武学奇术!$A:$ZZ,23,FALSE)=1,0,1)} -> 0.4495 | BN10: {=1+$B$14+VLOOKUP($R10,武学奇术!$A:$ZZ,20,FALSE)+SUM(_xlfn.XLOOKUP(S10:AG10,增益!$A:$A,增益!$T:$T,0))} -> 1.522 | BO10: =MIN((1-BM10)*BJ10,BJ10*BK10) -> 0.18803265 | BP10: =1-BM10-BO10-BQ10 -> 0.2649738 | BQ10: =IF(VLOOKUP($R10,武学奇术!$A:$ZZ,22,FALSE)=1,0,(1-$BJ10))*(1-$BM10) -> 0.09749355 | BR10: {=SUM(_xlfn.XLOOKUP(S10:AG10,增益!$A:$A,增益!$W:$W,0))+$I$5} -> 0.06
