Workbook

Sheet 期望
B1: 最小攻击 | C1: 最大攻击 | D1: 穿透 | E1: 伤害加成 | F1: 武学属性 | G1: 牵丝 | H1: 怪物属性 | K1: 期望 | L1: 会心期望 | M1: 会意期望 | N1: 普通期望 | O1: 擦伤期望 | P1: 次数 | Q1: 技能 | R1: 增益1 | S1: 增益2 | T1: 增益3 | U1: 增益4 | V1: 增益5 | W1: 增益6 | X1: 增益7 | Y1: 增益8 | Z1: 增益9 | AA1: 增益10 | AB1: 增益11 | AC1: 增益12 | AD1: 增益13 | AE1: 增益14 | AF1: 增益15 | AG1: 增益16 | AH1: 增益17 | AI1: 增益18 | AJ1: 增益19 | AK1: 增益20 | AL1: 类型 | AM1: 外功倍率 | AN1: 外攻固伤 | AO1: 属性倍率 | AP1: 属性固伤 | AQ1: 通用增伤 | AR1: 外攻加成 | AS1: 即时小外 | AT1: 即时大外 | AU1: 外穿加成 | AV1: 外伤加成 | AW1: 属攻加成 | AX1: 即时小鸣 | AY1: 即时大鸣 | AZ1: 鸣金穿透 | BA1: 鸣金加成 | BB1: 即时小裂 | BC1: 即时大裂 | BD1: 裂石穿透 | BE1: 裂石加成 | BF1: 即时小牵 | BG1: 即时大牵 | BH1: 牵丝穿透 | BI1: 牵丝加成 | BJ1: 即时小破 | BK1: 即时大破 | BL1: 破竹穿透 | BM1: 破竹加成 | BN1: 生效精准 | BO1: 生效会心 | BP1: 生效会心伤害 | BQ1: 生效会意 | BR1: 生效会意伤害 | BS1: 会心占比 | BT1: 普攻占比 | BU1: 擦伤占比 | BV1: 特殊增伤
A2: 外功 | B2: 4031.1 | C2: 3144.7 | D2: 58.4 | E2: 0.025 | F2: 套装 | G2: 裁云 | H2: 防御 | I2: =620*(1-IF(F17="√",0.06,0)-IF(D20="√",0.04,0)) -> 558 | K2: =($L2*$BS2+$M2*$BQ2+$N2*$BT2+$O2*$BU2) -> 33822.472 | L2: =((($AS2+$AT2)/2*$AM2+$AN2)*(1+$AU2)*(1+$AV2)+(($AX2+$AY2)/2*IF($G$1="鸣金",$AO2,$AM2)+IF($G$1="鸣金",$AP2*1.5,0))*(1+$AZ2)*(1+$BA2)+(($BB2+$BC2)/2*IF($G$1="裂石",$AO2,$AM2)+IF($G$1="裂石",$AP2*1.5,0))*(1+$BD2)*(1+$BE2)+(($BF2+$BG2)/2*IF($G$1="牵丝",$AO2,$AM2)+IF($G$1="牵丝",$AP2*1.5,0))*(1+$BH2)*(1+$BI2)+(($BJ2+$BK2)/2*IF($G$1="破竹",$AO2,$AM2)+IF($G$1="破竹",$AP2*1.5,0))*(1+$BL2)*(1+$BM2))*(1+$AQ2)*$BP2*$P2*(1+IF(VLOOKUP($Q2,武学奇术!$A:$ZZ,30,FALSE)="特殊技",$B$21,0))*(1+$BV2) -> 34261.442 | M2: =(($AT2*$AM2+$AN2)*(1+$AU2)*(1+$AV2)+($AY2*IF($G$1="鸣金",$AO2,$AM2)+IF($G$1="鸣金",$AP2*1.5,0))*(1+$AZ2)*(1+$BA2)+($BC2*IF($G$1="裂石",$AO2,$AM2)+IF($G$1="裂石",$AP2*1.5,0))*(1+$BD2)*(1+$BE2)+($BG2*IF($G$1="牵丝",$AO2,$AM2)+IF($G$1="牵丝",$AP2*1.5,0))*(1+$BH2)*(1+$BI2)+($BK2*IF($G$1="破竹",$AO2,$AM2)+IF($G$1="破竹",$AP2*1.5,0))*(1+$BL2)*(1+$BM2))*(1+$AQ2)*$BR2*$P2*(1+IF(VLOOKUP($Q2,武学奇术!$A:$ZZ,30,FALSE)="特殊技",$B$21,0))*(1+$BV2) -> 33649.904 | N2: =((($AS2+$AT2)/2*$AM2+$AN2)*(1+$AU2)*(1+$AV2)+(($AX2+$AY2)/2*IF($G$1="鸣金",$AO2,$AM2)+IF($G$1="鸣金",$AP2*1.5,0))*(1+$AZ2)*(1+$BA2)+(($BB2+$BC2)/2*IF($G$1="裂石",$AO2,$AM2)+IF($G$1="裂石",$AP2*1.5,0))*(1+$BD2)*(1+$BE2)+(($BF2+$BG2)/2*IF($G$1="牵丝",$AO2,$AM2)+IF($G$1="牵丝",$AP2*1.5,0))*(1+$BH2)*(1+$BI2)+(($BJ2+$BK2)/2*IF($G$1="破竹",$AO2,$AM2)+IF($G$1="破竹",$AP2*1.5,0))*(1+$BL2)*(1+$BM2))*(1+$AQ2)*$P2*(1+IF(VLOOKUP($Q2,武学奇术!$A:$ZZ,30,FALSE)="特殊技",$B$21,0))*(1+$BV2) -> 22104.156 | O2: =((($AS2*$AM2+$AN2)*(1+$AU2)*(1+$AV2)+($AX2*IF($G$1="鸣金",$AO2,$AM2)+IF($G$1="鸣金",$AP2*1.5,0))*(1+$AZ2)*(1+$BA2)+($BB2*IF($G$1="裂石",$AO2,$AM2)+IF($G$1="裂石",$AP2*1.5,0))*(1+$BD2)*(1+$BE2)+($BF2*IF($G$1="牵丝",$AO2,$AM2)+IF($G$1="牵丝",$AP2*1.5,0))*(1+$BH2)*(1+$BI2)+($BJ2*IF($G$1="破竹",$AO2,$AM2)+IF($G$1="破竹",$AP2*1.5,0))*(1+$BL2)*(1+$BM2))*(1+$AQ2))*$P2*(1+IF(VLOOKUP($Q2,武学奇术!$A:$ZZ,30,FALSE)="特殊技",$B$21,0))*(1+$BV2) -> 19282.457 | P2: 1 | Q2: 萧呤千浪流星 | R2: 易水歌1层 | S2: 沧海帖1层 | T2: 烁鼓 | U2: 中程笛 | V2: 裁云 | W2: N/a | X2: N/a | Y2: N/a | Z2: N/a | AA2: N/a | AB2: N/a | AC2: N/a | AD2: N/a | AE2: N/a | AF2: 无惧 | AG2: N/a | AH2: N/a | AI2: N/a | AJ2: N/a | AK2: 离猎(拐) | AL2: =VLOOKUP($Q2,武学奇术!$A:$ZZ,25,FALSE) -> 群体奇术 | AM2: =VLOOKUP($Q2,武学奇术!$A:$ZZ,26,FALSE) -> 1.4904 | AN2: =VLOOKUP($Q2,武学奇术!$A:$ZZ,27,FALSE)*(1+IF(OR($AL2=$F$4,$AL2=$F$5),$B$22,0)) -> 378 | AO2: =VLOOKUP($Q2,武学奇术!$A:$ZZ,28,FALSE) -> 2.2356 | AP2: =VLOOKUP($Q2,武学奇术!$A:$ZZ,29,FALSE)*(1+IF(OR($AL2=$F$4,$AL2=$F$5),$B$22,0)) -> 0 | AQ2: {=$G$3+IFERROR(VLOOKUP($AL2,$F$4:$G$7,2,FALSE),0)+VLOOKUP($Q2,武学奇术!$A:$ZZ,2,FALSE)+SUM(_xlfn.XLOOKUP($R2:$AK2,增益!$A:$A,增益!$B:$B,0))} -> 0.3187 | AR2: {=VLOOKUP($Q2,武学奇术!$A:$ZZ,5,FALSE)+SUM(_xlfn.XLOOKUP($R2:$AK2,增益!$A:$A,增益!$E:$E,0))} -> 0.18 | AS2: {=$D$10*(1+$AR2)+VLOOKUP($Q2,武学奇术!$A:$ZZ,3,FALSE)+SUM(_xlfn.XLOOKUP($R2:$AK2,增益!$A:$A,增益!$C:$C,0))-$I$2} -> 4434.698 | AT2: {=$E$10*(1+$AR2)+VLOOKUP($Q2,武学奇术!$A:$ZZ,4,FALSE)+SUM(_xlfn.XLOOKUP($R2:$AK2,增益!$A:$A,增益!$D:$D,0))-$I$2} -> 4434.698 | AU2: {=IF($F$10-$I$3+VLOOKUP($Q2,武学奇术!$A:$ZZ,6,FALSE)+SUM(_xlfn.XLOOKUP($R2:$AK2,增益!$A:$A,增益!$F:$F,0))>0,($F$10-$I$3+VLOOKUP($Q2,武学奇术!$A:$ZZ,6,FALSE)+SUM(_xlfn.XLOOKUP($R2:$AK2,增益!$A:$A,增益!$F:$F,0)))/200,($F$10-$I$3+VLOOKUP($Q2,武学奇术!$A:$ZZ,6,FALSE)+SUM(_xlfn.XLOOKUP($R2:$AK2,增益!$A:$A,增益!$F:$F,0)))/100)} -> 0.317 | AV2: {=$G$10+VLOOKUP($Q2,武学奇术!$A:$ZZ,7,FALSE)+SUM(_xlfn.XLOOKUP($R2:$AK2,增益!$A:$A,增益!$G:$G,0))} -> 0.205 | AW2: {=VLOOKUP($Q2,武学奇术!$A:$ZZ,8,FALSE)+SUM(_xlfn.XLOOKUP($R2:$AK2,增益!$A:$A,增益!$H:$H,0))} -> 0.18 | AX2: =$D$11*(1+$AW2) -> 0 | AY2: =$E$11*(1+$AW2) -> 0 | AZ2: {=IF($F$11-$I$4+VLOOKUP($Q2,武学奇术!$A:$ZZ,9,FALSE)+SUM(_xlfn.XLOOKUP($R2:$AK2,增益!$A:$A,增益!$I:$I,0))>0,($F$11-$I$4+VLOOKUP($Q2,武学奇术!$A:$ZZ,9,FALSE)+SUM(_xlfn.XLOOKUP($R2:$AK2,增益!$A:$A,增益!$I:$I,0)))/200,($F$11-$I$4+VLOOKUP($Q2,武学奇术!$A:$ZZ,9,FALSE)+SUM(_xlfn.XLOOKUP($R2:$AK2,增益!$A:$A,增益!$I:$I,0)))/100)} -> -0.22 | BA2: {=$G$11+VLOOKUP($Q2,武学奇术!$A:$ZZ,10,FALSE)+SUM(_xlfn.XLOOKUP($R2:$AK2,增益!$A:$A,增益!$J:$J,0))} -> 0.06 | BB2: =$D$12*(1+$AW2) -> 0 | BC2: =$E$12*(1+$AW2) -> 0 | BD2: {=IF($F$12-$I$4+VLOOKUP($Q2,武学奇术!$A:$ZZ,11,FALSE)+SUM(_xlfn.XLOOKUP($R2:$AK2,增益!$A:$A,增益!$K:$K,0))>0,($F$12-$I$4+VLOOKUP($Q2,武学奇术!$A:$ZZ,11,FALSE)+SUM(_xlfn.XLOOKUP($R2:$AK2,增益!$A:$A,增益!$K:$K,0)))/200,($F$12-$I$4+VLOOKUP($Q2,武学奇术!$A:$ZZ,11,FALSE)+SUM(_xlfn.XLOOKUP($R2:$AK2,增益!$A:$A,增益!$K:$K,0)))/100)} -> -0.22 | BE2: {=$G$12+VLOOKUP($Q2,武学奇术!$A:$ZZ,12,FALSE)+SUM(_xlfn.XLOOKUP($R2:$AK2,增益!$A:$A,增益!$L:$L,0))} -> 0.06 | BF2: =$D$13*(1+$AW2) -> 674.016 | BG2: =$E$13*(1+$AW2) -> 1920.804 | BH2: {=IF($F$13-$I$4+VLOOKUP($Q2,武学奇术!$A:$ZZ,13,FALSE)+SUM(_xlfn.XLOOKUP($R2:$AK2,增益!$A:$A,增益!$M:$M,0))>0,($F$13-$I$4+VLOOKUP($Q2,武学奇术!$A:$ZZ,13,FALSE)+SUM(_xlfn.XLOOKUP($R2:$AK2,增益!$A:$A,增益!$K:$K,0)))/200,($F$13-$I$4+VLOOKUP($Q2,武学奇术!$A:$ZZ,13,FALSE)+SUM(_xlfn.XLOOKUP($R2:$AK2,增益!$A:$A,增益!$M:$M,0)))/100)} -> 0.04 | BI2: {=$G$13+VLOOKUP($Q2,武学奇术!$A:$ZZ,14,FALSE)+SUM(_xlfn.XLOOKUP($R2:$AK2,增益!$A:$A,增益!$N:$N,0))} -> 0.33 | BJ2: =$D$14*(1+$AW2) -> 0 | BK2: =$E$14*(1+$AW2) -> 0 | BL2: {=IF($F$14-$I$4+VLOOKUP($Q2,武学奇术!$A:$ZZ,15,FALSE)+SUM(_xlfn.XLOOKUP($R2:$AK2,增益!$A:$A,增益!$O:$O,0))>0,($F$14-$I$4+VLOOKUP($Q2,武学奇术!$A:$ZZ,15,FALSE)+SUM(_xlfn.XLOOKUP($R2:$AK2,增益!$A:$A,增益!$O:$O,0)))/200,($F$14-$I$4+VLOOKUP($Q2,武学奇术!$A:$ZZ,15,FALSE)+SUM(_xlfn.XLOOKUP($R2:$AK2,增益!$A:$A,增益!$O:$O,0)))/100)} -> -0.22 | BM2: {=$G$14+VLOOKUP($Q2,武学奇术!$A:$ZZ,16,FALSE)+SUM(_xlfn.XLOOKUP($R2:$AK2,增益!$A:$A,增益!$P:$P,0))} -> 0.06 | BN2: =MIN(IF(VLOOKUP($Q2,武学奇术!$A:$ZZ,23,FALSE)=1,100%,$B$8),100%) -> 0.9859 | BO2: {=IF(VLOOKUP($Q2,武学奇术!$A:$ZZ,23,FALSE)=1,100%,MIN(80%,$B$9+VLOOKUP($Q2,武学奇术!$A:$ZZ,17,FALSE)+SUM(_xlfn.XLOOKUP($R2:$AK2,增益!$A:$A,增益!$Q:$Q,0)))+$B$11+SUM(_xlfn.XLOOKUP($R2:$AK2,增益!$A:$A,增益!$U:$U,0)))*IF(VLOOKUP($Q2,武学奇术!$A:$ZZ,24,FALSE)=1,0,1)} -> 0.8912 | BP2: {=1+$B$13+VLOOKUP($Q2,武学奇术!$A:$ZZ,18,FALSE)+SUM(_xlfn.XLOOKUP($R2:$AK2,增益!$A:$A,增益!$R:$R,0))} -> 1.55 | BQ2: {=IF(VLOOKUP($Q2,武学奇术!$A:$ZZ,24,FALSE)=1,100%,MIN(40%,$B$10+VLOOKUP($Q2,武学奇术!$A:$ZZ,19,FALSE)+SUM(_xlfn.XLOOKUP($R2:$AK2,增益!$A:$A,增益!$S:$S,0)))+$B$12+SUM(_xlfn.XLOOKUP($R2:$AK2,增益!$A:$A,增益!$V:$V,0)))*IF(VLOOKUP($Q2,武学奇术!$A:$ZZ,23,FALSE)=1,0,1)} -> 0.0929 | BR2: {=1+$B$14+VLOOKUP($Q2,武学奇术!$A:$ZZ,20,FALSE)+SUM(_xlfn.XLOOKUP($R2:$AK2,增益!$A:$A,增益!$T:$T,0))} -> 1.35 | BS2: =MIN((1-BQ2)*BN2,BN2*BO2) -> 0.87863408 | BT2: =1-BQ2-BS2-BU2 -> 0.01567581 | BU2: =IF(VLOOKUP($Q2,武学奇术!$A:$ZZ,22,FALSE)=1,0,(1-$BN2))*(1-$BQ2) -> 0.01279011 | BV2: {=SUM(_xlfn.XLOOKUP($R2:$AK2,增益!$A:$A,增益!$W:$W,0))+$I$5} -> 0.11
A3: 鸣金 | F3: 通用增伤 | G3: =B16+1.5%+IF($D$16="√",8%,0)+IF($E$24="征人归",8%,0) -> 0.1837 | H3: 外抗 | I3: =25-IF(D17="√",10,0)-IF(F17="√",10,0) -> 5 | K3: =($L3*$BS3+$M3*$BQ3+$N3*$BT3+$O3*$BU3) -> 35182.507 | L3: =((($AS3+$AT3)/2*$AM3+$AN3)*(1+$AU3)*(1+$AV3)+(($AX3+$AY3)/2*IF($G$1="鸣金",$AO3,$AM3)+IF($G$1="鸣金",$AP3*1.5,0))*(1+$AZ3)*(1+$BA3)+(($BB3+$BC3)/2*IF($G$1="裂石",$AO3,$AM3)+IF($G$1="裂石",$AP3*1.5,0))*(1+$BD3)*(1+$BE3)+(($BF3+$BG3)/2*IF($G$1="牵丝",$AO3,$AM3)+IF($G$1="牵丝",$AP3*1.5,0))*(1+$BH3)*(1+$BI3)+(($BJ3+$BK3)/2*IF($G$1="破竹",$AO3,$AM3)+IF($G$1="破竹",$AP3*1.5,0))*(1+$BL3)*(1+$BM3))*(1+$AQ3)*$BP3*$P3*(1+IF(VLOOKUP($Q3,武学奇术!$A:$ZZ,30,FALSE)="特殊技",$B$21,0))*(1+$BV3) -> 35647.743 | M3: =(($AT3*$AM3+$AN3)*(1+$AU3)*(1+$AV3)+($AY3*IF($G$1="鸣金",$AO3,$AM3)+IF($G$1="鸣金",$AP3*1.5,0))*(1+$AZ3)*(1+$BA3)+($BC3*IF($G$1="裂石",$AO3,$AM3)+IF($G$1="裂石",$AP3*1.5,0))*(1+$BD3)*(1+$BE3)+($BG3*IF($G$1="牵丝",$AO3,$AM3)+IF($G$1="牵丝",$AP3*1.5,0))*(1+$BH3)*(1+$BI3)+($BK3*IF($G$1="破竹",$AO3,$AM3)+IF($G$1="破竹",$AP3*1.5,0))*(1+$BL3)*(1+$BM3))*(1+$AQ3)*$BR3*$P3*(1+IF(VLOOKUP($Q3,武学奇术!$A:$ZZ,30,FALSE)="特殊技",$B$21,0))*(1+$BV3) -> 34982.433 | N3: =((($AS3+$AT3)/2*$AM3+$AN3)*(1+$AU3)*(1+$AV3)+(($AX3+$AY3)/2*IF($G$1="鸣金",$AO3,$AM3)+IF($G$1="鸣金",$AP3*1.5,0))*(1+$AZ3)*(1+$BA3)+(($BB3+$BC3)/2*IF($G$1="裂石",$AO3,$AM3)+IF($G$1="裂石",$AP3*1.5,0))*(1+$BD3)*(1+$BE3)+(($BF3+$BG3)/2*IF($G$1="牵丝",$AO3,$AM3)+IF($G$1="牵丝",$AP3*1.5,0))*(1+$BH3)*(1+$BI3)+(($BJ3+$BK3)/2*IF($G$1="破竹",$AO3,$AM3)+IF($G$1="破竹",$AP3*1.5,0))*(1+$BL3)*(1+$BM3))*(1+$AQ3)*$P3*(1+IF(VLOOKUP($Q3,武学奇术!$A:$ZZ,30,FALSE)="特殊技",$B$21,0))*(1+$BV3) -> 22851.117 | O3: =((($AS3*$AM3+$AN3)*(1+$AU3)*(1+$AV3)+($AX3*IF($G$1="鸣金",$AO3,$AM3)+IF($G$1="鸣金",$AP3*1.5,0))*(1+$AZ3)*(1+$BA3)+($BB3*IF($G$1="裂石",$AO3,$AM3)+IF($G$1="裂石",$AP3*1.5,0))*(1+$BD3)*(1+$BE3)+($BF3*IF($G$1="牵丝",$AO3,$AM3)+IF($G$1="牵丝",$AP3*1.5,0))*(1+$BH3)*(1+$BI3)+($BJ3*IF($G$1="破竹",$AO3,$AM3)+IF($G$1="破竹",$AP3*1.5,0))*(1+$BL3)*(1+$BM3))*(1+$AQ3))*$P3*(1+IF(VLOOKUP($Q3,武学奇术!$A:$ZZ,30,FALSE)="特殊技",$B$21,0))*(1+$BV3) -> 19789.321 | P3: 1 | Q3: 萧呤千浪流星 | R3: 易水歌2层 | S3: 沧海帖2层 | T3: 烁鼓 | U3: 中程笛 | V3: 裁云 | W3: N/a | X3: 惧刃(拐) | Y3: N/a | Z3: N/a | AA3: N/a | AB3: N/a | AC3: N/a | AD3: N/a | AE3: N/a | AF3: 无惧 | AG3: N/a | AH3: N/a | AI3: N/a | AJ3: N/a | AK3: 离猎(拐) | AL3: =VLOOKUP($Q3,武学奇术!$A:$ZZ,25,FALSE) -> 群体奇术 | AM3: =VLOOKUP($Q3,武学奇术!$A:$ZZ,26,FALSE) -> 1.4904 | AN3: =VLOOKUP($Q3,武学奇术!$A:$ZZ,27,FALSE)*(1+IF(OR($AL3=$F$4,$AL3=$F$5),$B$22,0)) -> 378 | AO3: =VLOOKUP($Q3,武学奇术!$A:$ZZ,28,FALSE) -> 2.2356 | AP3: =VLOOKUP($Q3,武学奇术!$A:$ZZ,29,FALSE)*(1+IF(OR($AL3=$F$4,$AL3=$F$5),$B$22,0)) -> 0 | AQ3: {=$G$3+IFERROR(VLOOKUP($AL3,$F$4:$G$7,2,FALSE),0)+VLOOKUP($Q3,武学奇术!$A:$ZZ,2,FALSE)+SUM(_xlfn.XLOOKUP($R3:$AK3,增益!$A:$A,增益!$B:$B,0))} -> 0.3287 | AR3: {=VLOOKUP($Q3,武学奇术!$A:$ZZ,5,FALSE)+SUM(_xlfn.XLOOKUP($R3:$AK3,增益!$A:$A,增益!$E:$E,0))} -> 0.18 | AS3: {=$D$10*(1+$AR3)+VLOOKUP($Q3,武学奇术!$A:$ZZ,3,FALSE)+SUM(_xlfn.XLOOKUP($R3:$AK3,增益!$A:$A,增益!$C:$C,0))-$I$2} -> 4434.698 | AT3: {=$E$10*(1+$AR3)+VLOOKUP($Q3,武学奇术!$A:$ZZ,4,FALSE)+SUM(_xlfn.XLOOKUP($R3:$AK3,增益!$A:$A,增益!$D:$D,0))-$I$2} -> 4434.698 | AU3: {=IF($F$10-$I$3+VLOOKUP($Q3,武学奇术!$A:$ZZ,6,FALSE)+SUM(_xlfn.XLOOKUP($R3:$AK3,增益!$A:$A,增益!$F:$F,0))>0,($F$10-$I$3+VLOOKUP($Q3,武学奇术!$A:$ZZ,6,FALSE)+SUM(_xlfn.XLOOKUP($R3:$AK3,增益!$A:$A,增益!$F:$F,0)))/200,($F$10-$I$3+VLOOKUP($Q3,武学奇术!$A:$ZZ,6,FALSE)+SUM(_xlfn.XLOOKUP($R3:$AK3,增益!$A:$A,增益!$F:$F,0)))/100)} -> 0.327 | AV3: {=$G$10+VLOOKUP($Q3,武学奇术!$A:$ZZ,7,FALSE)+SUM(_xlfn.XLOOKUP($R3:$AK3,增益!$A:$A,增益!$G:$G,0))} -> 0.205 | AW3: {=VLOOKUP($Q3,武学奇术!$A:$ZZ,8,FALSE)+SUM(_xlfn.XLOOKUP($R3:$AK3,增益!$A:$A,增益!$H:$H,0))} -> 0.18 | AX3: =$D$11*(1+$AW3) -> 0 | AY3: =$E$11*(1+$AW3) -> 0 | AZ3: {=IF($F$11-$I$4+VLOOKUP($Q3,武学奇术!$A:$ZZ,9,FALSE)+SUM(_xlfn.XLOOKUP($R3:$AK3,增益!$A:$A,增益!$I:$I,0))>0,($F$11-$I$4+VLOOKUP($Q3,武学奇术!$A:$ZZ,9,FALSE)+SUM(_xlfn.XLOOKUP($R3:$AK3,增益!$A:$A,增益!$I:$I,0)))/200,($F$11-$I$4+VLOOKUP($Q3,武学奇术!$A:$ZZ,9,FALSE)+SUM(_xlfn.XLOOKUP($R3:$AK3,增益!$A:$A,增益!$I:$I,0)))/100)} -> -0.06 | BA3: {=$G$11+VLOOKUP($Q3,武学奇术!$A:$ZZ,10,FALSE)+SUM(_xlfn.XLOOKUP($R3:$AK3,增益!$A:$A,增益!$J:$J,0))} -> 0.06 | BB3: =$D$12*(1+$AW3) -> 0 | BC3: =$E$12*(1+$AW3) -> 0 | BD3: {=IF($F$12-$I$4+VLOOKUP($Q3,武学奇术!$A:$ZZ,11,FALSE)+SUM(_xlfn.XLOOKUP($R3:$AK3,增益!$A:$A,增益!$K:$K,0))>0,($F$12-$I$4+VLOOKUP($Q3,武学奇术!$A:$ZZ,11,FALSE)+SUM(_xlfn.XLOOKUP($R3:$AK3,增益!$A:$A,增益!$K:$K,0)))/200,($F$12-$I$4+VLOOKUP($Q3,武学奇术!$A:$ZZ,11,FALSE)+SUM(_xlfn.XLOOKUP($R3:$AK3,增益!$A:$A,增益!$K:$K,0)))/100)} -> -0.06 | BE3: {=$G$12+VLOOKUP($Q3,武学奇术!$A:$ZZ,12,FALSE)+SUM(_xlfn.XLOOKUP($R3:$AK3,增益!$A:$A,增益!$L:$L,0))} -> 0.06 | BF3: =$D$13*(1+$AW3) -> 674.016 | BG3: =$E$13*(1+$AW3) -> 1920.804 | BH3: {=IF($F$13-$I$4+VLOOKUP($Q3,武学奇术!$A:$ZZ,13,FALSE)+SUM(_xlfn.XLOOKUP($R3:$AK3,增益!$A:$A,增益!$M:$M,0))>0,($F$13-$I$4+VLOOKUP($Q3,武学奇术!$A:$ZZ,13,FALSE)+SUM(_xlfn.XLOOKUP($R3:$AK3,增益!$A:$A,增益!$K:$K,0)))/200,($F$13-$I$4+VLOOKUP($Q3,武学奇术!$A:$ZZ,13,FALSE)+SUM(_xlfn.XLOOKUP($R3:$AK3,增益!$A:$A,增益!$M:$M,0)))/100)} -> 0.12 | BI3: {=$G$13+VLOOKUP($Q3,武学奇术!$A:$ZZ,14,FALSE)+SUM(_xlfn.XLOOKUP($R3:$AK3,增益!$A:$A,增益!$N:$N,0))} -> 0.33 | BJ3: =$D$14*(1+$AW3) -> 0 | BK3: =$E$14*(1+$AW3) -> 0 | BL3: {=IF($F$14-$I$4+VLOOKUP($Q3,武学奇术!$A:$ZZ,15,FALSE)+SUM(_xlfn.XLOOKUP($R3:$AK3,增益!$A:$A,增益!$O:$O,0))>0,($F$14-$I$4+VLOOKUP($Q3,武学奇术!$A:$ZZ,15,FALSE)+SUM(_xlfn.XLOOKUP($R3:$AK3,增益!$A:$A,增益!$O:$O,0)))/200,($F$14-$I$4+VLOOKUP($Q3,武学奇术!$A:$ZZ,15,FALSE)+SUM(_xlfn.XLOOKUP($R3:$AK3,增益!$A:$A,增益!$O:$O,0)))/100)} -> -0.06 | BM3: {=$G$14+VLOOKUP($Q3,武学奇术!$A:$ZZ,16,FALSE)+SUM(_xlfn.XLOOKUP($R3:$AK3,增益!$A:$A,增益!$P:$P,0))} -> 0.06 | BN3: =MIN(IF(VLOOKUP($Q3,武学奇术!$A:$ZZ,23,FALSE)=1,100%,$B$8),100%) -> 0.9859 | BO3: {=IF(VLOOKUP($Q3,武学奇术!$A:$ZZ,23,FALSE)=1,100%,MIN(80%,$B$9+VLOOKUP($Q3,武学奇术!$A:$ZZ,17,FALSE)+SUM(_xlfn.XLOOKUP($R3:$AK3,增益!$A:$A,增益!$Q:$Q,0)))+$B$11+SUM(_xlfn.XLOOKUP($R3:$AK3,增益!$A:$A,增益!$U:$U,0)))*IF(VLOOKUP($Q3,武学奇术!$A:$ZZ,24,FALSE)=1,0,1)} -> 0.8912 | BP3: {=1+$B$13+VLOOKUP($Q3,武学奇术!$A:$ZZ,18,FALSE)+SUM(_xlfn.XLOOKUP($R3:$AK3,增益!$A:$A,增益!$R:$R,0))} -> 1.56 | BQ3: {=IF(VLOOKUP($Q3,武学奇术!$A:$ZZ,24,FALSE)=1,100%,MIN(40%,$B$10+VLOOKUP($Q3,武学奇术!$A:$ZZ,19,FALSE)+SUM(_xlfn.XLOOKUP($R3:$AK3,增益!$A:$A,增益!$S:$S,0)))+$B$12+SUM(_xlfn.XLOOKUP($R3:$AK3,增益!$A:$A,增益!$V:$V,0)))*IF(VLOOKUP($Q3,武学奇术!$A:$ZZ,23,FALSE)=1,0,1)} -> 0.0929 | BR3: {=1+$B$14+VLOOKUP($Q3,武学奇术!$A:$ZZ,20,FALSE)+SUM(_xlfn.XLOOKUP($R3:$AK3,增益!$A:$A,增益!$T:$T,0))} -> 1.35 | BS3: =MIN((1-BQ3)*BN3,BN3*BO3) -> 0.87863408 | BT3: =1-BQ3-BS3-BU3 -> 0.01567581 | BU3: =IF(VLOOKUP($Q3,武学奇术!$A:$ZZ,22,FALSE)=1,0,(1-$BN3))*(1-$BQ3) -> 0.01279011 | BV3: {=SUM(_xlfn.XLOOKUP($R3:$AK3,增益!$A:$A,增益!$W:$W,0))+$I$5} -> 0.11
A4: 裂石 | F4: 鼓 | G4: =B15+B17 -> 0.1704 | H4: 属抗 | I4: =30 -> 30 | K4: =($L4*$BS4+$M4*$BQ4+$N4*$BT4+$O4*$BU4) -> 35841.43 | L4: =((($AS4+$AT4)/2*$AM4+$AN4)*(1+$AU4)*(1+$AV4)+(($AX4+$AY4)/2*IF($G$1="鸣金",$AO4,$AM4)+IF($G$1="鸣金",$AP4*1.5,0))*(1+$AZ4)*(1+$BA4)+(($BB4+$BC4)/2*IF($G$1="裂石",$AO4,$AM4)+IF($G$1="裂石",$AP4*1.5,0))*(1+$BD4)*(1+$BE4)+(($BF4+$BG4)/2*IF($G$1="牵丝",$AO4,$AM4)+IF($G$1="牵丝",$AP4*1.5,0))*(1+$BH4)*(1+$BI4)+(($BJ4+$BK4)/2*IF($G$1="破竹",$AO4,$AM4)+IF($G$1="破竹",$AP4*1.5,0))*(1+$BL4)*(1+$BM4))*(1+$AQ4)*$BP4*$P4*(1+IF(VLOOKUP($Q4,武学奇术!$A:$ZZ,30,FALSE)="特殊技",$B$21,0))*(1+$BV4) -> 36342.697 | M4: =(($AT4*$AM4+$AN4)*(1+$AU4)*(1+$AV4)+($AY4*IF($G$1="鸣金",$AO4,$AM4)+IF($G$1="鸣金",$AP4*1.5,0))*(1+$AZ4)*(1+$BA4)+($BC4*IF($G$1="裂石",$AO4,$AM4)+IF($G$1="裂石",$AP4*1.5,0))*(1+$BD4)*(1+$BE4)+($BG4*IF($G$1="牵丝",$AO4,$AM4)+IF($G$1="牵丝",$AP4*1.5,0))*(1+$BH4)*(1+$BI4)+($BK4*IF($G$1="破竹",$AO4,$AM4)+IF($G$1="破竹",$AP4*1.5,0))*(1+$BL4)*(1+$BM4))*(1+$AQ4)*$BR4*$P4*(1+IF(VLOOKUP($Q4,武学奇术!$A:$ZZ,30,FALSE)="特殊技",$B$21,0))*(1+$BV4) -> 35414.623 | N4: =((($AS4+$AT4)/2*$AM4+$AN4)*(1+$AU4)*(1+$AV4)+(($AX4+$AY4)/2*IF($G$1="鸣金",$AO4,$AM4)+IF($G$1="鸣金",$AP4*1.5,0))*(1+$AZ4)*(1+$BA4)+(($BB4+$BC4)/2*IF($G$1="裂石",$AO4,$AM4)+IF($G$1="裂石",$AP4*1.5,0))*(1+$BD4)*(1+$BE4)+(($BF4+$BG4)/2*IF($G$1="牵丝",$AO4,$AM4)+IF($G$1="牵丝",$AP4*1.5,0))*(1+$BH4)*(1+$BI4)+(($BJ4+$BK4)/2*IF($G$1="破竹",$AO4,$AM4)+IF($G$1="破竹",$AP4*1.5,0))*(1+$BL4)*(1+$BM4))*(1+$AQ4)*$P4*(1+IF(VLOOKUP($Q4,武学奇术!$A:$ZZ,30,FALSE)="特殊技",$B$21,0))*(1+$BV4) -> 23148.214 | O4: =((($AS4*$AM4+$AN4)*(1+$AU4)*(1+$AV4)+($AX4*IF($G$1="鸣金",$AO4,$AM4)+IF($G$1="鸣金",$AP4*1.5,0))*(1+$AZ4)*(1+$BA4)+($BB4*IF($G$1="裂石",$AO4,$AM4)+IF($G$1="裂石",$AP4*1.5,0))*(1+$BD4)*(1+$BE4)+($BF4*IF($G$1="牵丝",$AO4,$AM4)+IF($G$1="牵丝",$AP4*1.5,0))*(1+$BH4)*(1+$BI4)+($BJ4*IF($G$1="破竹",$AO4,$AM4)+IF($G$1="破竹",$AP4*1.5,0))*(1+$BL4)*(1+$BM4))*(1+$AQ4))*$P4*(1+IF(VLOOKUP($Q4,武学奇术!$A:$ZZ,30,FALSE)="特殊技",$B$21,0))*(1+$BV4) -> 20063.374 | P4: 1 | Q4: 萧呤千浪流星 | R4: 易水歌3层 | S4: 沧海帖3层 | T4: 烁鼓 | U4: 中程笛 | V4: 裁云 | W4: N/a | X4: 惧刃(拐) | Y4: N/a | Z4: N/a | AA4: N/a | AB4: N/a | AC4: N/a | AD4: N/a | AE4: N/a | AF4: 无惧 | AG4: N/a | AH4: N/a | AI4: N/a | AJ4: N/a | AK4: 离猎(拐) | AL4: =VLOOKUP($Q4,武学奇术!$A:$ZZ,25,FALSE) -> 群体奇术 | AM4: =VLOOKUP($Q4,武学奇术!$A:$ZZ,26,FALSE) -> 1.4904 | AN4: =VLOOKUP($Q4,武学奇术!$A:$ZZ,27,FALSE)*(1+IF(OR($AL4=$F$4,$AL4=$F$5),$B$22,0)) -> 378 | AO4: =VLOOKUP($Q4,武学奇术!$A:$ZZ,28,FALSE) -> 2.2356 | AP4: =VLOOKUP($Q4,武学奇术!$A:$ZZ,29,FALSE)*(1+IF(OR($AL4=$F$4,$AL4=$F$5),$B$22,0)) -> 0 | AQ4: {=$G$3+IFERROR(VLOOKUP($AL4,$F$4:$G$7,2,FALSE),0)+VLOOKUP($Q4,武学奇术!$A:$ZZ,2,FALSE)+SUM(_xlfn.XLOOKUP($R4:$AK4,增益!$A:$A,增益!$B:$B,0))} -> 0.3387 | AR4: {=VLOOKUP($Q4,武学奇术!$A:$ZZ,5,FALSE)+SUM(_xlfn.XLOOKUP($R4:$AK4,增益!$A:$A,增益!$E:$E,0))} -> 0.18 | AS4: {=$D$10*(1+$AR4)+VLOOKUP($Q4,武学奇术!$A:$ZZ,3,FALSE)+SUM(_xlfn.XLOOKUP($R4:$AK4,增益!$A:$A,增益!$C:$C,0))-$I$2} -> 4434.698 | AT4: {=$E$10*(1+$AR4)+VLOOKUP($Q4,武学奇术!$A:$ZZ,4,FALSE)+SUM(_xlfn.XLOOKUP($R4:$AK4,增益!$A:$A,增益!$D:$D,0))-$I$2} -> 4434.698 | AU4: {=IF($F$10-$I$3+VLOOKUP($Q4,武学奇术!$A:$ZZ,6,FALSE)+SUM(_xlfn.XLOOKUP($R4:$AK4,增益!$A:$A,增益!$F:$F,0))>0,($F$10-$I$3+VLOOKUP($Q4,武学奇术!$A:$ZZ,6,FALSE)+SUM(_xlfn.XLOOKUP($R4:$AK4,增益!$A:$A,增益!$F:$F,0)))/200,($F$10-$I$3+VLOOKUP($Q4,武学奇术!$A:$ZZ,6,FALSE)+SUM(_xlfn.XLOOKUP($R4:$AK4,增益!$A:$A,增益!$F:$F,0)))/100)} -> 0.337 | AV4: {=$G$10+VLOOKUP($Q4,武学奇术!$A:$ZZ,7,FALSE)+SUM(_xlfn.XLOOKUP($R4:$AK4,增益!$A:$A,增益!$G:$G,0))} -> 0.205 | AW4: {=VLOOKUP($Q4,武学奇术!$A:$ZZ,8,FALSE)+SUM(_xlfn.XLOOKUP($R4:$AK4,增益!$A:$A,增益!$H:$H,0))} -> 0.18 | AX4: =$D$11*(1+$AW4) -> 0 | AY4: =$E$11*(1+$AW4) -> 0 | AZ4: {=IF($F$11-$I$4+VLOOKUP($Q4,武学奇术!$A:$ZZ,9,FALSE)+SUM(_xlfn.XLOOKUP($R4:$AK4,增益!$A:$A,增益!$I:$I,0))>0,($F$11-$I$4+VLOOKUP($Q4,武学奇术!$A:$ZZ,9,FALSE)+SUM(_xlfn.XLOOKUP($R4:$AK4,增益!$A:$A,增益!$I:$I,0)))/200,($F$11-$I$4+VLOOKUP($Q4,武学奇术!$A:$ZZ,9,FALSE)+SUM(_xlfn.XLOOKUP($R4:$AK4,增益!$A:$A,增益!$I:$I,0)))/100)} -> -0.06 | BA4: {=$G$11+VLOOKUP($Q4,武学奇术!$A:$ZZ,10,FALSE)+SUM(_xlfn.XLOOKUP($R4:$AK4,增益!$A:$A,增益!$J:$J,0))} -> 0.06 | BB4: =$D$12*(1+$AW4) -> 0 | BC4: =$E$12*(1+$AW4) -> 0 | BD4: {=IF($F$12-$I$4+VLOOKUP($Q4,武学奇术!$A:$ZZ,11,FALSE)+SUM(_xlfn.XLOOKUP($R4:$AK4,增益!$A:$A,增益!$K:$K,0))>0,($F$12-$I$4+VLOOKUP($Q4,武学奇术!$A:$ZZ,11,FALSE)+SUM(_xlfn.XLOOKUP($R4:$AK4,增益!$A:$A,增益!$K:$K,0)))/200,($F$12-$I$4+VLOOKUP($Q4,武学奇术!$A:$ZZ,11,FALSE)+SUM(_xlfn.XLOOKUP($R4:$AK4,增益!$A:$A,增益!$K:$K,0)))/100)} -> -0.06 | BE4: {=$G$12+VLOOKUP($Q4,武学奇术!$A:$ZZ,12,FALSE)+SUM(_xlfn.XLOOKUP($R4:$AK4,增益!$A:$A,增益!$L:$L,0))} -> 0.06 | BF4: =$D$13*(1+$AW4) -> 674.016 | BG4: =$E$13*(1+$AW4) -> 1920.804 | BH4: {=IF($F$13-$I$4+VLOOKUP($Q4,武学奇术!$A:$ZZ,13,FALSE)+SUM(_xlfn.XLOOKUP($R4:$AK4,增益!$A:$A,增益!$M:$M,0))>0,($F$13-$I$4+VLOOKUP($Q4,武学奇术!$A:$ZZ,13,FALSE)+SUM(_xlfn.XLOOKUP($R4:$AK4,增益!$A:$A,增益!$K:$K,0)))/200,($F$13-$I$4+VLOOKUP($Q4,武学奇术!$A:$ZZ,13,FALSE)+SUM(_xlfn.XLOOKUP($R4:$AK4,增益!$A:$A,增益!$M:$M,0)))/100)} -> 0.12 | BI4: {=$G$13+VLOOKUP($Q4,武学奇术!$A:$ZZ,14,FALSE)+SUM(_xlfn.XLOOKUP($R4:$AK4,增益!$A:$A,增益!$N:$N,0))} -> 0.33 | BJ4: =$D$14*(1+$AW4) -> 0 | BK4: =$E$14*(1+$AW4) -> 0 | BL4: {=IF($F$14-$I$4+VLOOKUP($Q4,武学奇术!$A:$ZZ,15,FALSE)+SUM(_xlfn.XLOOKUP($R4:$AK4,增益!$A:$A,增益!$O:$O,0))>0,($F$14-$I$4+VLOOKUP($Q4,武学奇术!$A:$ZZ,15,FALSE)+SUM(_xlfn.XLOOKUP($R4:$AK4,增益!$A:$A,增益!$O:$O,0)))/200,($F$14-$I$4+VLOOKUP($Q4,武学奇术!$A:$ZZ,15,FALSE)+SUM(_xlfn.XLOOKUP($R4:$AK4,增益!$A:$A,增益!$O:$O,0)))/100)} -> -0.06 | BM4: {=$G$14+VLOOKUP($Q4,武学奇术!$A:$ZZ,16,FALSE)+SUM(_xlfn.XLOOKUP($R4:$AK4,增益!$A:$A,增益!$P:$P,0))} -> 0.06 | BN4: =MIN(IF(VLOOKUP($Q4,武学奇术!$A:$ZZ,23,FALSE)=1,100%,$B$8),100%) -> 0.9859 | BO4: {=IF(VLOOKUP($Q4,武学奇术!$A:$ZZ,23,FALSE)=1,100%,MIN(80%,$B$9+VLOOKUP($Q4,武学奇术!$A:$ZZ,17,FALSE)+SUM(_xlfn.XLOOKUP($R4:$AK4,增益!$A:$A,增益!$Q:$Q,0)))+$B$11+SUM(_xlfn.XLOOKUP($R4:$AK4,增益!$A:$A,增益!$U:$U,0)))*IF(VLOOKUP($Q4,武学奇术!$A:$ZZ,24,FALSE)=1,0,1)} -> 0.8912 | BP4: {=1+$B$13+VLOOKUP($Q4,武学奇术!$A:$ZZ,18,FALSE)+SUM(_xlfn.XLOOKUP($R4:$AK4,增益!$A:$A,增益!$R:$R,0))} -> 1.57 | BQ4: {=IF(VLOOKUP($Q4,武学奇术!$A:$ZZ,24,FALSE)=1,100%,MIN(40%,$B$10+VLOOKUP($Q4,武学奇术!$A:$ZZ,19,FALSE)+SUM(_xlfn.XLOOKUP($R4:$AK4,增益!$A:$A,增益!$S:$S,0)))+$B$12+SUM(_xlfn.XLOOKUP($R4:$AK4,增益!$A:$A,增益!$V:$V,0)))*IF(VLOOKUP($Q4,武学奇术!$A:$ZZ,23,FALSE)=1,0,1)} -> 0.0929 | BR4: {=1+$B$14+VLOOKUP($Q4,武学奇术!$A:$ZZ,20,FALSE)+SUM(_xlfn.XLOOKUP($R4:$AK4,增益!$A:$A,增益!$T:$T,0))} -> 1.35 | BS4: =MIN((1-BQ4)*BN4,BN4*BO4) -> 0.87863408 | BT4: =1-BQ4-BS4-BU4 -> 0.01567581 | BU4: =IF(VLOOKUP($Q4,武学奇术!$A:$ZZ,22,FALSE)=1,0,(1-$BN4))*(1-$BQ4) -> 0.01279011 | BV4: {=SUM(_xlfn.XLOOKUP($R4:$AK4,增益!$A:$A,增益!$W:$W,0))+$I$5} -> 0.11
A5: 牵丝 | B5: 492 | C5: 1397.8 | D5: 30 | E5: 0.15 | F5: 扇 | G5: =B15+B18 -> 0.0852 | H5: 副本天赋 | I5: 0.06 | K5: =($L5*$BS5+$M5*$BQ5+$N5*$BT5+$O5*$BU5) -> 31730.03 | L5: =((($AS5+$AT5)/2*$AM5+$AN5)*(1+$AU5)*(1+$AV5)+(($AX5+$AY5)/2*IF($G$1="鸣金",$AO5,$AM5)+IF($G$1="鸣金",$AP5*1.5,0))*(1+$AZ5)*(1+$BA5)+(($BB5+$BC5)/2*IF($G$1="裂石",$AO5,$AM5)+IF($G$1="裂石",$AP5*1.5,0))*(1+$BD5)*(1+$BE5)+(($BF5+$BG5)/2*IF($G$1="牵丝",$AO5,$AM5)+IF($G$1="牵丝",$AP5*1.5,0))*(1+$BH5)*(1+$BI5)+(($BJ5+$BK5)/2*IF($G$1="破竹",$AO5,$AM5)+IF($G$1="破竹",$AP5*1.5,0))*(1+$BL5)*(1+$BM5))*(1+$AQ5)*$BP5*$P5*(1+IF(VLOOKUP($Q5,武学奇术!$A:$ZZ,30,FALSE)="特殊技",$B$21,0))*(1+$BV5) -> 32168.987 | M5: =(($AT5*$AM5+$AN5)*(1+$AU5)*(1+$AV5)+($AY5*IF($G$1="鸣金",$AO5,$AM5)+IF($G$1="鸣金",$AP5*1.5,0))*(1+$AZ5)*(1+$BA5)+($BC5*IF($G$1="裂石",$AO5,$AM5)+IF($G$1="裂石",$AP5*1.5,0))*(1+$BD5)*(1+$BE5)+($BG5*IF($G$1="牵丝",$AO5,$AM5)+IF($G$1="牵丝",$AP5*1.5,0))*(1+$BH5)*(1+$BI5)+($BK5*IF($G$1="破竹",$AO5,$AM5)+IF($G$1="破竹",$AP5*1.5,0))*(1+$BL5)*(1+$BM5))*(1+$AQ5)*$BR5*$P5*(1+IF(VLOOKUP($Q5,武学奇术!$A:$ZZ,30,FALSE)="特殊技",$B$21,0))*(1+$BV5) -> 31468.465 | N5: =((($AS5+$AT5)/2*$AM5+$AN5)*(1+$AU5)*(1+$AV5)+(($AX5+$AY5)/2*IF($G$1="鸣金",$AO5,$AM5)+IF($G$1="鸣金",$AP5*1.5,0))*(1+$AZ5)*(1+$BA5)+(($BB5+$BC5)/2*IF($G$1="裂石",$AO5,$AM5)+IF($G$1="裂石",$AP5*1.5,0))*(1+$BD5)*(1+$BE5)+(($BF5+$BG5)/2*IF($G$1="牵丝",$AO5,$AM5)+IF($G$1="牵丝",$AP5*1.5,0))*(1+$BH5)*(1+$BI5)+(($BJ5+$BK5)/2*IF($G$1="破竹",$AO5,$AM5)+IF($G$1="破竹",$AP5*1.5,0))*(1+$BL5)*(1+$BM5))*(1+$AQ5)*$P5*(1+IF(VLOOKUP($Q5,武学奇术!$A:$ZZ,30,FALSE)="特殊技",$B$21,0))*(1+$BV5) -> 20360.119 | O5: =((($AS5*$AM5+$AN5)*(1+$AU5)*(1+$AV5)+($AX5*IF($G$1="鸣金",$AO5,$AM5)+IF($G$1="鸣金",$AP5*1.5,0))*(1+$AZ5)*(1+$BA5)+($BB5*IF($G$1="裂石",$AO5,$AM5)+IF($G$1="裂石",$AP5*1.5,0))*(1+$BD5)*(1+$BE5)+($BF5*IF($G$1="牵丝",$AO5,$AM5)+IF($G$1="牵丝",$AP5*1.5,0))*(1+$BH5)*(1+$BI5)+($BJ5*IF($G$1="破竹",$AO5,$AM5)+IF($G$1="破竹",$AP5*1.5,0))*(1+$BL5)*(1+$BM5))*(1+$AQ5))*$P5*(1+IF(VLOOKUP($Q5,武学奇术!$A:$ZZ,30,FALSE)="特殊技",$B$21,0))*(1+$BV5) -> 17410.263 | P5: 1 | Q5: 萧呤千浪流星 | R5: 易水歌4层 | S5: 沧海帖4层 | T5: 扶风 | U5: 中程笛 | V5: 裁云 | W5: N/a | X5: 惧刃(拐) | Y5: N/a | Z5: N/a | AA5: N/a | AB5: N/a | AC5: N/a | AD5: N/a | AE5: N/a | AF5: 无惧 | AG5: N/a | AH5: N/a | AI5: N/a | AJ5: N/a | AK5: 离猎(拐) | AL5: =VLOOKUP($Q5,武学奇术!$A:$ZZ,25,FALSE) -> 群体奇术 | AM5: =VLOOKUP($Q5,武学奇术!$A:$ZZ,26,FALSE) -> 1.4904 | AN5: =VLOOKUP($Q5,武学奇术!$A:$ZZ,27,FALSE)*(1+IF(OR($AL5=$F$4,$AL5=$F$5),$B$22,0)) -> 378 | AO5: =VLOOKUP($Q5,武学奇术!$A:$ZZ,28,FALSE) -> 2.2356 | AP5: =VLOOKUP($Q5,武学奇术!$A:$ZZ,29,FALSE)*(1+IF(OR($AL5=$F$4,$AL5=$F$5),$B$22,0)) -> 0 | AQ5: {=$G$3+IFERROR(VLOOKUP($AL5,$F$4:$G$7,2,FALSE),0)+VLOOKUP($Q5,武学奇术!$A:$ZZ,2,FALSE)+SUM(_xlfn.XLOOKUP($R5:$AK5,增益!$A:$A,增益!$B:$B,0))} -> 0.3487 | AR5: {=VLOOKUP($Q5,武学奇术!$A:$ZZ,5,FALSE)+SUM(_xlfn.XLOOKUP($R5:$AK5,增益!$A:$A,增益!$E:$E,0))} -> 0 | AS5: {=$D$10*(1+$AR5)+VLOOKUP($Q5,武学奇术!$A:$ZZ,3,FALSE)+SUM(_xlfn.XLOOKUP($R5:$AK5,增益!$A:$A,增益!$C:$C,0))-$I$2} -> 3673.1 | AT5: {=$E$10*(1+$AR5)+VLOOKUP($Q5,武学奇术!$A:$ZZ,4,FALSE)+SUM(_xlfn.XLOOKUP($R5:$AK5,增益!$A:$A,增益!$D:$D,0))-$I$2} -> 3673.1 | AU5: {=IF($F$10-$I$3+VLOOKUP($Q5,武学奇术!$A:$ZZ,6,FALSE)+SUM(_xlfn.XLOOKUP($R5:$AK5,增益!$A:$A,增益!$F:$F,0))>0,($F$10-$I$3+VLOOKUP($Q5,武学奇术!$A:$ZZ,6,FALSE)+SUM(_xlfn.XLOOKUP($R5:$AK5,增益!$A:$A,增益!$F:$F,0)))/200,($F$10-$I$3+VLOOKUP($Q5,武学奇术!$A:$ZZ,6,FALSE)+SUM(_xlfn.XLOOKUP($R5:$AK5,增益!$A:$A,增益!$F:$F,0)))/100)} -> 0.347 | AV5: {=$G$10+VLOOKUP($Q5,武学奇术!$A:$ZZ,7,FALSE)+SUM(_xlfn.XLOOKUP($R5:$AK5,增益!$A:$A,增益!$G:$G,0))} -> 0.205 | AW5: {=VLOOKUP($Q5,武学奇术!$A:$ZZ,8,FALSE)+SUM(_xlfn.XLOOKUP($R5:$AK5,增益!$A:$A,增益!$H:$H,0))} -> 0.12 | AX5: =$D$11*(1+$AW5) -> 0 | AY5: =$E$11*(1+$AW5) -> 0 | AZ5: {=IF($F$11-$I$4+VLOOKUP($Q5,武学奇术!$A:$ZZ,9,FALSE)+SUM(_xlfn.XLOOKUP($R5:$AK5,增益!$A:$A,增益!$I:$I,0))>0,($F$11-$I$4+VLOOKUP($Q5,武学奇术!$A:$ZZ,9,FALSE)+SUM(_xlfn.XLOOKUP($R5:$AK5,增益!$A:$A,增益!$I:$I,0)))/200,($F$11-$I$4+VLOOKUP($Q5,武学奇术!$A:$ZZ,9,FALSE)+SUM(_xlfn.XLOOKUP($R5:$AK5,增益!$A:$A,增益!$I:$I,0)))/100)} -> -0.06 | BA5: {=$G$11+VLOOKUP($Q5,武学奇术!$A:$ZZ,10,FALSE)+SUM(_xlfn.XLOOKUP($R5:$AK5,增益!$A:$A,增益!$J:$J,0))} -> 0.06 | BB5: =$D$12*(1+$AW5) -> 0 | BC5: =$E$12*(1+$AW5) -> 0 | BD5: {=IF($F$12-$I$4+VLOOKUP($Q5,武学奇术!$A:$ZZ,11,FALSE)+SUM(_xlfn.XLOOKUP($R5:$AK5,增益!$A:$A,增益!$K:$K,0))>0,($F$12-$I$4+VLOOKUP($Q5,武学奇术!$A:$ZZ,11,FALSE)+SUM(_xlfn.XLOOKUP($R5:$AK5,增益!$A:$A,增益!$K:$K,0)))/200,($F$12-$I$4+VLOOKUP($Q5,武学奇术!$A:$ZZ,11,FALSE)+SUM(_xlfn.XLOOKUP($R5:$AK5,增益!$A:$A,增益!$K:$K,0)))/100)} -> -0.06 | BE5: {=$G$12+VLOOKUP($Q5,武学奇术!$A:$ZZ,12,FALSE)+SUM(_xlfn.XLOOKUP($R5:$AK5,增益!$A:$A,增益!$L:$L,0))} -> 0.06 | BF5: =$D$13*(1+$AW5) -> 639.744 | BG5: =$E$13*(1+$AW5) -> 1823.136 | BH5: {=IF($F$13-$I$4+VLOOKUP($Q5,武学奇术!$A:$ZZ,13,FALSE)+SUM(_xlfn.XLOOKUP($R5:$AK5,增益!$A:$A,增益!$M:$M,0))>0,($F$13-$I$4+VLOOKUP($Q5,武学奇术!$A:$ZZ,13,FALSE)+SUM(_xlfn.XLOOKUP($R5:$AK5,增益!$A:$A,增益!$K:$K,0)))/200,($F$13-$I$4+VLOOKUP($Q5,武学奇术!$A:$ZZ,13,FALSE)+SUM(_xlfn.XLOOKUP($R5:$AK5,增益!$A:$A,增益!$M:$M,0)))/100)} -> 0.12 | BI5: {=$G$13+VLOOKUP($Q5,武学奇术!$A:$ZZ,14,FALSE)+SUM(_xlfn.XLOOKUP($R5:$AK5,增益!$A:$A,增益!$N:$N,0))} -> 0.33 | BJ5: =$D$14*(1+$AW5) -> 0 | BK5: =$E$14*(1+$AW5) -> 0 | BL5: {=IF($F$14-$I$4+VLOOKUP($Q5,武学奇术!$A:$ZZ,15,FALSE)+SUM(_xlfn.XLOOKUP($R5:$AK5,增益!$A:$A,增益!$O:$O,0))>0,($F$14-$I$4+VLOOKUP($Q5,武学奇术!$A:$ZZ,15,FALSE)+SUM(_xlfn.XLOOKUP($R5:$AK5,增益!$A:$A,增益!$O:$O,0)))/200,($F$14-$I$4+VLOOKUP($Q5,武学奇术!$A:$ZZ,15,FALSE)+SUM(_xlfn.XLOOKUP($R5:$AK5,增益!$A:$A,增益!$O:$O,0)))/100)} -> -0.06 | BM5: {=$G$14+VLOOKUP($Q5,武学奇术!$A:$ZZ,16,FALSE)+SUM(_xlfn.XLOOKUP($R5:$AK5,增益!$A:$A,增益!$P:$P,0))} -> 0.06 | BN5: =MIN(IF(VLOOKUP($Q5,武学奇术!$A:$ZZ,23,FALSE)=1,100%,$B$8),100%) -> 0.9859 | BO5: {=IF(VLOOKUP($Q5,武学奇术!$A:$ZZ,23,FALSE)=1,100%,MIN(80%,$B$9+VLOOKUP($Q5,武学奇术!$A:$ZZ,17,FALSE)+SUM(_xlfn.XLOOKUP($R5:$AK5,增益!$A:$A,增益!$Q:$Q,0)))+$B$11+SUM(_xlfn.XLOOKUP($R5:$AK5,增益!$A:$A,增益!$U:$U,0)))*IF(VLOOKUP($Q5,武学奇术!$A:$ZZ,24,FALSE)=1,0,1)} -> 0.8912 | BP5: {=1+$B$13+VLOOKUP($Q5,武学奇术!$A:$ZZ,18,FALSE)+SUM(_xlfn.XLOOKUP($R5:$AK5,增益!$A:$A,增益!$R:$R,0))} -> 1.58 | BQ5: {=IF(VLOOKUP($Q5,武学奇术!$A:$ZZ,24,FALSE)=1,100%,MIN(40%,$B$10+VLOOKUP($Q5,武学奇术!$A:$ZZ,19,FALSE)+SUM(_xlfn.XLOOKUP($R5:$AK5,增益!$A:$A,增益!$S:$S,0)))+$B$12+SUM(_xlfn.XLOOKUP($R5:$AK5,增益!$A:$A,增益!$V:$V,0)))*IF(VLOOKUP($Q5,武学奇术!$A:$ZZ,23,FALSE)=1,0,1)} -> 0.0929 | BR5: {=1+$B$14+VLOOKUP($Q5,武学奇术!$A:$ZZ,20,FALSE)+SUM(_xlfn.XLOOKUP($R5:$AK5,增益!$A:$A,增益!$T:$T,0))} -> 1.35 | BS5: =MIN((1-BQ5)*BN5,BN5*BO5) -> 0.87863408 | BT5: =1-BQ5-BS5-BU5 -> 0.01567581 | BU5: =IF(VLOOKUP($Q5,武学奇术!$A:$ZZ,22,FALSE)=1,0,(1-$BN5))*(1-$BQ5) -> 0.01279011 | BV5: {=SUM(_xlfn.XLOOKUP($R5:$AK5,增益!$A:$A,增益!$W:$W,0))+$I$5} -> 0.11
A6: 破竹 | F6: 单体奇术 | G6: =B19 -> 0 | K6: =($L6*$BS6+$M6*$BQ6+$N6*$BT6+$O6*$BU6) -> 32310.461 | L6: =((($AS6+$AT6)/2*$AM6+$AN6)*(1+$AU6)*(1+$AV6)+(($AX6+$AY6)/2*IF($G$1="鸣金",$AO6,$AM6)+IF($G$1="鸣金",$AP6*1.5,0))*(1+$AZ6)*(1+$BA6)+(($BB6+$BC6)/2*IF($G$1="裂石",$AO6,$AM6)+IF($G$1="裂石",$AP6*1.5,0))*(1+$BD6)*(1+$BE6)+(($BF6+$BG6)/2*IF($G$1="牵丝",$AO6,$AM6)+IF($G$1="牵丝",$AP6*1.5,0))*(1+$BH6)*(1+$BI6)+(($BJ6+$BK6)/2*IF($G$1="破竹",$AO6,$AM6)+IF($G$1="破竹",$AP6*1.5,0))*(1+$BL6)*(1+$BM6))*(1+$AQ6)*$BP6*$P6*(1+IF(VLOOKUP($Q6,武学奇术!$A:$ZZ,30,FALSE)="特殊技",$B$21,0))*(1+$BV6) -> 32781.725 | M6: =(($AT6*$AM6+$AN6)*(1+$AU6)*(1+$AV6)+($AY6*IF($G$1="鸣金",$AO6,$AM6)+IF($G$1="鸣金",$AP6*1.5,0))*(1+$AZ6)*(1+$BA6)+($BC6*IF($G$1="裂石",$AO6,$AM6)+IF($G$1="裂石",$AP6*1.5,0))*(1+$BD6)*(1+$BE6)+($BG6*IF($G$1="牵丝",$AO6,$AM6)+IF($G$1="牵丝",$AP6*1.5,0))*(1+$BH6)*(1+$BI6)+($BK6*IF($G$1="破竹",$AO6,$AM6)+IF($G$1="破竹",$AP6*1.5,0))*(1+$BL6)*(1+$BM6))*(1+$AQ6)*$BR6*$P6*(1+IF(VLOOKUP($Q6,武学奇术!$A:$ZZ,30,FALSE)="特殊技",$B$21,0))*(1+$BV6) -> 31845.372 | N6: =((($AS6+$AT6)/2*$AM6+$AN6)*(1+$AU6)*(1+$AV6)+(($AX6+$AY6)/2*IF($G$1="鸣金",$AO6,$AM6)+IF($G$1="鸣金",$AP6*1.5,0))*(1+$AZ6)*(1+$BA6)+(($BB6+$BC6)/2*IF($G$1="裂石",$AO6,$AM6)+IF($G$1="裂石",$AP6*1.5,0))*(1+$BD6)*(1+$BE6)+(($BF6+$BG6)/2*IF($G$1="牵丝",$AO6,$AM6)+IF($G$1="牵丝",$AP6*1.5,0))*(1+$BH6)*(1+$BI6)+(($BJ6+$BK6)/2*IF($G$1="破竹",$AO6,$AM6)+IF($G$1="破竹",$AP6*1.5,0))*(1+$BL6)*(1+$BM6))*(1+$AQ6)*$P6*(1+IF(VLOOKUP($Q6,武学奇术!$A:$ZZ,30,FALSE)="特殊技",$B$21,0))*(1+$BV6) -> 20617.437 | O6: =((($AS6*$AM6+$AN6)*(1+$AU6)*(1+$AV6)+($AX6*IF($G$1="鸣金",$AO6,$AM6)+IF($G$1="鸣金",$AP6*1.5,0))*(1+$AZ6)*(1+$BA6)+($BB6*IF($G$1="裂石",$AO6,$AM6)+IF($G$1="裂石",$AP6*1.5,0))*(1+$BD6)*(1+$BE6)+($BF6*IF($G$1="牵丝",$AO6,$AM6)+IF($G$1="牵丝",$AP6*1.5,0))*(1+$BH6)*(1+$BI6)+($BJ6*IF($G$1="破竹",$AO6,$AM6)+IF($G$1="破竹",$AP6*1.5,0))*(1+$BL6)*(1+$BM6))*(1+$AQ6))*$P6*(1+IF(VLOOKUP($Q6,武学奇术!$A:$ZZ,30,FALSE)="特殊技",$B$21,0))*(1+$BV6) -> 17645.71 | P6: 1 | Q6: 萧呤千浪流星 | R6: 易水歌5层 | S6: 沧海帖5层 | T6: 扶风 | U6: 中程笛 | V6: 裁云 | W6: N/a | X6: 惧刃(拐) | Y6: N/a | Z6: N/a | AA6: N/a | AB6: N/a | AC6: N/a | AD6: N/a | AE6: N/a | AF6: 无惧 | AG6: N/a | AH6: N/a | AI6: N/a | AJ6: N/a | AK6: 离猎(拐) | AL6: =VLOOKUP($Q6,武学奇术!$A:$ZZ,25,FALSE) -> 群体奇术 | AM6: =VLOOKUP($Q6,武学奇术!$A:$ZZ,26,FALSE) -> 1.4904 | AN6: =VLOOKUP($Q6,武学奇术!$A:$ZZ,27,FALSE)*(1+IF(OR($AL6=$F$4,$AL6=$F$5),$B$22,0)) -> 378 | AO6: =VLOOKUP($Q6,武学奇术!$A:$ZZ,28,FALSE) -> 2.2356 | AP6: =VLOOKUP($Q6,武学奇术!$A:$ZZ,29,FALSE)*(1+IF(OR($AL6=$F$4,$AL6=$F$5),$B$22,0)) -> 0 | AQ6: {=$G$3+IFERROR(VLOOKUP($AL6,$F$4:$G$7,2,FALSE),0)+VLOOKUP($Q6,武学奇术!$A:$ZZ,2,FALSE)+SUM(_xlfn.XLOOKUP($R6:$AK6,增益!$A:$A,增益!$B:$B,0))} -> 0.3587 | AR6: {=VLOOKUP($Q6,武学奇术!$A:$ZZ,5,FALSE)+SUM(_xlfn.XLOOKUP($R6:$AK6,增益!$A:$A,增益!$E:$E,0))} -> 0 | AS6: {=$D$10*(1+$AR6)+VLOOKUP($Q6,武学奇术!$A:$ZZ,3,FALSE)+SUM(_xlfn.XLOOKUP($R6:$AK6,增益!$A:$A,增益!$C:$C,0))-$I$2} -> 3673.1 | AT6: {=$E$10*(1+$AR6)+VLOOKUP($Q6,武学奇术!$A:$ZZ,4,FALSE)+SUM(_xlfn.XLOOKUP($R6:$AK6,增益!$A:$A,增益!$D:$D,0))-$I$2} -> 3673.1 | AU6: {=IF($F$10-$I$3+VLOOKUP($Q6,武学奇术!$A:$ZZ,6,FALSE)+SUM(_xlfn.XLOOKUP($R6:$AK6,增益!$A:$A,增益!$F:$F,0))>0,($F$10-$I$3+VLOOKUP($Q6,武学奇术!$A:$ZZ,6,FALSE)+SUM(_xlfn.XLOOKUP($R6:$AK6,增益!$A:$A,增益!$F:$F,0)))/200,($F$10-$I$3+VLOOKUP($Q6,武学奇术!$A:$ZZ,6,FALSE)+SUM(_xlfn.XLOOKUP($R6:$AK6,增益!$A:$A,增益!$F:$F,0)))/100)} -> 0.357 | AV6: {=$G$10+VLOOKUP($Q6,武学奇术!$A:$ZZ,7,FALSE)+SUM(_xlfn.XLOOKUP($R6:$AK6,增益!$A:$A,增益!$G:$G,0))} -> 0.205 | AW6: {=VLOOKUP($Q6,武学奇术!$A:$ZZ,8,FALSE)+SUM(_xlfn.XLOOKUP($R6:$AK6,增益!$A:$A,增益!$H:$H,0))} -> 0.12 | AX6: =$D$11*(1+$AW6) -> 0 | AY6: =$E$11*(1+$AW6) -> 0 | AZ6: {=IF($F$11-$I$4+VLOOKUP($Q6,武学奇术!$A:$ZZ,9,FALSE)+SUM(_xlfn.XLOOKUP($R6:$AK6,增益!$A:$A,增益!$I:$I,0))>0,($F$11-$I$4+VLOOKUP($Q6,武学奇术!$A:$ZZ,9,FALSE)+SUM(_xlfn.XLOOKUP($R6:$AK6,增益!$A:$A,增益!$I:$I,0)))/200,($F$11-$I$4+VLOOKUP($Q6,武学奇术!$A:$ZZ,9,FALSE)+SUM(_xlfn.XLOOKUP($R6:$AK6,增益!$A:$A,增益!$I:$I,0)))/100)} -> -0.06 | BA6: {=$G$11+VLOOKUP($Q6,武学奇术!$A:$ZZ,10,FALSE)+SUM(_xlfn.XLOOKUP($R6:$AK6,增益!$A:$A,增益!$J:$J,0))} -> 0.06 | BB6: =$D$12*(1+$AW6) -> 0 | BC6: =$E$12*(1+$AW6) -> 0 | BD6: {=IF($F$12-$I$4+VLOOKUP($Q6,武学奇术!$A:$ZZ,11,FALSE)+SUM(_xlfn.XLOOKUP($R6:$AK6,增益!$A:$A,增益!$K:$K,0))>0,($F$12-$I$4+VLOOKUP($Q6,武学奇术!$A:$ZZ,11,FALSE)+SUM(_xlfn.XLOOKUP($R6:$AK6,增益!$A:$A,增益!$K:$K,0)))/200,($F$12-$I$4+VLOOKUP($Q6,武学奇术!$A:$ZZ,11,FALSE)+SUM(_xlfn.XLOOKUP($R6:$AK6,增益!$A:$A,增益!$K:$K,0)))/100)} -> -0.06 | BE6: {=$G$12+VLOOKUP($Q6,武学奇术!$A:$ZZ,12,FALSE)+SUM(_xlfn.XLOOKUP($R6:$AK6,增益!$A:$A,增益!$L:$L,0))} -> 0.06 | BF6: =$D$13*(1+$AW6) -> 639.744 | BG6: =$E$13*(1+$AW6) -> 1823.136 | BH6: {=IF($F$13-$I$4+VLOOKUP($Q6,武学奇术!$A:$ZZ,13,FALSE)+SUM(_xlfn.XLOOKUP($R6:$AK6,增益!$A:$A,增益!$M:$M,0))>0,($F$13-$I$4+VLOOKUP($Q6,武学奇术!$A:$ZZ,13,FALSE)+SUM(_xlfn.XLOOKUP($R6:$AK6,增益!$A:$A,增益!$K:$K,0)))/200,($F$13-$I$4+VLOOKUP($Q6,武学奇术!$A:$ZZ,13,FALSE)+SUM(_xlfn.XLOOKUP($R6:$AK6,增益!$A:$A,增益!$M:$M,0)))/100)} -> 0.12 | BI6: {=$G$13+VLOOKUP($Q6,武学奇术!$A:$ZZ,14,FALSE)+SUM(_xlfn.XLOOKUP($R6:$AK6,增益!$A:$A,增益!$N:$N,0))} -> 0.33 | BJ6: =$D$14*(1+$AW6) -> 0 | BK6: =$E$14*(1+$AW6) -> 0 | BL6: {=IF($F$14-$I$4+VLOOKUP($Q6,武学奇术!$A:$ZZ,15,FALSE)+SUM(_xlfn.XLOOKUP($R6:$AK6,增益!$A:$A,增益!$O:$O,0))>0,($F$14-$I$4+VLOOKUP($Q6,武学奇术!$A:$ZZ,15,FALSE)+SUM(_xlfn.XLOOKUP($R6:$AK6,增益!$A:$A,增益!$O:$O,0)))/200,($F$14-$I$4+VLOOKUP($Q6,武学奇术!$A:$ZZ,15,FALSE)+SUM(_xlfn.XLOOKUP($R6:$AK6,增益!$A:$A,增益!$O:$O,0)))/100)} -> -0.06 | BM6: {=$G$14+VLOOKUP($Q6,武学奇术!$A:$ZZ,16,FALSE)+SUM(_xlfn.XLOOKUP($R6:$AK6,增益!$A:$A,增益!$P:$P,0))} -> 0.06 | BN6: =MIN(IF(VLOOKUP($Q6,武学奇术!$A:$ZZ,23,FALSE)=1,100%,$B$8),100%) -> 0.9859 | BO6: {=IF(VLOOKUP($Q6,武学奇术!$A:$ZZ,23,FALSE)=1,100%,MIN(80%,$B$9+VLOOKUP($Q6,武学奇术!$A:$ZZ,17,FALSE)+SUM(_xlfn.XLOOKUP($R6:$AK6,增益!$A:$A,增益!$Q:$Q,0)))+$B$11+SUM(_xlfn.XLOOKUP($R6:$AK6,增益!$A:$A,增益!$U:$U,0)))*IF(VLOOKUP($Q6,武学奇术!$A:$ZZ,24,FALSE)=1,0,1)} -> 0.8912 | BP6: {=1+$B$13+VLOOKUP($Q6,武学奇术!$A:$ZZ,18,FALSE)+SUM(_xlfn.XLOOKUP($R6:$AK6,增益!$A:$A,增益!$R:$R,0))} -> 1.59 | BQ6: {=IF(VLOOKUP($Q6,武学奇术!$A:$ZZ,24,FALSE)=1,100%,MIN(40%,$B$10+VLOOKUP($Q6,武学奇术!$A:$ZZ,19,FALSE)+SUM(_xlfn.XLOOKUP($R6:$AK6,增益!$A:$A,增益!$S:$S,0)))+$B$12+SUM(_xlfn.XLOOKUP($R6:$AK6,增益!$A:$A,增益!$V:$V,0)))*IF(VLOOKUP($Q6,武学奇术!$A:$ZZ,23,FALSE)=1,0,1)} -> 0.0929 | BR6: {=1+$B$14+VLOOKUP($Q6,武学奇术!$A:$ZZ,20,FALSE)+SUM(_xlfn.XLOOKUP($R6:$AK6,增益!$A:$A,增益!$T:$T,0))} -> 1.35 | BS6: =MIN((1-BQ6)*BN6,BN6*BO6) -> 0.87863408 | BT6: =1-BQ6-BS6-BU6 -> 0.01567581 | BU6: =IF(VLOOKUP($Q6,武学奇术!$A:$ZZ,22,FALSE)=1,0,(1-$BN6))*(1-$BQ6) -> 0.01279011 | BV6: {=SUM(_xlfn.XLOOKUP($R6:$AK6,增益!$A:$A,增益!$W:$W,0))+$I$5} -> 0.11
A7: 无相 | B7: 79.2 | C7: =92.4+68.8*2 -> 230 | F7: 群体奇术 | G7: =B20 -> 0 | K7: =($L7*$BS7+$M7*$BQ7+$N7*$BT7+$O7*$BU7) -> 19161.492 | L7: =((($AS7+$AT7)/2*$AM7+$AN7)*(1+$AU7)*(1+$AV7)+(($AX7+$AY7)/2*IF($G$1="鸣金",$AO7,$AM7)+IF($G$1="鸣金",$AP7*1.5,0))*(1+$AZ7)*(1+$BA7)+(($BB7+$BC7)/2*IF($G$1="裂石",$AO7,$AM7)+IF($G$1="裂石",$AP7*1.5,0))*(1+$BD7)*(1+$BE7)+(($BF7+$BG7)/2*IF($G$1="牵丝",$AO7,$AM7)+IF($G$1="牵丝",$AP7*1.5,0))*(1+$BH7)*(1+$BI7)+(($BJ7+$BK7)/2*IF($G$1="破竹",$AO7,$AM7)+IF($G$1="破竹",$AP7*1.5,0))*(1+$BL7)*(1+$BM7))*(1+$AQ7)*$BP7*$P7*(1+IF(VLOOKUP($Q7,武学奇术!$A:$ZZ,30,FALSE)="特殊技",$B$21,0))*(1+$BV7) -> 19408.204 | M7: =(($AT7*$AM7+$AN7)*(1+$AU7)*(1+$AV7)+($AY7*IF($G$1="鸣金",$AO7,$AM7)+IF($G$1="鸣金",$AP7*1.5,0))*(1+$AZ7)*(1+$BA7)+($BC7*IF($G$1="裂石",$AO7,$AM7)+IF($G$1="裂石",$AP7*1.5,0))*(1+$BD7)*(1+$BE7)+($BG7*IF($G$1="牵丝",$AO7,$AM7)+IF($G$1="牵丝",$AP7*1.5,0))*(1+$BH7)*(1+$BI7)+($BK7*IF($G$1="破竹",$AO7,$AM7)+IF($G$1="破竹",$AP7*1.5,0))*(1+$BL7)*(1+$BM7))*(1+$AQ7)*$BR7*$P7*(1+IF(VLOOKUP($Q7,武学奇术!$A:$ZZ,30,FALSE)="特殊技",$B$21,0))*(1+$BV7) -> 19085.195 | N7: =((($AS7+$AT7)/2*$AM7+$AN7)*(1+$AU7)*(1+$AV7)+(($AX7+$AY7)/2*IF($G$1="鸣金",$AO7,$AM7)+IF($G$1="鸣金",$AP7*1.5,0))*(1+$AZ7)*(1+$BA7)+(($BB7+$BC7)/2*IF($G$1="裂石",$AO7,$AM7)+IF($G$1="裂石",$AP7*1.5,0))*(1+$BD7)*(1+$BE7)+(($BF7+$BG7)/2*IF($G$1="牵丝",$AO7,$AM7)+IF($G$1="牵丝",$AP7*1.5,0))*(1+$BH7)*(1+$BI7)+(($BJ7+$BK7)/2*IF($G$1="破竹",$AO7,$AM7)+IF($G$1="破竹",$AP7*1.5,0))*(1+$BL7)*(1+$BM7))*(1+$AQ7)*$P7*(1+IF(VLOOKUP($Q7,武学奇术!$A:$ZZ,30,FALSE)="特殊技",$B$21,0))*(1+$BV7) -> 12521.422 | O7: =((($AS7*$AM7+$AN7)*(1+$AU7)*(1+$AV7)+($AX7*IF($G$1="鸣金",$AO7,$AM7)+IF($G$1="鸣金",$AP7*1.5,0))*(1+$AZ7)*(1+$BA7)+($BB7*IF($G$1="裂石",$AO7,$AM7)+IF($G$1="裂石",$AP7*1.5,0))*(1+$BD7)*(1+$BE7)+($BF7*IF($G$1="牵丝",$AO7,$AM7)+IF($G$1="牵丝",$AP7*1.5,0))*(1+$BH7)*(1+$BI7)+($BJ7*IF($G$1="破竹",$AO7,$AM7)+IF($G$1="破竹",$AP7*1.5,0))*(1+$BL7)*(1+$BM7))*(1+$AQ7))*$P7*(1+IF(VLOOKUP($Q7,武学奇术!$A:$ZZ,30,FALSE)="特殊技",$B$21,0))*(1+$BV7) -> 10905.663 | P7: 1 | Q7: 扇～ | R7: 易水歌1层 | S7: 沧海帖1层 | T7: 扶风 | U7: N/a | V7: 裁云 | W7: N/a | X7: N/a | Y7: N/a | Z7: N/a | AA7: N/a | AB7: N/a | AC7: N/a | AD7: N/a | AE7: N/a | AF7: 无惧 | AG7: N/a | AH7: N/a | AI7: N/a | AJ7: N/a | AK7: 离猎(拐) | AL7: =VLOOKUP($Q7,武学奇术!$A:$ZZ,25,FALSE) -> 扇 | AM7: =VLOOKUP($Q7,武学奇术!$A:$ZZ,26,FALSE) -> 0.9271 | AN7: =VLOOKUP($Q7,武学奇术!$A:$ZZ,27,FALSE)*(1+IF(OR($AL7=$F$4,$AL7=$F$5),$B$22,0)) -> 385.5 | AO7: =VLOOKUP($Q7,武学奇术!$A:$ZZ,28,FALSE) -> 1.3907 | AP7: =VLOOKUP($Q7,武学奇术!$A:$ZZ,29,FALSE)*(1+IF(OR($AL7=$F$4,$AL7=$F$5),$B$22,0)) -> 210 | AQ7: {=$G$3+IFERROR(VLOOKUP($AL7,$F$4:$G$7,2,FALSE),0)+VLOOKUP($Q7,武学奇术!$A:$ZZ,2,FALSE)+SUM(_xlfn.XLOOKUP($R7:$AK7,增益!$A:$A,增益!$B:$B,0))} -> 0.2789 | AR7: {=VLOOKUP($Q7,武学奇术!$A:$ZZ,5,FALSE)+SUM(_xlfn.XLOOKUP($R7:$AK7,增益!$A:$A,增益!$E:$E,0))} -> 0 | AS7: {=$D$10*(1+$AR7)+VLOOKUP($Q7,武学奇术!$A:$ZZ,3,FALSE)+SUM(_xlfn.XLOOKUP($R7:$AK7,增益!$A:$A,增益!$C:$C,0))-$I$2} -> 3673.1 | AT7: {=$E$10*(1+$AR7)+VLOOKUP($Q7,武学奇术!$A:$ZZ,4,FALSE)+SUM(_xlfn.XLOOKUP($R7:$AK7,增益!$A:$A,增益!$D:$D,0))-$I$2} -> 3673.1 | AU7: {=IF($F$10-$I$3+VLOOKUP($Q7,武学奇术!$A:$ZZ,6,FALSE)+SUM(_xlfn.XLOOKUP($R7:$AK7,增益!$A:$A,增益!$F:$F,0))>0,($F$10-$I$3+VLOOKUP($Q7,武学奇术!$A:$ZZ,6,FALSE)+SUM(_xlfn.XLOOKUP($R7:$AK7,增益!$A:$A,增益!$F:$F,0)))/200,($F$10-$I$3+VLOOKUP($Q7,武学奇术!$A:$ZZ,6,FALSE)+SUM(_xlfn.XLOOKUP($R7:$AK7,增益!$A:$A,增益!$F:$F,0)))/100)} -> 0.317 | AV7: {=$G$10+VLOOKUP($Q7,武学奇术!$A:$ZZ,7,FALSE)+SUM(_xlfn.XLOOKUP($R7:$AK7,增益!$A:$A,增益!$G:$G,0))} -> 0.205 | AW7: {=VLOOKUP($Q7,武学奇术!$A:$ZZ,8,FALSE)+SUM(_xlfn.XLOOKUP($R7:$AK7,增益!$A:$A,增益!$H:$H,0))} -> 0.12 | AX7: =$D$11*(1+$AW7) -> 0 | AY7: =$E$11*(1+$AW7) -> 0 | AZ7: {=IF($F$11-$I$4+VLOOKUP($Q7,武学奇术!$A:$ZZ,9,FALSE)+SUM(_xlfn.XLOOKUP($R7:$AK7,增益!$A:$A,增益!$I:$I,0))>0,($F$11-$I$4+VLOOKUP($Q7,武学奇术!$A:$ZZ,9,FALSE)+SUM(_xlfn.XLOOKUP($R7:$AK7,增益!$A:$A,增益!$I:$I,0)))/200,($F$11-$I$4+VLOOKUP($Q7,武学奇术!$A:$ZZ,9,FALSE)+SUM(_xlfn.XLOOKUP($R7:$AK7,增益!$A:$A,增益!$I:$I,0)))/100)} -> -0.22 | BA7: {=$G$11+VLOOKUP($Q7,武学奇术!$A:$ZZ,10,FALSE)+SUM(_xlfn.XLOOKUP($R7:$AK7,增益!$A:$A,增益!$J:$J,0))} -> 0.06 | BB7: =$D$12*(1+$AW7) -> 0 | BC7: =$E$12*(1+$AW7) -> 0 | BD7: {=IF($F$12-$I$4+VLOOKUP($Q7,武学奇术!$A:$ZZ,11,FALSE)+SUM(_xlfn.XLOOKUP($R7:$AK7,增益!$A:$A,增益!$K:$K,0))>0,($F$12-$I$4+VLOOKUP($Q7,武学奇术!$A:$ZZ,11,FALSE)+SUM(_xlfn.XLOOKUP($R7:$AK7,增益!$A:$A,增益!$K:$K,0)))/200,($F$12-$I$4+VLOOKUP($Q7,武学奇术!$A:$ZZ,11,FALSE)+SUM(_xlfn.XLOOKUP($R7:$AK7,增益!$A:$A,增益!$K:$K,0)))/100)} -> -0.22 | BE7: {=$G$12+VLOOKUP($Q7,武学奇术!$A:$ZZ,12,FALSE)+SUM(_xlfn.XLOOKUP($R7:$AK7,增益!$A:$A,增益!$L:$L,0))} -> 0.06 | BF7: =$D$13*(1+$AW7) -> 639.744 | BG7: =$E$13*(1+$AW7) -> 1823.136 | BH7: {=IF($F$13-$I$4+VLOOKUP($Q7,武学奇术!$A:$ZZ,13,FALSE)+SUM(_xlfn.XLOOKUP($R7:$AK7,增益!$A:$A,增益!$M:$M,0))>0,($F$13-$I$4+VLOOKUP($Q7,武学奇术!$A:$ZZ,13,FALSE)+SUM(_xlfn.XLOOKUP($R7:$AK7,增益!$A:$A,增益!$K:$K,0)))/200,($F$13-$I$4+VLOOKUP($Q7,武学奇术!$A:$ZZ,13,FALSE)+SUM(_xlfn.XLOOKUP($R7:$AK7,增益!$A:$A,增益!$M:$M,0)))/100)} -> 0.04 | BI7: {=$G$13+VLOOKUP($Q7,武学奇术!$A:$ZZ,14,FALSE)+SUM(_xlfn.XLOOKUP($R7:$AK7,增益!$A:$A,增益!$N:$N,0))} -> 0.33 | BJ7: =$D$14*(1+$AW7) -> 0 | BK7: =$E$14*(1+$AW7) -> 0 | BL7: {=IF($F$14-$I$4+VLOOKUP($Q7,武学奇术!$A:$ZZ,15,FALSE)+SUM(_xlfn.XLOOKUP($R7:$AK7,增益!$A:$A,增益!$O:$O,0))>0,($F$14-$I$4+VLOOKUP($Q7,武学奇术!$A:$ZZ,15,FALSE)+SUM(_xlfn.XLOOKUP($R7:$AK7,增益!$A:$A,增益!$O:$O,0)))/200,($F$14-$I$4+VLOOKUP($Q7,武学奇术!$A:$ZZ,15,FALSE)+SUM(_xlfn.XLOOKUP($R7:$AK7,增益!$A:$A,增益!$O:$O,0)))/100)} -> -0.22 | BM7: {=$G$14+VLOOKUP($Q7,武学奇术!$A:$ZZ,16,FALSE)+SUM(_xlfn.XLOOKUP($R7:$AK7,增益!$A:$A,增益!$P:$P,0))} -> 0.06 | BN7: =MIN(IF(VLOOKUP($Q7,武学奇术!$A:$ZZ,23,FALSE)=1,100%,$B$8),100%) -> 0.9859 | BO7: {=IF(VLOOKUP($Q7,武学奇术!$A:$ZZ,23,FALSE)=1,100%,MIN(80%,$B$9+VLOOKUP($Q7,武学奇术!$A:$ZZ,17,FALSE)+SUM(_xlfn.XLOOKUP($R7:$AK7,增益!$A:$A,增益!$Q:$Q,0)))+$B$11+SUM(_xlfn.XLOOKUP($R7:$AK7,增益!$A:$A,增益!$U:$U,0)))*IF(VLOOKUP($Q7,武学奇术!$A:$ZZ,24,FALSE)=1,0,1)} -> 0.8912 | BP7: {=1+$B$13+VLOOKUP($Q7,武学奇术!$A:$ZZ,18,FALSE)+SUM(_xlfn.XLOOKUP($R7:$AK7,增益!$A:$A,增益!$R:$R,0))} -> 1.55 | BQ7: {=IF(VLOOKUP($Q7,武学奇术!$A:$ZZ,24,FALSE)=1,100%,MIN(40%,$B$10+VLOOKUP($Q7,武学奇术!$A:$ZZ,19,FALSE)+SUM(_xlfn.XLOOKUP($R7:$AK7,增益!$A:$A,增益!$S:$S,0)))+$B$12+SUM(_xlfn.XLOOKUP($R7:$AK7,增益!$A:$A,增益!$V:$V,0)))*IF(VLOOKUP($Q7,武学奇术!$A:$ZZ,23,FALSE)=1,0,1)} -> 0.0929 | BR7: {=1+$B$14+VLOOKUP($Q7,武学奇术!$A:$ZZ,20,FALSE)+SUM(_xlfn.XLOOKUP($R7:$AK7,增益!$A:$A,增益!$T:$T,0))} -> 1.35 | BS7: =MIN((1-BQ7)*BN7,BN7*BO7) -> 0.87863408 | BT7: =1-BQ7-BS7-BU7 -> 0.01567581 | BU7: =IF(VLOOKUP($Q7,武学奇术!$A:$ZZ,22,FALSE)=1,0,(1-$BN7))*(1-$BQ7) -> 0.01279011 | BV7: {=SUM(_xlfn.XLOOKUP($R7:$AK7,增益!$A:$A,增益!$W:$W,0))+$I$5} -> 0.11
A8: 精准率 | B8: 0.9859 | C8: 实际属性 | H8: 战斗时间 | I8: 100.8 | K8: =($L8*$BS8+$M8*$BQ8+$N8*$BT8+$O8*$BU8) -> 85667.572 | L8: =((($AS8+$AT8)/2*$AM8+$AN8)*(1+$AU8)*(1+$AV8)+(($AX8+$AY8)/2*IF($G$1="鸣金",$AO8,$AM8)+IF($G$1="鸣金",$AP8*1.5,0))*(1+$AZ8)*(1+$BA8)+(($BB8+$BC8)/2*IF($G$1="裂石",$AO8,$AM8)+IF($G$1="裂石",$AP8*1.5,0))*(1+$BD8)*(1+$BE8)+(($BF8+$BG8)/2*IF($G$1="牵丝",$AO8,$AM8)+IF($G$1="牵丝",$AP8*1.5,0))*(1+$BH8)*(1+$BI8)+(($BJ8+$BK8)/2*IF($G$1="破竹",$AO8,$AM8)+IF($G$1="破竹",$AP8*1.5,0))*(1+$BL8)*(1+$BM8))*(1+$AQ8)*$BP8*$P8*(1+IF(VLOOKUP($Q8,武学奇术!$A:$ZZ,30,FALSE)="特殊技",$B$21,0))*(1+$BV8) -> 86728.115 | M8: =(($AT8*$AM8+$AN8)*(1+$AU8)*(1+$AV8)+($AY8*IF($G$1="鸣金",$AO8,$AM8)+IF($G$1="鸣金",$AP8*1.5,0))*(1+$AZ8)*(1+$BA8)+($BC8*IF($G$1="裂石",$AO8,$AM8)+IF($G$1="裂石",$AP8*1.5,0))*(1+$BD8)*(1+$BE8)+($BG8*IF($G$1="牵丝",$AO8,$AM8)+IF($G$1="牵丝",$AP8*1.5,0))*(1+$BH8)*(1+$BI8)+($BK8*IF($G$1="破竹",$AO8,$AM8)+IF($G$1="破竹",$AP8*1.5,0))*(1+$BL8)*(1+$BM8))*(1+$AQ8)*$BR8*$P8*(1+IF(VLOOKUP($Q8,武学奇术!$A:$ZZ,30,FALSE)="特殊技",$B$21,0))*(1+$BV8) -> 85787.208 | N8: =((($AS8+$AT8)/2*$AM8+$AN8)*(1+$AU8)*(1+$AV8)+(($AX8+$AY8)/2*IF($G$1="鸣金",$AO8,$AM8)+IF($G$1="鸣金",$AP8*1.5,0))*(1+$AZ8)*(1+$BA8)+(($BB8+$BC8)/2*IF($G$1="裂石",$AO8,$AM8)+IF($G$1="裂石",$AP8*1.5,0))*(1+$BD8)*(1+$BE8)+(($BF8+$BG8)/2*IF($G$1="牵丝",$AO8,$AM8)+IF($G$1="牵丝",$AP8*1.5,0))*(1+$BH8)*(1+$BI8)+(($BJ8+$BK8)/2*IF($G$1="破竹",$AO8,$AM8)+IF($G$1="破竹",$AP8*1.5,0))*(1+$BL8)*(1+$BM8))*(1+$AQ8)*$P8*(1+IF(VLOOKUP($Q8,武学奇术!$A:$ZZ,30,FALSE)="特殊技",$B$21,0))*(1+$BV8) -> 55953.623 | O8: =((($AS8*$AM8+$AN8)*(1+$AU8)*(1+$AV8)+($AX8*IF($G$1="鸣金",$AO8,$AM8)+IF($G$1="鸣金",$AP8*1.5,0))*(1+$AZ8)*(1+$BA8)+($BB8*IF($G$1="裂石",$AO8,$AM8)+IF($G$1="裂石",$AP8*1.5,0))*(1+$BD8)*(1+$BE8)+($BF8*IF($G$1="牵丝",$AO8,$AM8)+IF($G$1="牵丝",$AP8*1.5,0))*(1+$BH8)*(1+$BI8)+($BJ8*IF($G$1="破竹",$AO8,$AM8)+IF($G$1="破竹",$AP8*1.5,0))*(1+$BL8)*(1+$BM8))*(1+$AQ8))*$P8*(1+IF(VLOOKUP($Q8,武学奇术!$A:$ZZ,30,FALSE)="特殊技",$B$21,0))*(1+$BV8) -> 48361.165 | P8: 1 | Q8: 扇Q | R8: 易水歌1层 | S8: 沧海帖1层 | T8: 扶风 | U8: N/a | V8: 裁云 | W8: N/a | X8: 惧刃(拐) | Y8: N/a | Z8: N/a | AA8: N/a | AB8: N/a | AC8: N/a | AD8: N/a | AE8: N/a | AF8: 无惧 | AG8: N/a | AH8: N/a | AI8: N/a | AJ8: N/a | AK8: 离猎(拐) | AL8: =VLOOKUP($Q8,武学奇术!$A:$ZZ,25,FALSE) -> 扇 | AM8: =VLOOKUP($Q8,武学奇术!$A:$ZZ,26,FALSE) -> 4.045375 | AN8: =VLOOKUP($Q8,武学奇术!$A:$ZZ,27,FALSE)*(1+IF(OR($AL8=$F$4,$AL8=$F$5),$B$22,0)) -> 1678.125 | AO8: =VLOOKUP($Q8,武学奇术!$A:$ZZ,28,FALSE) -> 6.068125 | AP8: =VLOOKUP($Q8,武学奇术!$A:$ZZ,29,FALSE)*(1+IF(OR($AL8=$F$4,$AL8=$F$5),$B$22,0)) -> 913.125 | AQ8: {=$G$3+IFERROR(VLOOKUP($AL8,$F$4:$G$7,2,FALSE),0)+VLOOKUP($Q8,武学奇术!$A:$ZZ,2,FALSE)+SUM(_xlfn.XLOOKUP($R8:$AK8,增益!$A:$A,增益!$B:$B,0))} -> 0.2789 | AR8: {=VLOOKUP($Q8,武学奇术!$A:$ZZ,5,FALSE)+SUM(_xlfn.XLOOKUP($R8:$AK8,增益!$A:$A,增益!$E:$E,0))} -> 0 | AS8: {=$D$10*(1+$AR8)+VLOOKUP($Q8,武学奇术!$A:$ZZ,3,FALSE)+SUM(_xlfn.XLOOKUP($R8:$AK8,增益!$A:$A,增益!$C:$C,0))-$I$2} -> 3673.1 | AT8: {=$E$10*(1+$AR8)+VLOOKUP($Q8,武学奇术!$A:$ZZ,4,FALSE)+SUM(_xlfn.XLOOKUP($R8:$AK8,增益!$A:$A,增益!$D:$D,0))-$I$2} -> 3673.1 | AU8: {=IF($F$10-$I$3+VLOOKUP($Q8,武学奇术!$A:$ZZ,6,FALSE)+SUM(_xlfn.XLOOKUP($R8:$AK8,增益!$A:$A,增益!$F:$F,0))>0,($F$10-$I$3+VLOOKUP($Q8,武学奇术!$A:$ZZ,6,FALSE)+SUM(_xlfn.XLOOKUP($R8:$AK8,增益!$A:$A,增益!$F:$F,0)))/200,($F$10-$I$3+VLOOKUP($Q8,武学奇术!$A:$ZZ,6,FALSE)+SUM(_xlfn.XLOOKUP($R8:$AK8,增益!$A:$A,增益!$F:$F,0)))/100)} -> 0.317 | AV8: {=$G$10+VLOOKUP($Q8,武学奇术!$A:$ZZ,7,FALSE)+SUM(_xlfn.XLOOKUP($R8:$AK8,增益!$A:$A,增益!$G:$G,0))} -> 0.205 | AW8: {=VLOOKUP($Q8,武学奇术!$A:$ZZ,8,FALSE)+SUM(_xlfn.XLOOKUP($R8:$AK8,增益!$A:$A,增益!$H:$H,0))} -> 0.12 | AX8: =$D$11*(1+$AW8) -> 0 | AY8: =$E$11*(1+$AW8) -> 0 | AZ8: {=IF($F$11-$I$4+VLOOKUP($Q8,武学奇术!$A:$ZZ,9,FALSE)+SUM(_xlfn.XLOOKUP($R8:$AK8,增益!$A:$A,增益!$I:$I,0))>0,($F$11-$I$4+VLOOKUP($Q8,武学奇术!$A:$ZZ,9,FALSE)+SUM(_xlfn.XLOOKUP($R8:$AK8,增益!$A:$A,增益!$I:$I,0)))/200,($F$11-$I$4+VLOOKUP($Q8,武学奇术!$A:$ZZ,9,FALSE)+SUM(_xlfn.XLOOKUP($R8:$AK8,增益!$A:$A,增益!$I:$I,0)))/100)} -> -0.06 | BA8: {=$G$11+VLOOKUP($Q8,武学奇术!$A:$ZZ,10,FALSE)+SUM(_xlfn.XLOOKUP($R8:$AK8,增益!$A:$A,增益!$J:$J,0))} -> 0.06 | BB8: =$D$12*(1+$AW8) -> 0 | BC8: =$E$12*(1+$AW8) -> 0 | BD8: {=IF($F$12-$I$4+VLOOKUP($Q8,武学奇术!$A:$ZZ,11,FALSE)+SUM(_xlfn.XLOOKUP($R8:$AK8,增益!$A:$A,增益!$K:$K,0))>0,($F$12-$I$4+VLOOKUP($Q8,武学奇术!$A:$ZZ,11,FALSE)+SUM(_xlfn.XLOOKUP($R8:$AK8,增益!$A:$A,增益!$K:$K,0)))/200,($F$12-$I$4+VLOOKUP($Q8,武学奇术!$A:$ZZ,11,FALSE)+SUM(_xlfn.XLOOKUP($R8:$AK8,增益!$A:$A,增益!$K:$K,0)))/100)} -> -0.06 | BE8: {=$G$12+VLOOKUP($Q8,武学奇术!$A:$ZZ,12,FALSE)+SUM(_xlfn.XLOOKUP($R8:$AK8,增益!$A:$A,增益!$L:$L,0))} -> 0.06 | BF8: =$D$13*(1+$AW8) -> 639.744 | BG8: =$E$13*(1+$AW8) -> 1823.136 | BH8: {=IF($F$13-$I$4+VLOOKUP($Q8,武学奇术!$A:$ZZ,13,FALSE)+SUM(_xlfn.XLOOKUP($R8:$AK8,增益!$A:$A,增益!$M:$M,0))>0,($F$13-$I$4+VLOOKUP($Q8,武学奇术!$A:$ZZ,13,FALSE)+SUM(_xlfn.XLOOKUP($R8:$AK8,增益!$A:$A,增益!$K:$K,0)))/200,($F$13-$I$4+VLOOKUP($Q8,武学奇术!$A:$ZZ,13,FALSE)+SUM(_xlfn.XLOOKUP($R8:$AK8,增益!$A:$A,增益!$M:$M,0)))/100)} -> 0.12 | BI8: {=$G$13+VLOOKUP($Q8,武学奇术!$A:$ZZ,14,FALSE)+SUM(_xlfn.XLOOKUP($R8:$AK8,增益!$A:$A,增益!$N:$N,0))} -> 0.33 | BJ8: =$D$14*(1+$AW8) -> 0 | BK8: =$E$14*(1+$AW8) -> 0 | BL8: {=IF($F$14-$I$4+VLOOKUP($Q8,武学奇术!$A:$ZZ,15,FALSE)+SUM(_xlfn.XLOOKUP($R8:$AK8,增益!$A:$A,增益!$O:$O,0))>0,($F$14-$I$4+VLOOKUP($Q8,武学奇术!$A:$ZZ,15,FALSE)+SUM(_xlfn.XLOOKUP($R8:$AK8,增益!$A:$A,增益!$O:$O,0)))/200,($F$14-$I$4+VLOOKUP($Q8,武学奇术!$A:$ZZ,15,FALSE)+SUM(_xlfn.XLOOKUP($R8:$AK8,增益!$A:$A,增益!$O:$O,0)))/100)} -> -0.06 | BM8: {=$G$14+VLOOKUP($Q8,武学奇术!$A:$ZZ,16,FALSE)+SUM(_xlfn.XLOOKUP($R8:$AK8,增益!$A:$A,增益!$P:$P,0))} -> 0.06 | BN8: =MIN(IF(VLOOKUP($Q8,武学奇术!$A:$ZZ,23,FALSE)=1,100%,$B$8),100%) -> 0.9859 | BO8: {=IF(VLOOKUP($Q8,武学奇术!$A:$ZZ,23,FALSE)=1,100%,MIN(80%,$B$9+VLOOKUP($Q8,武学奇术!$A:$ZZ,17,FALSE)+SUM(_xlfn.XLOOKUP($R8:$AK8,增益!$A:$A,增益!$Q:$Q,0)))+$B$11+SUM(_xlfn.XLOOKUP($R8:$AK8,增益!$A:$A,增益!$U:$U,0)))*IF(VLOOKUP($Q8,武学奇术!$A:$ZZ,24,FALSE)=1,0,1)} -> 0.8912 | BP8: {=1+$B$13+VLOOKUP($Q8,武学奇术!$A:$ZZ,18,FALSE)+SUM(_xlfn.XLOOKUP($R8:$AK8,增益!$A:$A,增益!$R:$R,0))} -> 1.55 | BQ8: {=IF(VLOOKUP($Q8,武学奇术!$A:$ZZ,24,FALSE)=1,100%,MIN(40%,$B$10+VLOOKUP($Q8,武学奇术!$A:$ZZ,19,FALSE)+SUM(_xlfn.XLOOKUP($R8:$AK8,增益!$A:$A,增益!$S:$S,0)))+$B$12+SUM(_xlfn.XLOOKUP($R8:$AK8,增益!$A:$A,增益!$V:$V,0)))*IF(VLOOKUP($Q8,武学奇术!$A:$ZZ,23,FALSE)=1,0,1)} -> 0.0929 | BR8: {=1+$B$14+VLOOKUP($Q8,武学奇术!$A:$ZZ,20,FALSE)+SUM(_xlfn.XLOOKUP($R8:$AK8,增益!$A:$A,增益!$T:$T,0))} -> 1.35 | BS8: =MIN((1-BQ8)*BN8,BN8*BO8) -> 0.87863408 | BT8: =1-BQ8-BS8-BU8 -> 0.01567581 | BU8: =IF(VLOOKUP($Q8,武学奇术!$A:$ZZ,22,FALSE)=1,0,(1-$BN8))*(1-$BQ8) -> 0.01279011 | BV8: {=SUM(_xlfn.XLOOKUP($R8:$AK8,增益!$A:$A,增益!$W:$W,0))+$I$5} -> 0.11
A9: 会心率 | B9: 0.7992 | D9: 最小攻击 | E9: 最大攻击 | F9: 穿透 | G9: 伤害加成 | K9: =($L9*$BS9+$M9*$BQ9+$N9*$BT9+$O9*$BU9) -> 23063.938 | L9: =((($AS9+$AT9)/2*$AM9+$AN9)*(1+$AU9)*(1+$AV9)+(($AX9+$AY9)/2*IF($G$1="鸣金",$AO9,$AM9)+IF($G$1="鸣金",$AP9*1.5,0))*(1+$AZ9)*(1+$BA9)+(($BB9+$BC9)/2*IF($G$1="裂石",$AO9,$AM9)+IF($G$1="裂石",$AP9*1.5,0))*(1+$BD9)*(1+$BE9)+(($BF9+$BG9)/2*IF($G$1="牵丝",$AO9,$AM9)+IF($G$1="牵丝",$AP9*1.5,0))*(1+$BH9)*(1+$BI9)+(($BJ9+$BK9)/2*IF($G$1="破竹",$AO9,$AM9)+IF($G$1="破竹",$AP9*1.5,0))*(1+$BL9)*(1+$BM9))*(1+$AQ9)*$BP9*$P9*(1+IF(VLOOKUP($Q9,武学奇术!$A:$ZZ,30,FALSE)="特殊技",$B$21,0))*(1+$BV9) -> 23350.615 | M9: =(($AT9*$AM9+$AN9)*(1+$AU9)*(1+$AV9)+($AY9*IF($G$1="鸣金",$AO9,$AM9)+IF($G$1="鸣金",$AP9*1.5,0))*(1+$AZ9)*(1+$BA9)+($BC9*IF($G$1="裂石",$AO9,$AM9)+IF($G$1="裂石",$AP9*1.5,0))*(1+$BD9)*(1+$BE9)+($BG9*IF($G$1="牵丝",$AO9,$AM9)+IF($G$1="牵丝",$AP9*1.5,0))*(1+$BH9)*(1+$BI9)+($BK9*IF($G$1="破竹",$AO9,$AM9)+IF($G$1="破竹",$AP9*1.5,0))*(1+$BL9)*(1+$BM9))*(1+$AQ9)*$BR9*$P9*(1+IF(VLOOKUP($Q9,武学奇术!$A:$ZZ,30,FALSE)="特殊技",$B$21,0))*(1+$BV9) -> 23083.649 | N9: =((($AS9+$AT9)/2*$AM9+$AN9)*(1+$AU9)*(1+$AV9)+(($AX9+$AY9)/2*IF($G$1="鸣金",$AO9,$AM9)+IF($G$1="鸣金",$AP9*1.5,0))*(1+$AZ9)*(1+$BA9)+(($BB9+$BC9)/2*IF($G$1="裂石",$AO9,$AM9)+IF($G$1="裂石",$AP9*1.5,0))*(1+$BD9)*(1+$BE9)+(($BF9+$BG9)/2*IF($G$1="牵丝",$AO9,$AM9)+IF($G$1="牵丝",$AP9*1.5,0))*(1+$BH9)*(1+$BI9)+(($BJ9+$BK9)/2*IF($G$1="破竹",$AO9,$AM9)+IF($G$1="破竹",$AP9*1.5,0))*(1+$BL9)*(1+$BM9))*(1+$AQ9)*$P9*(1+IF(VLOOKUP($Q9,武学奇术!$A:$ZZ,30,FALSE)="特殊技",$B$21,0))*(1+$BV9) -> 15064.913 | O9: =((($AS9*$AM9+$AN9)*(1+$AU9)*(1+$AV9)+($AX9*IF($G$1="鸣金",$AO9,$AM9)+IF($G$1="鸣金",$AP9*1.5,0))*(1+$AZ9)*(1+$BA9)+($BB9*IF($G$1="裂石",$AO9,$AM9)+IF($G$1="裂石",$AP9*1.5,0))*(1+$BD9)*(1+$BE9)+($BF9*IF($G$1="牵丝",$AO9,$AM9)+IF($G$1="牵丝",$AP9*1.5,0))*(1+$BH9)*(1+$BI9)+($BJ9*IF($G$1="破竹",$AO9,$AM9)+IF($G$1="破竹",$AP9*1.5,0))*(1+$BL9)*(1+$BM9))*(1+$AQ9))*$P9*(1+IF(VLOOKUP($Q9,武学奇术!$A:$ZZ,30,FALSE)="特殊技",$B$21,0))*(1+$BV9) -> 13030.826 | P9: 1 | Q9: 扇重击派生斩击 | R9: 易水歌2层 | S9: 沧海帖1层 | T9: 扶风 | U9: 近战笛 | V9: 裁云 | W9: N/a | X9: 惧刃(拐) | Y9: N/a | Z9: N/a | AA9: N/a | AB9: N/a | AC9: N/a | AD9: N/a | AE9: N/a | AF9: 无惧 | AG9: N/a | AH9: N/a | AI9: N/a | AJ9: N/a | AK9: 离猎(拐) | AL9: =VLOOKUP($Q9,武学奇术!$A:$ZZ,25,FALSE) -> 扇 | AM9: =VLOOKUP($Q9,武学奇术!$A:$ZZ,26,FALSE) -> 0.9186 | AN9: =VLOOKUP($Q9,武学奇术!$A:$ZZ,27,FALSE)*(1+IF(OR($AL9=$F$4,$AL9=$F$5),$B$22,0)) -> 381 | AO9: =VLOOKUP($Q9,武学奇术!$A:$ZZ,28,FALSE) -> 1.3779 | AP9: =VLOOKUP($Q9,武学奇术!$A:$ZZ,29,FALSE)*(1+IF(OR($AL9=$F$4,$AL9=$F$5),$B$22,0)) -> 207 | AQ9: {=$G$3+IFERROR(VLOOKUP($AL9,$F$4:$G$7,2,FALSE),0)+VLOOKUP($Q9,武学奇术!$A:$ZZ,2,FALSE)+SUM(_xlfn.XLOOKUP($R9:$AK9,增益!$A:$A,增益!$B:$B,0))} -> 0.5089 | AR9: {=VLOOKUP($Q9,武学奇术!$A:$ZZ,5,FALSE)+SUM(_xlfn.XLOOKUP($R9:$AK9,增益!$A:$A,增益!$E:$E,0))} -> 0 | AS9: {=$D$10*(1+$AR9)+VLOOKUP($Q9,武学奇术!$A:$ZZ,3,FALSE)+SUM(_xlfn.XLOOKUP($R9:$AK9,增益!$A:$A,增益!$C:$C,0))-$I$2} -> 3673.1 | AT9: {=$E$10*(1+$AR9)+VLOOKUP($Q9,武学奇术!$A:$ZZ,4,FALSE)+SUM(_xlfn.XLOOKUP($R9:$AK9,增益!$A:$A,增益!$D:$D,0))-$I$2} -> 3673.1 | AU9: {=IF($F$10-$I$3+VLOOKUP($Q9,武学奇术!$A:$ZZ,6,FALSE)+SUM(_xlfn.XLOOKUP($R9:$AK9,增益!$A:$A,增益!$F:$F,0))>0,($F$10-$I$3+VLOOKUP($Q9,武学奇术!$A:$ZZ,6,FALSE)+SUM(_xlfn.XLOOKUP($R9:$AK9,增益!$A:$A,增益!$F:$F,0)))/200,($F$10-$I$3+VLOOKUP($Q9,武学奇术!$A:$ZZ,6,FALSE)+SUM(_xlfn.XLOOKUP($R9:$AK9,增益!$A:$A,增益!$F:$F,0)))/100)} -> 0.327 | AV9: {=$G$10+VLOOKUP($Q9,武学奇术!$A:$ZZ,7,FALSE)+SUM(_xlfn.XLOOKUP($R9:$AK9,增益!$A:$A,增益!$G:$G,0))} -> 0.205 | AW9: {=VLOOKUP($Q9,武学奇术!$A:$ZZ,8,FALSE)+SUM(_xlfn.XLOOKUP($R9:$AK9,增益!$A:$A,增益!$H:$H,0))} -> 0.12 | AX9: =$D$11*(1+$AW9) -> 0 | AY9: =$E$11*(1+$AW9) -> 0 | AZ9: {=IF($F$11-$I$4+VLOOKUP($Q9,武学奇术!$A:$ZZ,9,FALSE)+SUM(_xlfn.XLOOKUP($R9:$AK9,增益!$A:$A,增益!$I:$I,0))>0,($F$11-$I$4+VLOOKUP($Q9,武学奇术!$A:$ZZ,9,FALSE)+SUM(_xlfn.XLOOKUP($R9:$AK9,增益!$A:$A,增益!$I:$I,0)))/200,($F$11-$I$4+VLOOKUP($Q9,武学奇术!$A:$ZZ,9,FALSE)+SUM(_xlfn.XLOOKUP($R9:$AK9,增益!$A:$A,增益!$I:$I,0)))/100)} -> -0.06 | BA9: {=$G$11+VLOOKUP($Q9,武学奇术!$A:$ZZ,10,FALSE)+SUM(_xlfn.XLOOKUP($R9:$AK9,增益!$A:$A,增益!$J:$J,0))} -> 0.06 | BB9: =$D$12*(1+$AW9) -> 0 | BC9: =$E$12*(1+$AW9) -> 0 | BD9: {=IF($F$12-$I$4+VLOOKUP($Q9,武学奇术!$A:$ZZ,11,FALSE)+SUM(_xlfn.XLOOKUP($R9:$AK9,增益!$A:$A,增益!$K:$K,0))>0,($F$12-$I$4+VLOOKUP($Q9,武学奇术!$A:$ZZ,11,FALSE)+SUM(_xlfn.XLOOKUP($R9:$AK9,增益!$A:$A,增益!$K:$K,0)))/200,($F$12-$I$4+VLOOKUP($Q9,武学奇术!$A:$ZZ,11,FALSE)+SUM(_xlfn.XLOOKUP($R9:$AK9,增益!$A:$A,增益!$K:$K,0)))/100)} -> -0.06 | BE9: {=$G$12+VLOOKUP($Q9,武学奇术!$A:$ZZ,12,FALSE)+SUM(_xlfn.XLOOKUP($R9:$AK9,增益!$A:$A,增益!$L:$L,0))} -> 0.06 | BF9: =$D$13*(1+$AW9) -> 639.744 | BG9: =$E$13*(1+$AW9) -> 1823.136 | BH9: {=IF($F$13-$I$4+VLOOKUP($Q9,武学奇术!$A:$ZZ,13,FALSE)+SUM(_xlfn.XLOOKUP($R9:$AK9,增益!$A:$A,增益!$M:$M,0))>0,($F$13-$I$4+VLOOKUP($Q9,武学奇术!$A:$ZZ,13,FALSE)+SUM(_xlfn.XLOOKUP($R9:$AK9,增益!$A:$A,增益!$K:$K,0)))/200,($F$13-$I$4+VLOOKUP($Q9,武学奇术!$A:$ZZ,13,FALSE)+SUM(_xlfn.XLOOKUP($R9:$AK9,增益!$A:$A,增益!$M:$M,0)))/100)} -> 0.12 | BI9: {=$G$13+VLOOKUP($Q9,武学奇术!$A:$ZZ,14,FALSE)+SUM(_xlfn.XLOOKUP($R9:$AK9,增益!$A:$A,增益!$N:$N,0))} -> 0.33 | BJ9: =$D$14*(1+$AW9) -> 0 | BK9: =$E$14*(1+$AW9) -> 0 | BL9: {=IF($F$14-$I$4+VLOOKUP($Q9,武学奇术!$A:$ZZ,15,FALSE)+SUM(_xlfn.XLOOKUP($R9:$AK9,增益!$A:$A,增益!$O:$O,0))>0,($F$14-$I$4+VLOOKUP($Q9,武学奇术!$A:$ZZ,15,FALSE)+SUM(_xlfn.XLOOKUP($R9:$AK9,增益!$A:$A,增益!$O:$O,0)))/200,($F$14-$I$4+VLOOKUP($Q9,武学奇术!$A:$ZZ,15,FALSE)+SUM(_xlfn.XLOOKUP($R9:$AK9,增益!$A:$A,增益!$O:$O,0)))/100)} -> -0.06 | BM9: {=$G$14+VLOOKUP($Q9,武学奇术!$A:$ZZ,16,FALSE)+SUM(_xlfn.XLOOKUP($R9:$AK9,增益!$A:$A,增益!$P:$P,0))} -> 0.06 | BN9: =MIN(IF(VLOOKUP($Q9,武学奇术!$A:$ZZ,23,FALSE)=1,100%,$B$8),100%) -> 0.9859 | BO9: {=IF(VLOOKUP($Q9,武学奇术!$A:$ZZ,23,FALSE)=1,100%,MIN(80%,$B$9+VLOOKUP($Q9,武学奇术!$A:$ZZ,17,FALSE)+SUM(_xlfn.XLOOKUP($R9:$AK9,增益!$A:$A,增益!$Q:$Q,0)))+$B$11+SUM(_xlfn.XLOOKUP($R9:$AK9,增益!$A:$A,增益!$U:$U,0)))*IF(VLOOKUP($Q9,武学奇术!$A:$ZZ,24,FALSE)=1,0,1)} -> 0.8912 | BP9: {=1+$B$13+VLOOKUP($Q9,武学奇术!$A:$ZZ,18,FALSE)+SUM(_xlfn.XLOOKUP($R9:$AK9,增益!$A:$A,增益!$R:$R,0))} -> 1.55 | BQ9: {=IF(VLOOKUP($Q9,武学奇术!$A:$ZZ,24,FALSE)=1,100%,MIN(40%,$B$10+VLOOKUP($Q9,武学奇术!$A:$ZZ,19,FALSE)+SUM(_xlfn.XLOOKUP($R9:$AK9,增益!$A:$A,增益!$S:$S,0)))+$B$12+SUM(_xlfn.XLOOKUP($R9:$AK9,增益!$A:$A,增益!$V:$V,0)))*IF(VLOOKUP($Q9,武学奇术!$A:$ZZ,23,FALSE)=1,0,1)} -> 0.0929 | BR9: {=1+$B$14+VLOOKUP($Q9,武学奇术!$A:$ZZ,20,FALSE)+SUM(_xlfn.XLOOKUP($R9:$AK9,增益!$A:$A,增益!$T:$T,0))} -> 1.35 | BS9: =MIN((1-BQ9)*BN9,BN9*BO9) -> 0.87863408 | BT9: =1-BQ9-BS9-BU9 -> 0.01567581 | BU9: =IF(VLOOKUP($Q9,武学奇术!$A:$ZZ,22,FALSE)=1,0,(1-$BN9))*(1-$BQ9) -> 0.01279011 | BV9: {=SUM(_xlfn.XLOOKUP($R9:$AK9,增益!$A:$A,增益!$W:$W,0))+$I$5} -> 0.11
