Workbook

Sheet 期望
B1: 最小攻击 | C1: 最大攻击 | D1: 穿透 | E1: 伤害加成 | F1: 武学属性 | G1: 牵丝 | H1: 怪物属性 | K1: 期望 | L1: 会心期望 | M1: 会意期望 | N1: 普通期望 | O1: 擦伤期望 | P1: 次数 | Q1: 技能 | R1: 增益1 | S1: 增益2 | T1: 增益3 | U1: 增益4 | V1: 增益5 | W1: 增益6 | X1: 增益7 | Y1: 增益8 | Z1: 增益9 | AA1: 增益10 | AB1: 增益11 | AC1: 增益12 | AD1: 增益13 | AE1: 增益14 | AF1: 增益15 | AG1: 增益16 | AH1: 增益17 | AI1: 类型 | AJ1: 外功倍率 | AK1: 外攻固伤 | AL1: 属性倍率 | AM1: 属性固伤 | AN1: 通用增伤 | AO1: 外攻加成 | AP1: 即时小外 | AQ1: 即时大外 | AR1: 外穿加成 | AS1: 外伤加成 | AT1: 属攻加成 | AU1: 即时小鸣 | AV1: 即时大鸣 | AW1: 鸣金穿透 | AX1: 鸣金加成 | AY1: 即时小裂 | AZ1: 即时大裂 | BA1: 裂石穿透 | BB1: 裂石加成 | BC1: 即时小牵 | BD1: 即时大牵 | BE1: 牵丝穿透 | BF1: 牵丝加成 | BG1: 即时小破 | BH1: 即时大破 | BI1: 破竹穿透 | BJ1: 破竹加成 | BK1: 生效精准 | BL1: 生效会心 | BM1: 生效会心伤害 | BN1: 生效会意 | BO1: 生效会意伤害 | BP1: 会心占比 | BQ1: 普攻占比 | BR1: 擦伤占比 | BS1: 特殊增伤
A2: 外功 | B2: 2155.4 | C2: 5646 | D2: 63.5 | E2: =IF(J21="N/A",0,2.5%) -> 0 | F2: 套装 | G2: 烟柳 | H2: 防御 | I2: =620*(1-IF(F17="√",0.06,0)-IF(D20="√",0.04,0)) -> 558 | K2: =($L2*$BP2+$M2*$BN2+$N2*$BQ2+$O2*$BR2) -> 0 | L2: =((($AP2+$AQ2)/2*$AJ2+$AK2)*(1+$AR2)*(1+$AS2)+(($AU2+$AV2)/2*IF($G$1="鸣金",$AL2,$AJ2)+IF($G$1="鸣金",$AM2*1.5,0))*(1+$AW2)*(1+$AX2)+(($AY2+$AZ2)/2*IF($G$1="裂石",$AL2,$AJ2)+IF($G$1="裂石",$AM2*1.5,0))*(1+$BA2)*(1+$BB2)+(($BC2+$BD2)/2*IF($G$1="牵丝",$AL2,$AJ2)+IF($G$1="牵丝",$AM2*1.5,0))*(1+$BE2)*(1+$BF2)+(($BG2+$BH2)/2*IF($G$1="破竹",$AL2,$AJ2)+IF($G$1="破竹",$AM2*1.5,0))*(1+$BI2)*(1+$BJ2))*(1+$AN2)*$BM2*$P2*(1+IF(VLOOKUP($Q2,武学奇术!$A:$ZZ,30,FALSE)="弹道",$B$21,0))*(1+$BS2) -> 0 | M2: =(($AQ2*$AJ2+$AK2)*(1+$AR2)*(1+$AS2)+($AV2*IF($G$1="鸣金",$AL2,$AJ2)+IF($G$1="鸣金",$AM2*1.5,0))*(1+$AW2)*(1+$AX2)+($AZ2*IF($G$1="裂石",$AL2,$AJ2)+IF($G$1="裂石",$AM2*1.5,0))*(1+$BA2)*(1+$BB2)+($BD2*IF($G$1="牵丝",$AL2,$AJ2)+IF($G$1="牵丝",$AM2*1.5,0))*(1+$BE2)*(1+$BF2)+($BH2*IF($G$1="破竹",$AL2,$AJ2)+IF($G$1="破竹",$AM2*1.5,0))*(1+$BI2)*(1+$BJ2))*(1+$AN2)*$BO2*$P2*(1+IF(VLOOKUP($Q2,武学奇术!$A:$ZZ,30,FALSE)="弹道",$B$21,0))*(1+$BS2) -> 0 | N2: =((($AP2+$AQ2)/2*$AJ2+$AK2)*(1+$AR2)*(1+$AS2)+(($AU2+$AV2)/2*IF($G$1="鸣金",$AL2,$AJ2)+IF($G$1="鸣金",$AM2*1.5,0))*(1+$AW2)*(1+$AX2)+(($AY2+$AZ2)/2*IF($G$1="裂石",$AL2,$AJ2)+IF($G$1="裂石",$AM2*1.5,0))*(1+$BA2)*(1+$BB2)+(($BC2+$BD2)/2*IF($G$1="牵丝",$AL2,$AJ2)+IF($G$1="牵丝",$AM2*1.5,0))*(1+$BE2)*(1+$BF2)+(($BG2+$BH2)/2*IF($G$1="破竹",$AL2,$AJ2)+IF($G$1="破竹",$AM2*1.5,0))*(1+$BI2)*(1+$BJ2))*(1+$AN2)*$P2*(1+IF(VLOOKUP($Q2,武学奇术!$A:$ZZ,30,FALSE)="弹道",$B$21,0))*(1+$BS2) -> 0 | O2: =((($AP2*$AJ2+$AK2)*(1+$AR2)*(1+$AS2)+($AU2*IF($G$1="鸣金",$AL2,$AJ2)+IF($G$1="鸣金",$AM2*1.5,0))*(1+$AW2)*(1+$AX2)+($AY2*IF($G$1="裂石",$AL2,$AJ2)+IF($G$1="裂石",$AM2*1.5,0))*(1+$BA2)*(1+$BB2)+($BC2*IF($G$1="牵丝",$AL2,$AJ2)+IF($G$1="牵丝",$AM2*1.5,0))*(1+$BE2)*(1+$BF2)+($BG2*IF($G$1="破竹",$AL2,$AJ2)+IF($G$1="破竹",$AM2*1.5,0))*(1+$BI2)*(1+$BJ2))*(1+$AN2))*$P2*(1+IF(VLOOKUP($Q2,武学奇术!$A:$ZZ,30,FALSE)="弹道",$B$21,0))*(1+$BS2) -> 0 | P2: 1 | Q2: N/a | R2: N/a | S2: N/a | T2: N/a | U2: N/a | V2: N/a | W2: N/a | X2: N/a | Y2: N/a | Z2: N/a | AA2: N/a | AB2: N/a | AC2: N/a | AD2: N/a | AE2: N/a | AF2: N/a | AG2: N/a | AH2: N/a | AI2: =VLOOKUP($Q2,武学奇术!$A:$ZZ,25,FALSE) -> 心法 | AJ2: =VLOOKUP($Q2,武学奇术!$A:$ZZ,26,FALSE) -> 0 | AK2: =VLOOKUP($Q2,武学奇术!$A:$ZZ,27,FALSE)*(1+IF(OR($AI2=$F$4,$AI2=$F$5),$B$22,0)) -> 0 | AL2: =VLOOKUP($Q2,武学奇术!$A:$ZZ,28,FALSE) -> 0 | AM2: =VLOOKUP($Q2,武学奇术!$A:$ZZ,29,FALSE)*(1+IF(OR($AI2=$F$4,$AI2=$F$5),$B$22,0)) -> 0 | AN2: {=$G$3+IFERROR(VLOOKUP($AI2,$F$4:$G$7,2,FALSE),0)+VLOOKUP($Q2,武学奇术!$A:$ZZ,2,FALSE)+SUM(_xlfn.XLOOKUP($R2:$AH2,增益!$A:$A,增益!$B:$B,0))} -> 0.1837 | AO2: {=VLOOKUP($Q2,武学奇术!$A:$ZZ,5,FALSE)+SUM(_xlfn.XLOOKUP($R2:$AH2,增益!$A:$A,增益!$E:$E,0))} -> 0 | AP2: {=$D$10*(1+$AO2)+VLOOKUP($Q2,武学奇术!$A:$ZZ,3,FALSE)+SUM(_xlfn.XLOOKUP($R2:$AH2,增益!$A:$A,增益!$C:$C,0))-$I$2} -> 1797.4 | AQ2: {=$E$10*(1+$AO2)+VLOOKUP($Q2,武学奇术!$A:$ZZ,4,FALSE)+SUM(_xlfn.XLOOKUP($R2:$AH2,增益!$A:$A,增益!$D:$D,0))-$I$2} -> 5488 | AR2: {=IF($F$10-$I$3+VLOOKUP($Q2,武学奇术!$A:$ZZ,6,FALSE)+SUM(_xlfn.XLOOKUP(R2:AH2,增益!$A:$A,增益!$F:$F,0))>0,($F$10-$I$3+VLOOKUP($Q2,武学奇术!$A:$ZZ,6,FALSE)+SUM(_xlfn.XLOOKUP(R2:AH2,增益!$A:$A,增益!$F:$F,0)))/200,($F$10-$I$3+VLOOKUP($Q2,武学奇术!$A:$ZZ,6,FALSE)+SUM(_xlfn.XLOOKUP(R2:AH2,增益!$A:$A,增益!$F:$F,0)))/100)} -> 0.2925 | AS2: {=$G$10+VLOOKUP($Q2,武学奇术!$A:$ZZ,7,FALSE)+SUM(_xlfn.XLOOKUP(R2:AH2,增益!$A:$A,增益!$G:$G,0))} -> 0 | AT2: {=VLOOKUP($Q2,武学奇术!$A:$ZZ,8,FALSE)+SUM(_xlfn.XLOOKUP(R2:AH2,增益!$A:$A,增益!$H:$H,0))} -> 0 | AU2: =$D$11*(1+$AT2) -> 0 | AV2: =$E$11*(1+$AT2) -> 0 | AW2: {=IF($F$11-$I$4+VLOOKUP($Q2,武学奇术!$A:$ZZ,9,FALSE)+SUM(_xlfn.XLOOKUP(R2:AH2,增益!$A:$A,增益!$I:$I,0))>0,($F$11-$I$4+VLOOKUP($Q2,武学奇术!$A:$ZZ,9,FALSE)+SUM(_xlfn.XLOOKUP(R2:AH2,增益!$A:$A,增益!$I:$I,0)))/200,($F$11-$I$4+VLOOKUP($Q2,武学奇术!$A:$ZZ,9,FALSE)+SUM(_xlfn.XLOOKUP(R2:AH2,增益!$A:$A,增益!$I:$I,0)))/100)} -> -0.3 | AX2: {=$G$11+VLOOKUP($Q2,武学奇术!$A:$ZZ,10,FALSE)+SUM(_xlfn.XLOOKUP(R2:AH2,增益!$A:$A,增益!$J:$J,0))} -> 0 | AY2: =$D$12*(1+$AT2) -> 0 | AZ2: =$E$12*(1+$AT2) -> 0 | BA2: {=IF($F$12-$I$4+VLOOKUP($Q2,武学奇术!$A:$ZZ,11,FALSE)+SUM(_xlfn.XLOOKUP(R2:AH2,增益!$A:$A,增益!$K:$K,0))>0,($F$12-$I$4+VLOOKUP($Q2,武学奇术!$A:$ZZ,11,FALSE)+SUM(_xlfn.XLOOKUP(R2:AH2,增益!$A:$A,增益!$K:$K,0)))/200,($F$12-$I$4+VLOOKUP($Q2,武学奇术!$A:$ZZ,11,FALSE)+SUM(_xlfn.XLOOKUP(R2:AH2,增益!$A:$A,增益!$K:$K,0)))/100)} -> -0.3 | BB2: {=$G$12+VLOOKUP($Q2,武学奇术!$A:$ZZ,12,FALSE)+SUM(_xlfn.XLOOKUP(R2:AH2,增益!$A:$A,增益!$L:$L,0))} -> 0 | BC2: =$D$13*(1+$AT2) -> 571.2 | BD2: =$E$13*(1+$AT2) -> 1077.4 | BE2: {=IF($F$13-$I$4+VLOOKUP($Q2,武学奇术!$A:$ZZ,13,FALSE)+SUM(_xlfn.XLOOKUP(R2:AH2,增益!$A:$A,增益!$M:$M,0))>0,($F$13-$I$4+VLOOKUP($Q2,武学奇术!$A:$ZZ,13,FALSE)+SUM(_xlfn.XLOOKUP(R2:AH2,增益!$A:$A,增益!$K:$K,0)))/200,($F$13-$I$4+VLOOKUP($Q2,武学奇术!$A:$ZZ,13,FALSE)+SUM(_xlfn.XLOOKUP(R2:AH2,增益!$A:$A,增益!$M:$M,0)))/100)} -> 0 | BF2: {=$G$13+VLOOKUP($Q2,武学奇术!$A:$ZZ,14,FALSE)+SUM(_xlfn.XLOOKUP(R2:AH2,增益!$A:$A,增益!$N:$N,0))} -> 0.15 | BG2: =$D$14*(1+$AT2) -> 0 | BH2: =$E$14*(1+$AT2) -> 0 | BI2: {=IF($F$14-$I$4+VLOOKUP($Q2,武学奇术!$A:$ZZ,15,FALSE)+SUM(_xlfn.XLOOKUP(R2:AH2,增益!$A:$A,增益!$O:$O,0))>0,($F$14-$I$4+VLOOKUP($Q2,武学奇术!$A:$ZZ,15,FALSE)+SUM(_xlfn.XLOOKUP(R2:AH2,增益!$A:$A,增益!$O:$O,0)))/200,($F$14-$I$4+VLOOKUP($Q2,武学奇术!$A:$ZZ,15,FALSE)+SUM(_xlfn.XLOOKUP(R2:AH2,增益!$A:$A,增益!$O:$O,0)))/100)} -> -0.3 | BJ2: {=$G$14+VLOOKUP($Q2,武学奇术!$A:$ZZ,16,FALSE)+SUM(_xlfn.XLOOKUP(R2:AH2,增益!$A:$A,增益!$P:$P,0))} -> 0 | BK2: =MIN(IF(VLOOKUP($Q2,武学奇术!$A:$ZZ,23,FALSE)=1,100%,$B$8),100%) -> 1 | BL2: {=IF(VLOOKUP($Q2,武学奇术!$A:$ZZ,23,FALSE)=1,100%,MIN(80%,$B$9+VLOOKUP($Q2,武学奇术!$A:$ZZ,17,FALSE)+SUM(_xlfn.XLOOKUP(R2:AH2,增益!$A:$A,增益!$Q:$Q,0)))+$B$11+SUM(_xlfn.XLOOKUP(R2:AH2,增益!$A:$A,增益!$U:$U,0)))*IF(VLOOKUP($Q2,武学奇术!$A:$ZZ,24,FALSE)=1,0,1)} -> 0.9045 | BM2: {=1+$B$13+VLOOKUP($Q2,武学奇术!$A:$ZZ,18,FALSE)+SUM(_xlfn.XLOOKUP(R2:AH2,增益!$A:$A,增益!$R:$R,0))} -> 1.5 | BN2: {=IF(VLOOKUP($Q2,武学奇术!$A:$ZZ,24,FALSE)=1,100%,MIN(40%,$B$10+VLOOKUP($Q2,武学奇术!$A:$ZZ,19,FALSE)+SUM(_xlfn.XLOOKUP(R2:AH2,增益!$A:$A,增益!$S:$S,0)))+$B$12+SUM(_xlfn.XLOOKUP(R2:AH2,增益!$A:$A,增益!$V:$V,0)))*IF(VLOOKUP($Q2,武学奇术!$A:$ZZ,23,FALSE)=1,0,1)} -> 0.0929 | BO2: {=1+$B$14+VLOOKUP($Q2,武学奇术!$A:$ZZ,20,FALSE)+SUM(_xlfn.XLOOKUP(R2:AH2,增益!$A:$A,增益!$T:$T,0))} -> 1.35 | BP2: =MIN((1-BN2)*BK2,BK2*BL2) -> 0.9045 | BQ2: =1-BN2-BP2-BR2 -> 0.0026 | BR2: =IF(VLOOKUP($Q2,武学奇术!$A:$ZZ,22,FALSE)=1,0,(1-$BK2))*(1-$BN2) -> 0 | BS2: {=SUM(_xlfn.XLOOKUP(R2:AH2,增益!$A:$A,增益!$W:$W,0))+$I$5} -> 0.06
A3: 鸣金 | F3: 通用增伤 | G3: =B16+1.5%+IF($D$16="√",8%,0)+IF($C$22="征人归",8%,0) -> 0.1837 | H3: 外抗 | I3: =25-IF(D17="√",10,0)-IF(F17="√",10,0) -> 5 | K3: =($L3*$BP3+$M3*$BN3+$N3*$BQ3+$O3*$BR3) -> 0 | L3: =((($AP3+$AQ3)/2*$AJ3+$AK3)*(1+$AR3)*(1+$AS3)+(($AU3+$AV3)/2*IF($G$1="鸣金",$AL3,$AJ3)+IF($G$1="鸣金",$AM3*1.5,0))*(1+$AW3)*(1+$AX3)+(($AY3+$AZ3)/2*IF($G$1="裂石",$AL3,$AJ3)+IF($G$1="裂石",$AM3*1.5,0))*(1+$BA3)*(1+$BB3)+(($BC3+$BD3)/2*IF($G$1="牵丝",$AL3,$AJ3)+IF($G$1="牵丝",$AM3*1.5,0))*(1+$BE3)*(1+$BF3)+(($BG3+$BH3)/2*IF($G$1="破竹",$AL3,$AJ3)+IF($G$1="破竹",$AM3*1.5,0))*(1+$BI3)*(1+$BJ3))*(1+$AN3)*$BM3*$P3*(1+IF(VLOOKUP($Q3,武学奇术!$A:$ZZ,30,FALSE)="弹道",$B$21,0))*(1+$BS3) -> 0 | M3: =(($AQ3*$AJ3+$AK3)*(1+$AR3)*(1+$AS3)+($AV3*IF($G$1="鸣金",$AL3,$AJ3)+IF($G$1="鸣金",$AM3*1.5,0))*(1+$AW3)*(1+$AX3)+($AZ3*IF($G$1="裂石",$AL3,$AJ3)+IF($G$1="裂石",$AM3*1.5,0))*(1+$BA3)*(1+$BB3)+($BD3*IF($G$1="牵丝",$AL3,$AJ3)+IF($G$1="牵丝",$AM3*1.5,0))*(1+$BE3)*(1+$BF3)+($BH3*IF($G$1="破竹",$AL3,$AJ3)+IF($G$1="破竹",$AM3*1.5,0))*(1+$BI3)*(1+$BJ3))*(1+$AN3)*$BO3*$P3*(1+IF(VLOOKUP($Q3,武学奇术!$A:$ZZ,30,FALSE)="弹道",$B$21,0))*(1+$BS3) -> 0 | N3: =((($AP3+$AQ3)/2*$AJ3+$AK3)*(1+$AR3)*(1+$AS3)+(($AU3+$AV3)/2*IF($G$1="鸣金",$AL3,$AJ3)+IF($G$1="鸣金",$AM3*1.5,0))*(1+$AW3)*(1+$AX3)+(($AY3+$AZ3)/2*IF($G$1="裂石",$AL3,$AJ3)+IF($G$1="裂石",$AM3*1.5,0))*(1+$BA3)*(1+$BB3)+(($BC3+$BD3)/2*IF($G$1="牵丝",$AL3,$AJ3)+IF($G$1="牵丝",$AM3*1.5,0))*(1+$BE3)*(1+$BF3)+(($BG3+$BH3)/2*IF($G$1="破竹",$AL3,$AJ3)+IF($G$1="破竹",$AM3*1.5,0))*(1+$BI3)*(1+$BJ3))*(1+$AN3)*$P3*(1+IF(VLOOKUP($Q3,武学奇术!$A:$ZZ,30,FALSE)="弹道",$B$21,0))*(1+$BS3) -> 0 | O3: =((($AP3*$AJ3+$AK3)*(1+$AR3)*(1+$AS3)+($AU3*IF($G$1="鸣金",$AL3,$AJ3)+IF($G$1="鸣金",$AM3*1.5,0))*(1+$AW3)*(1+$AX3)+($AY3*IF($G$1="裂石",$AL3,$AJ3)+IF($G$1="裂石",$AM3*1.5,0))*(1+$BA3)*(1+$BB3)+($BC3*IF($G$1="牵丝",$AL3,$AJ3)+IF($G$1="牵丝",$AM3*1.5,0))*(1+$BE3)*(1+$BF3)+($BG3*IF($G$1="破竹",$AL3,$AJ3)+IF($G$1="破竹",$AM3*1.5,0))*(1+$BI3)*(1+$BJ3))*(1+$AN3))*$P3*(1+IF(VLOOKUP($Q3,武学奇术!$A:$ZZ,30,FALSE)="弹道",$B$21,0))*(1+$BS3) -> 0 | P3: 1 | Q3: N/a | R3: N/a | S3: N/a | T3: N/a | U3: N/a | V3: N/a | W3: N/a | X3: N/a | Y3: N/a | Z3: N/a | AA3: N/a | AB3: N/a | AC3: N/a | AD3: N/a | AE3: N/a | AF3: N/a | AG3: N/a | AH3: N/a | AI3: =VLOOKUP($Q3,武学奇术!$A:$ZZ,25,FALSE) -> 心法 | AJ3: =VLOOKUP($Q3,武学奇术!$A:$ZZ,26,FALSE) -> 0 | AK3: =VLOOKUP($Q3,武学奇术!$A:$ZZ,27,FALSE)*(1+IF(OR($AI3=$F$4,$AI3=$F$5),$B$22,0)) -> 0 | AL3: =VLOOKUP($Q3,武学奇术!$A:$ZZ,28,FALSE) -> 0 | AM3: =VLOOKUP($Q3,武学奇术!$A:$ZZ,29,FALSE)*(1+IF(OR($AI3=$F$4,$AI3=$F$5),$B$22,0)) -> 0 | AN3: {=$G$3+IFERROR(VLOOKUP($AI3,$F$4:$G$7,2,FALSE),0)+VLOOKUP($Q3,武学奇术!$A:$ZZ,2,FALSE)+SUM(_xlfn.XLOOKUP($R3:$AH3,增益!$A:$A,增益!$B:$B,0))} -> 0.1837 | AO3: {=VLOOKUP($Q3,武学奇术!$A:$ZZ,5,FALSE)+SUM(_xlfn.XLOOKUP($R3:$AH3,增益!$A:$A,增益!$E:$E,0))} -> 0 | AP3: {=$D$10*(1+$AO3)+VLOOKUP($Q3,武学奇术!$A:$ZZ,3,FALSE)+SUM(_xlfn.XLOOKUP($R3:$AH3,增益!$A:$A,增益!$C:$C,0))-$I$2} -> 1797.4 | AQ3: {=$E$10*(1+$AO3)+VLOOKUP($Q3,武学奇术!$A:$ZZ,4,FALSE)+SUM(_xlfn.XLOOKUP($R3:$AH3,增益!$A:$A,增益!$D:$D,0))-$I$2} -> 5488 | AR3: {=IF($F$10-$I$3+VLOOKUP($Q3,武学奇术!$A:$ZZ,6,FALSE)+SUM(_xlfn.XLOOKUP(R3:AH3,增益!$A:$A,增益!$F:$F,0))>0,($F$10-$I$3+VLOOKUP($Q3,武学奇术!$A:$ZZ,6,FALSE)+SUM(_xlfn.XLOOKUP(R3:AH3,增益!$A:$A,增益!$F:$F,0)))/200,($F$10-$I$3+VLOOKUP($Q3,武学奇术!$A:$ZZ,6,FALSE)+SUM(_xlfn.XLOOKUP(R3:AH3,增益!$A:$A,增益!$F:$F,0)))/100)} -> 0.2925 | AS3: {=$G$10+VLOOKUP($Q3,武学奇术!$A:$ZZ,7,FALSE)+SUM(_xlfn.XLOOKUP(R3:AH3,增益!$A:$A,增益!$G:$G,0))} -> 0 | AT3: {=VLOOKUP($Q3,武学奇术!$A:$ZZ,8,FALSE)+SUM(_xlfn.XLOOKUP(R3:AH3,增益!$A:$A,增益!$H:$H,0))} -> 0 | AU3: =$D$11*(1+$AT3) -> 0 | AV3: =$E$11*(1+$AT3) -> 0 | AW3: {=IF($F$11-$I$4+VLOOKUP($Q3,武学奇术!$A:$ZZ,9,FALSE)+SUM(_xlfn.XLOOKUP(R3:AH3,增益!$A:$A,增益!$I:$I,0))>0,($F$11-$I$4+VLOOKUP($Q3,武学奇术!$A:$ZZ,9,FALSE)+SUM(_xlfn.XLOOKUP(R3:AH3,增益!$A:$A,增益!$I:$I,0)))/200,($F$11-$I$4+VLOOKUP($Q3,武学奇术!$A:$ZZ,9,FALSE)+SUM(_xlfn.XLOOKUP(R3:AH3,增益!$A:$A,增益!$I:$I,0)))/100)} -> -0.3 | AX3: {=$G$11+VLOOKUP($Q3,武学奇术!$A:$ZZ,10,FALSE)+SUM(_xlfn.XLOOKUP(R3:AH3,增益!$A:$A,增益!$J:$J,0))} -> 0 | AY3: =$D$12*(1+$AT3) -> 0 | AZ3: =$E$12*(1+$AT3) -> 0 | BA3: {=IF($F$12-$I$4+VLOOKUP($Q3,武学奇术!$A:$ZZ,11,FALSE)+SUM(_xlfn.XLOOKUP(R3:AH3,增益!$A:$A,增益!$K:$K,0))>0,($F$12-$I$4+VLOOKUP($Q3,武学奇术!$A:$ZZ,11,FALSE)+SUM(_xlfn.XLOOKUP(R3:AH3,增益!$A:$A,增益!$K:$K,0)))/200,($F$12-$I$4+VLOOKUP($Q3,武学奇术!$A:$ZZ,11,FALSE)+SUM(_xlfn.XLOOKUP(R3:AH3,增益!$A:$A,增益!$K:$K,0)))/100)} -> -0.3 | BB3: {=$G$12+VLOOKUP($Q3,武学奇术!$A:$ZZ,12,FALSE)+SUM(_xlfn.XLOOKUP(R3:AH3,增益!$A:$A,增益!$L:$L,0))} -> 0 | BC3: =$D$13*(1+$AT3) -> 571.2 | BD3: =$E$13*(1+$AT3) -> 1077.4 | BE3: {=IF($F$13-$I$4+VLOOKUP($Q3,武学奇术!$A:$ZZ,13,FALSE)+SUM(_xlfn.XLOOKUP(R3:AH3,增益!$A:$A,增益!$M:$M,0))>0,($F$13-$I$4+VLOOKUP($Q3,武学奇术!$A:$ZZ,13,FALSE)+SUM(_xlfn.XLOOKUP(R3:AH3,增益!$A:$A,增益!$K:$K,0)))/200,($F$13-$I$4+VLOOKUP($Q3,武学奇术!$A:$ZZ,13,FALSE)+SUM(_xlfn.XLOOKUP(R3:AH3,增益!$A:$A,增益!$M:$M,0)))/100)} -> 0 | BF3: {=$G$13+VLOOKUP($Q3,武学奇术!$A:$ZZ,14,FALSE)+SUM(_xlfn.XLOOKUP(R3:AH3,增益!$A:$A,增益!$N:$N,0))} -> 0.15 | BG3: =$D$14*(1+$AT3) -> 0 | BH3: =$E$14*(1+$AT3) -> 0 | BI3: {=IF($F$14-$I$4+VLOOKUP($Q3,武学奇术!$A:$ZZ,15,FALSE)+SUM(_xlfn.XLOOKUP(R3:AH3,增益!$A:$A,增益!$O:$O,0))>0,($F$14-$I$4+VLOOKUP($Q3,武学奇术!$A:$ZZ,15,FALSE)+SUM(_xlfn.XLOOKUP(R3:AH3,增益!$A:$A,增益!$O:$O,0)))/200,($F$14-$I$4+VLOOKUP($Q3,武学奇术!$A:$ZZ,15,FALSE)+SUM(_xlfn.XLOOKUP(R3:AH3,增益!$A:$A,增益!$O:$O,0)))/100)} -> -0.3 | BJ3: {=$G$14+VLOOKUP($Q3,武学奇术!$A:$ZZ,16,FALSE)+SUM(_xlfn.XLOOKUP(R3:AH3,增益!$A:$A,增益!$P:$P,0))} -> 0 | BK3: =MIN(IF(VLOOKUP($Q3,武学奇术!$A:$ZZ,23,FALSE)=1,100%,$B$8),100%) -> 1 | BL3: {=IF(VLOOKUP($Q3,武学奇术!$A:$ZZ,23,FALSE)=1,100%,MIN(80%,$B$9+VLOOKUP($Q3,武学奇术!$A:$ZZ,17,FALSE)+SUM(_xlfn.XLOOKUP(R3:AH3,增益!$A:$A,增益!$Q:$Q,0)))+$B$11+SUM(_xlfn.XLOOKUP(R3:AH3,增益!$A:$A,增益!$U:$U,0)))*IF(VLOOKUP($Q3,武学奇术!$A:$ZZ,24,FALSE)=1,0,1)} -> 0.9045 | BM3: {=1+$B$13+VLOOKUP($Q3,武学奇术!$A:$ZZ,18,FALSE)+SUM(_xlfn.XLOOKUP(R3:AH3,增益!$A:$A,增益!$R:$R,0))} -> 1.5 | BN3: {=IF(VLOOKUP($Q3,武学奇术!$A:$ZZ,24,FALSE)=1,100%,MIN(40%,$B$10+VLOOKUP($Q3,武学奇术!$A:$ZZ,19,FALSE)+SUM(_xlfn.XLOOKUP(R3:AH3,增益!$A:$A,增益!$S:$S,0)))+$B$12+SUM(_xlfn.XLOOKUP(R3:AH3,增益!$A:$A,增益!$V:$V,0)))*IF(VLOOKUP($Q3,武学奇术!$A:$ZZ,23,FALSE)=1,0,1)} -> 0.0929 | BO3: {=1+$B$14+VLOOKUP($Q3,武学奇术!$A:$ZZ,20,FALSE)+SUM(_xlfn.XLOOKUP(R3:AH3,增益!$A:$A,增益!$T:$T,0))} -> 1.35 | BP3: =MIN((1-BN3)*BK3,BK3*BL3) -> 0.9045 | BQ3: =1-BN3-BP3-BR3 -> 0.0026 | BR3: =IF(VLOOKUP($Q3,武学奇术!$A:$ZZ,22,FALSE)=1,0,(1-$BK3))*(1-$BN3) -> 0 | BS3: {=SUM(_xlfn.XLOOKUP(R3:AH3,增益!$A:$A,增益!$W:$W,0))+$I$5} -> 0.06
A4: 裂石 | F4: 伞 | G4: =B15+B17 -> 0.1704 | H4: 属抗 | I4: =30 -> 30 | K4: =($L4*$BP4+$M4*$BN4+$N4*$BQ4+$O4*$BR4) -> 0 | L4: =((($AP4+$AQ4)/2*$AJ4+$AK4)*(1+$AR4)*(1+$AS4)+(($AU4+$AV4)/2*IF($G$1="鸣金",$AL4,$AJ4)+IF($G$1="鸣金",$AM4*1.5,0))*(1+$AW4)*(1+$AX4)+(($AY4+$AZ4)/2*IF($G$1="裂石",$AL4,$AJ4)+IF($G$1="裂石",$AM4*1.5,0))*(1+$BA4)*(1+$BB4)+(($BC4+$BD4)/2*IF($G$1="牵丝",$AL4,$AJ4)+IF($G$1="牵丝",$AM4*1.5,0))*(1+$BE4)*(1+$BF4)+(($BG4+$BH4)/2*IF($G$1="破竹",$AL4,$AJ4)+IF($G$1="破竹",$AM4*1.5,0))*(1+$BI4)*(1+$BJ4))*(1+$AN4)*$BM4*$P4*(1+IF(VLOOKUP($Q4,武学奇术!$A:$ZZ,30,FALSE)="弹道",$B$21,0))*(1+$BS4) -> 0 | M4: =(($AQ4*$AJ4+$AK4)*(1+$AR4)*(1+$AS4)+($AV4*IF($G$1="鸣金",$AL4,$AJ4)+IF($G$1="鸣金",$AM4*1.5,0))*(1+$AW4)*(1+$AX4)+($AZ4*IF($G$1="裂石",$AL4,$AJ4)+IF($G$1="裂石",$AM4*1.5,0))*(1+$BA4)*(1+$BB4)+($BD4*IF($G$1="牵丝",$AL4,$AJ4)+IF($G$1="牵丝",$AM4*1.5,0))*(1+$BE4)*(1+$BF4)+($BH4*IF($G$1="破竹",$AL4,$AJ4)+IF($G$1="破竹",$AM4*1.5,0))*(1+$BI4)*(1+$BJ4))*(1+$AN4)*$BO4*$P4*(1+IF(VLOOKUP($Q4,武学奇术!$A:$ZZ,30,FALSE)="弹道",$B$21,0))*(1+$BS4) -> 0 | N4: =((($AP4+$AQ4)/2*$AJ4+$AK4)*(1+$AR4)*(1+$AS4)+(($AU4+$AV4)/2*IF($G$1="鸣金",$AL4,$AJ4)+IF($G$1="鸣金",$AM4*1.5,0))*(1+$AW4)*(1+$AX4)+(($AY4+$AZ4)/2*IF($G$1="裂石",$AL4,$AJ4)+IF($G$1="裂石",$AM4*1.5,0))*(1+$BA4)*(1+$BB4)+(($BC4+$BD4)/2*IF($G$1="牵丝",$AL4,$AJ4)+IF($G$1="牵丝",$AM4*1.5,0))*(1+$BE4)*(1+$BF4)+(($BG4+$BH4)/2*IF($G$1="破竹",$AL4,$AJ4)+IF($G$1="破竹",$AM4*1.5,0))*(1+$BI4)*(1+$BJ4))*(1+$AN4)*$P4*(1+IF(VLOOKUP($Q4,武学奇术!$A:$ZZ,30,FALSE)="弹道",$B$21,0))*(1+$BS4) -> 0 | O4: =((($AP4*$AJ4+$AK4)*(1+$AR4)*(1+$AS4)+($AU4*IF($G$1="鸣金",$AL4,$AJ4)+IF($G$1="鸣金",$AM4*1.5,0))*(1+$AW4)*(1+$AX4)+($AY4*IF($G$1="裂石",$AL4,$AJ4)+IF($G$1="裂石",$AM4*1.5,0))*(1+$BA4)*(1+$BB4)+($BC4*IF($G$1="牵丝",$AL4,$AJ4)+IF($G$1="牵丝",$AM4*1.5,0))*(1+$BE4)*(1+$BF4)+($BG4*IF($G$1="破竹",$AL4,$AJ4)+IF($G$1="破竹",$AM4*1.5,0))*(1+$BI4)*(1+$BJ4))*(1+$AN4))*$P4*(1+IF(VLOOKUP($Q4,武学奇术!$A:$ZZ,30,FALSE)="弹道",$B$21,0))*(1+$BS4) -> 0 | P4: 1 | Q4: N/a | R4: N/a | S4: N/a | T4: N/a | U4: N/a | V4: N/a | W4: N/a | X4: N/a | Y4: N/a | Z4: N/a | AA4: N/a | AB4: N/a | AC4: N/a | AD4: N/a | AE4: N/a | AF4: N/a | AG4: N/a | AH4: N/a | AI4: =VLOOKUP($Q4,武学奇术!$A:$ZZ,25,FALSE) -> 心法 | AJ4: =VLOOKUP($Q4,武学奇术!$A:$ZZ,26,FALSE) -> 0 | AK4: =VLOOKUP($Q4,武学奇术!$A:$ZZ,27,FALSE)*(1+IF(OR($AI4=$F$4,$AI4=$F$5),$B$22,0)) -> 0 | AL4: =VLOOKUP($Q4,武学奇术!$A:$ZZ,28,FALSE) -> 0 | AM4: =VLOOKUP($Q4,武学奇术!$A:$ZZ,29,FALSE)*(1+IF(OR($AI4=$F$4,$AI4=$F$5),$B$22,0)) -> 0 | AN4: {=$G$3+IFERROR(VLOOKUP($AI4,$F$4:$G$7,2,FALSE),0)+VLOOKUP($Q4,武学奇术!$A:$ZZ,2,FALSE)+SUM(_xlfn.XLOOKUP($R4:$AH4,增益!$A:$A,增益!$B:$B,0))} -> 0.1837 | AO4: {=VLOOKUP($Q4,武学奇术!$A:$ZZ,5,FALSE)+SUM(_xlfn.XLOOKUP($R4:$AH4,增益!$A:$A,增益!$E:$E,0))} -> 0 | AP4: {=$D$10*(1+$AO4)+VLOOKUP($Q4,武学奇术!$A:$ZZ,3,FALSE)+SUM(_xlfn.XLOOKUP($R4:$AH4,增益!$A:$A,增益!$C:$C,0))-$I$2} -> 1797.4 | AQ4: {=$E$10*(1+$AO4)+VLOOKUP($Q4,武学奇术!$A:$ZZ,4,FALSE)+SUM(_xlfn.XLOOKUP($R4:$AH4,增益!$A:$A,增益!$D:$D,0))-$I$2} -> 5488 | AR4: {=IF($F$10-$I$3+VLOOKUP($Q4,武学奇术!$A:$ZZ,6,FALSE)+SUM(_xlfn.XLOOKUP(R4:AH4,增益!$A:$A,增益!$F:$F,0))>0,($F$10-$I$3+VLOOKUP($Q4,武学奇术!$A:$ZZ,6,FALSE)+SUM(_xlfn.XLOOKUP(R4:AH4,增益!$A:$A,增益!$F:$F,0)))/200,($F$10-$I$3+VLOOKUP($Q4,武学奇术!$A:$ZZ,6,FALSE)+SUM(_xlfn.XLOOKUP(R4:AH4,增益!$A:$A,增益!$F:$F,0)))/100)} -> 0.2925 | AS4: {=$G$10+VLOOKUP($Q4,武学奇术!$A:$ZZ,7,FALSE)+SUM(_xlfn.XLOOKUP(R4:AH4,增益!$A:$A,增益!$G:$G,0))} -> 0 | AT4: {=VLOOKUP($Q4,武学奇术!$A:$ZZ,8,FALSE)+SUM(_xlfn.XLOOKUP(R4:AH4,增益!$A:$A,增益!$H:$H,0))} -> 0 | AU4: =$D$11*(1+$AT4) -> 0 | AV4: =$E$11*(1+$AT4) -> 0 | AW4: {=IF($F$11-$I$4+VLOOKUP($Q4,武学奇术!$A:$ZZ,9,FALSE)+SUM(_xlfn.XLOOKUP(R4:AH4,增益!$A:$A,增益!$I:$I,0))>0,($F$11-$I$4+VLOOKUP($Q4,武学奇术!$A:$ZZ,9,FALSE)+SUM(_xlfn.XLOOKUP(R4:AH4,增益!$A:$A,增益!$I:$I,0)))/200,($F$11-$I$4+VLOOKUP($Q4,武学奇术!$A:$ZZ,9,FALSE)+SUM(_xlfn.XLOOKUP(R4:AH4,增益!$A:$A,增益!$I:$I,0)))/100)} -> -0.3 | AX4: {=$G$11+VLOOKUP($Q4,武学奇术!$A:$ZZ,10,FALSE)+SUM(_xlfn.XLOOKUP(R4:AH4,增益!$A:$A,增益!$J:$J,0))} -> 0 | AY4: =$D$12*(1+$AT4) -> 0 | AZ4: =$E$12*(1+$AT4) -> 0 | BA4: {=IF($F$12-$I$4+VLOOKUP($Q4,武学奇术!$A:$ZZ,11,FALSE)+SUM(_xlfn.XLOOKUP(R4:AH4,增益!$A:$A,增益!$K:$K,0))>0,($F$12-$I$4+VLOOKUP($Q4,武学奇术!$A:$ZZ,11,FALSE)+SUM(_xlfn.XLOOKUP(R4:AH4,增益!$A:$A,增益!$K:$K,0)))/200,($F$12-$I$4+VLOOKUP($Q4,武学奇术!$A:$ZZ,11,FALSE)+SUM(_xlfn.XLOOKUP(R4:AH4,增益!$A:$A,增益!$K:$K,0)))/100)} -> -0.3 | BB4: {=$G$12+VLOOKUP($Q4,武学奇术!$A:$ZZ,12,FALSE)+SUM(_xlfn.XLOOKUP(R4:AH4,增益!$A:$A,增益!$L:$L,0))} -> 0 | BC4: =$D$13*(1+$AT4) -> 571.2 | BD4: =$E$13*(1+$AT4) -> 1077.4 | BE4: {=IF($F$13-$I$4+VLOOKUP($Q4,武学奇术!$A:$ZZ,13,FALSE)+SUM(_xlfn.XLOOKUP(R4:AH4,增益!$A:$A,增益!$M:$M,0))>0,($F$13-$I$4+VLOOKUP($Q4,武学奇术!$A:$ZZ,13,FALSE)+SUM(_xlfn.XLOOKUP(R4:AH4,增益!$A:$A,增益!$K:$K,0)))/200,($F$13-$I$4+VLOOKUP($Q4,武学奇术!$A:$ZZ,13,FALSE)+SUM(_xlfn.XLOOKUP(R4:AH4,增益!$A:$A,增益!$M:$M,0)))/100)} -> 0 | BF4: {=$G$13+VLOOKUP($Q4,武学奇术!$A:$ZZ,14,FALSE)+SUM(_xlfn.XLOOKUP(R4:AH4,增益!$A:$A,增益!$N:$N,0))} -> 0.15 | BG4: =$D$14*(1+$AT4) -> 0 | BH4: =$E$14*(1+$AT4) -> 0 | BI4: {=IF($F$14-$I$4+VLOOKUP($Q4,武学奇术!$A:$ZZ,15,FALSE)+SUM(_xlfn.XLOOKUP(R4:AH4,增益!$A:$A,增益!$O:$O,0))>0,($F$14-$I$4+VLOOKUP($Q4,武学奇术!$A:$ZZ,15,FALSE)+SUM(_xlfn.XLOOKUP(R4:AH4,增益!$A:$A,增益!$O:$O,0)))/200,($F$14-$I$4+VLOOKUP($Q4,武学奇术!$A:$ZZ,15,FALSE)+SUM(_xlfn.XLOOKUP(R4:AH4,增益!$A:$A,增益!$O:$O,0)))/100)} -> -0.3 | BJ4: {=$G$14+VLOOKUP($Q4,武学奇术!$A:$ZZ,16,FALSE)+SUM(_xlfn.XLOOKUP(R4:AH4,增益!$A:$A,增益!$P:$P,0))} -> 0 | BK4: =MIN(IF(VLOOKUP($Q4,武学奇术!$A:$ZZ,23,FALSE)=1,100%,$B$8),100%) -> 1 | BL4: {=IF(VLOOKUP($Q4,武学奇术!$A:$ZZ,23,FALSE)=1,100%,MIN(80%,$B$9+VLOOKUP($Q4,武学奇术!$A:$ZZ,17,FALSE)+SUM(_xlfn.XLOOKUP(R4:AH4,增益!$A:$A,增益!$Q:$Q,0)))+$B$11+SUM(_xlfn.XLOOKUP(R4:AH4,增益!$A:$A,增益!$U:$U,0)))*IF(VLOOKUP($Q4,武学奇术!$A:$ZZ,24,FALSE)=1,0,1)} -> 0.9045 | BM4: {=1+$B$13+VLOOKUP($Q4,武学奇术!$A:$ZZ,18,FALSE)+SUM(_xlfn.XLOOKUP(R4:AH4,增益!$A:$A,增益!$R:$R,0))} -> 1.5 | BN4: {=IF(VLOOKUP($Q4,武学奇术!$A:$ZZ,24,FALSE)=1,100%,MIN(40%,$B$10+VLOOKUP($Q4,武学奇术!$A:$ZZ,19,FALSE)+SUM(_xlfn.XLOOKUP(R4:AH4,增益!$A:$A,增益!$S:$S,0)))+$B$12+SUM(_xlfn.XLOOKUP(R4:AH4,增益!$A:$A,增益!$V:$V,0)))*IF(VLOOKUP($Q4,武学奇术!$A:$ZZ,23,FALSE)=1,0,1)} -> 0.0929 | BO4: {=1+$B$14+VLOOKUP($Q4,武学奇术!$A:$ZZ,20,FALSE)+SUM(_xlfn.XLOOKUP(R4:AH4,增益!$A:$A,增益!$T:$T,0))} -> 1.35 | BP4: =MIN((1-BN4)*BK4,BK4*BL4) -> 0.9045 | BQ4: =1-BN4-BP4-BR4 -> 0.0026 | BR4: =IF(VLOOKUP($Q4,武学奇术!$A:$ZZ,22,FALSE)=1,0,(1-$BK4))*(1-$BN4) -> 0 | BS4: {=SUM(_xlfn.XLOOKUP(R4:AH4,增益!$A:$A,增益!$W:$W,0))+$I$5} -> 0.06
A5: 牵丝 | B5: 492 | C5: 985 | D5: 30 | E5: 0.15 | F5: 扇 | G5: =B15+B18 -> 0.0852 | H5: 副本天赋 | I5: 0.06 | K5: =($L5*$BP5+$M5*$BN5+$N5*$BQ5+$O5*$BR5) -> 0 | L5: =((($AP5+$AQ5)/2*$AJ5+$AK5)*(1+$AR5)*(1+$AS5)+(($AU5+$AV5)/2*IF($G$1="鸣金",$AL5,$AJ5)+IF($G$1="鸣金",$AM5*1.5,0))*(1+$AW5)*(1+$AX5)+(($AY5+$AZ5)/2*IF($G$1="裂石",$AL5,$AJ5)+IF($G$1="裂石",$AM5*1.5,0))*(1+$BA5)*(1+$BB5)+(($BC5+$BD5)/2*IF($G$1="牵丝",$AL5,$AJ5)+IF($G$1="牵丝",$AM5*1.5,0))*(1+$BE5)*(1+$BF5)+(($BG5+$BH5)/2*IF($G$1="破竹",$AL5,$AJ5)+IF($G$1="破竹",$AM5*1.5,0))*(1+$BI5)*(1+$BJ5))*(1+$AN5)*$BM5*$P5*(1+IF(VLOOKUP($Q5,武学奇术!$A:$ZZ,30,FALSE)="弹道",$B$21,0))*(1+$BS5) -> 0 | M5: =(($AQ5*$AJ5+$AK5)*(1+$AR5)*(1+$AS5)+($AV5*IF($G$1="鸣金",$AL5,$AJ5)+IF($G$1="鸣金",$AM5*1.5,0))*(1+$AW5)*(1+$AX5)+($AZ5*IF($G$1="裂石",$AL5,$AJ5)+IF($G$1="裂石",$AM5*1.5,0))*(1+$BA5)*(1+$BB5)+($BD5*IF($G$1="牵丝",$AL5,$AJ5)+IF($G$1="牵丝",$AM5*1.5,0))*(1+$BE5)*(1+$BF5)+($BH5*IF($G$1="破竹",$AL5,$AJ5)+IF($G$1="破竹",$AM5*1.5,0))*(1+$BI5)*(1+$BJ5))*(1+$AN5)*$BO5*$P5*(1+IF(VLOOKUP($Q5,武学奇术!$A:$ZZ,30,FALSE)="弹道",$B$21,0))*(1+$BS5) -> 0 | N5: =((($AP5+$AQ5)/2*$AJ5+$AK5)*(1+$AR5)*(1+$AS5)+(($AU5+$AV5)/2*IF($G$1="鸣金",$AL5,$AJ5)+IF($G$1="鸣金",$AM5*1.5,0))*(1+$AW5)*(1+$AX5)+(($AY5+$AZ5)/2*IF($G$1="裂石",$AL5,$AJ5)+IF($G$1="裂石",$AM5*1.5,0))*(1+$BA5)*(1+$BB5)+(($BC5+$BD5)/2*IF($G$1="牵丝",$AL5,$AJ5)+IF($G$1="牵丝",$AM5*1.5,0))*(1+$BE5)*(1+$BF5)+(($BG5+$BH5)/2*IF($G$1="破竹",$AL5,$AJ5)+IF($G$1="破竹",$AM5*1.5,0))*(1+$BI5)*(1+$BJ5))*(1+$AN5)*$P5*(1+IF(VLOOKUP($Q5,武学奇术!$A:$ZZ,30,FALSE)="弹道",$B$21,0))*(1+$BS5) -> 0 | O5: =((($AP5*$AJ5+$AK5)*(1+$AR5)*(1+$AS5)+($AU5*IF($G$1="鸣金",$AL5,$AJ5)+IF($G$1="鸣金",$AM5*1.5,0))*(1+$AW5)*(1+$AX5)+($AY5*IF($G$1="裂石",$AL5,$AJ5)+IF($G$1="裂石",$AM5*1.5,0))*(1+$BA5)*(1+$BB5)+($BC5*IF($G$1="牵丝",$AL5,$AJ5)+IF($G$1="牵丝",$AM5*1.5,0))*(1+$BE5)*(1+$BF5)+($BG5*IF($G$1="破竹",$AL5,$AJ5)+IF($G$1="破竹",$AM5*1.5,0))*(1+$BI5)*(1+$BJ5))*(1+$AN5))*$P5*(1+IF(VLOOKUP($Q5,武学奇术!$A:$ZZ,30,FALSE)="弹道",$B$21,0))*(1+$BS5) -> 0 | P5: 1 | Q5: N/a | R5: N/a | S5: N/a | T5: N/a | U5: N/a | V5: N/a | W5: N/a | X5: N/a | Y5: N/a | Z5: N/a | AA5: N/a | AB5: N/a | AC5: N/a | AD5: N/a | AE5: N/a | AF5: N/a | AG5: N/a | AH5: N/a | AI5: =VLOOKUP($Q5,武学奇术!$A:$ZZ,25,FALSE) -> 心法 | AJ5: =VLOOKUP($Q5,武学奇术!$A:$ZZ,26,FALSE) -> 0 | AK5: =VLOOKUP($Q5,武学奇术!$A:$ZZ,27,FALSE)*(1+IF(OR($AI5=$F$4,$AI5=$F$5),$B$22,0)) -> 0 | AL5: =VLOOKUP($Q5,武学奇术!$A:$ZZ,28,FALSE) -> 0 | AM5: =VLOOKUP($Q5,武学奇术!$A:$ZZ,29,FALSE)*(1+IF(OR($AI5=$F$4,$AI5=$F$5),$B$22,0)) -> 0 | AN5: {=$G$3+IFERROR(VLOOKUP($AI5,$F$4:$G$7,2,FALSE),0)+VLOOKUP($Q5,武学奇术!$A:$ZZ,2,FALSE)+SUM(_xlfn.XLOOKUP($R5:$AH5,增益!$A:$A,增益!$B:$B,0))} -> 0.1837 | AO5: {=VLOOKUP($Q5,武学奇术!$A:$ZZ,5,FALSE)+SUM(_xlfn.XLOOKUP($R5:$AH5,增益!$A:$A,增益!$E:$E,0))} -> 0 | AP5: {=$D$10*(1+$AO5)+VLOOKUP($Q5,武学奇术!$A:$ZZ,3,FALSE)+SUM(_xlfn.XLOOKUP($R5:$AH5,增益!$A:$A,增益!$C:$C,0))-$I$2} -> 1797.4 | AQ5: {=$E$10*(1+$AO5)+VLOOKUP($Q5,武学奇术!$A:$ZZ,4,FALSE)+SUM(_xlfn.XLOOKUP($R5:$AH5,增益!$A:$A,增益!$D:$D,0))-$I$2} -> 5488 | AR5: {=IF($F$10-$I$3+VLOOKUP($Q5,武学奇术!$A:$ZZ,6,FALSE)+SUM(_xlfn.XLOOKUP(R5:AH5,增益!$A:$A,增益!$F:$F,0))>0,($F$10-$I$3+VLOOKUP($Q5,武学奇术!$A:$ZZ,6,FALSE)+SUM(_xlfn.XLOOKUP(R5:AH5,增益!$A:$A,增益!$F:$F,0)))/200,($F$10-$I$3+VLOOKUP($Q5,武学奇术!$A:$ZZ,6,FALSE)+SUM(_xlfn.XLOOKUP(R5:AH5,增益!$A:$A,增益!$F:$F,0)))/100)} -> 0.2925 | AS5: {=$G$10+VLOOKUP($Q5,武学奇术!$A:$ZZ,7,FALSE)+SUM(_xlfn.XLOOKUP(R5:AH5,增益!$A:$A,增益!$G:$G,0))} -> 0 | AT5: {=VLOOKUP($Q5,武学奇术!$A:$ZZ,8,FALSE)+SUM(_xlfn.XLOOKUP(R5:AH5,增益!$A:$A,增益!$H:$H,0))} -> 0 | AU5: =$D$11*(1+$AT5) -> 0 | AV5: =$E$11*(1+$AT5) -> 0 | AW5: {=IF($F$11-$I$4+VLOOKUP($Q5,武学奇术!$A:$ZZ,9,FALSE)+SUM(_xlfn.XLOOKUP(R5:AH5,增益!$A:$A,增益!$I:$I,0))>0,($F$11-$I$4+VLOOKUP($Q5,武学奇术!$A:$ZZ,9,FALSE)+SUM(_xlfn.XLOOKUP(R5:AH5,增益!$A:$A,增益!$I:$I,0)))/200,($F$11-$I$4+VLOOKUP($Q5,武学奇术!$A:$ZZ,9,FALSE)+SUM(_xlfn.XLOOKUP(R5:AH5,增益!$A:$A,增益!$I:$I,0)))/100)} -> -0.3 | AX5: {=$G$11+VLOOKUP($Q5,武学奇术!$A:$ZZ,10,FALSE)+SUM(_xlfn.XLOOKUP(R5:AH5,增益!$A:$A,增益!$J:$J,0))} -> 0 | AY5: =$D$12*(1+$AT5) -> 0 | AZ5: =$E$12*(1+$AT5) -> 0 | BA5: {=IF($F$12-$I$4+VLOOKUP($Q5,武学奇术!$A:$ZZ,11,FALSE)+SUM(_xlfn.XLOOKUP(R5:AH5,增益!$A:$A,增益!$K:$K,0))>0,($F$12-$I$4+VLOOKUP($Q5,武学奇术!$A:$ZZ,11,FALSE)+SUM(_xlfn.XLOOKUP(R5:AH5,增益!$A:$A,增益!$K:$K,0)))/200,($F$12-$I$4+VLOOKUP($Q5,武学奇术!$A:$ZZ,11,FALSE)+SUM(_xlfn.XLOOKUP(R5:AH5,增益!$A:$A,增益!$K:$K,0)))/100)} -> -0.3 | BB5: {=$G$12+VLOOKUP($Q5,武学奇术!$A:$ZZ,12,FALSE)+SUM(_xlfn.XLOOKUP(R5:AH5,增益!$A:$A,增益!$L:$L,0))} -> 0 | BC5: =$D$13*(1+$AT5) -> 571.2 | BD5: =$E$13*(1+$AT5) -> 1077.4 | BE5: {=IF($F$13-$I$4+VLOOKUP($Q5,武学奇术!$A:$ZZ,13,FALSE)+SUM(_xlfn.XLOOKUP(R5:AH5,增益!$A:$A,增益!$M:$M,0))>0,($F$13-$I$4+VLOOKUP($Q5,武学奇术!$A:$ZZ,13,FALSE)+SUM(_xlfn.XLOOKUP(R5:AH5,增益!$A:$A,增益!$K:$K,0)))/200,($F$13-$I$4+VLOOKUP($Q5,武学奇术!$A:$ZZ,13,FALSE)+SUM(_xlfn.XLOOKUP(R5:AH5,增益!$A:$A,增益!$M:$M,0)))/100)} -> 0 | BF5: {=$G$13+VLOOKUP($Q5,武学奇术!$A:$ZZ,14,FALSE)+SUM(_xlfn.XLOOKUP(R5:AH5,增益!$A:$A,增益!$N:$N,0))} -> 0.15 | BG5: =$D$14*(1+$AT5) -> 0 | BH5: =$E$14*(1+$AT5) -> 0 | BI5: {=IF($F$14-$I$4+VLOOKUP($Q5,武学奇术!$A:$ZZ,15,FALSE)+SUM(_xlfn.XLOOKUP(R5:AH5,增益!$A:$A,增益!$O:$O,0))>0,($F$14-$I$4+VLOOKUP($Q5,武学奇术!$A:$ZZ,15,FALSE)+SUM(_xlfn.XLOOKUP(R5:AH5,增益!$A:$A,增益!$O:$O,0)))/200,($F$14-$I$4+VLOOKUP($Q5,武学奇术!$A:$ZZ,15,FALSE)+SUM(_xlfn.XLOOKUP(R5:AH5,增益!$A:$A,增益!$O:$O,0)))/100)} -> -0.3 | BJ5: {=$G$14+VLOOKUP($Q5,武学奇术!$A:$ZZ,16,FALSE)+SUM(_xlfn.XLOOKUP(R5:AH5,增益!$A:$A,增益!$P:$P,0))} -> 0 | BK5: =MIN(IF(VLOOKUP($Q5,武学奇术!$A:$ZZ,23,FALSE)=1,100%,$B$8),100%) -> 1 | BL5: {=IF(VLOOKUP($Q5,武学奇术!$A:$ZZ,23,FALSE)=1,100%,MIN(80%,$B$9+VLOOKUP($Q5,武学奇术!$A:$ZZ,17,FALSE)+SUM(_xlfn.XLOOKUP(R5:AH5,增益!$A:$A,增益!$Q:$Q,0)))+$B$11+SUM(_xlfn.XLOOKUP(R5:AH5,增益!$A:$A,增益!$U:$U,0)))*IF(VLOOKUP($Q5,武学奇术!$A:$ZZ,24,FALSE)=1,0,1)} -> 0.9045 | BM5: {=1+$B$13+VLOOKUP($Q5,武学奇术!$A:$ZZ,18,FALSE)+SUM(_xlfn.XLOOKUP(R5:AH5,增益!$A:$A,增益!$R:$R,0))} -> 1.5 | BN5: {=IF(VLOOKUP($Q5,武学奇术!$A:$ZZ,24,FALSE)=1,100%,MIN(40%,$B$10+VLOOKUP($Q5,武学奇术!$A:$ZZ,19,FALSE)+SUM(_xlfn.XLOOKUP(R5:AH5,增益!$A:$A,增益!$S:$S,0)))+$B$12+SUM(_xlfn.XLOOKUP(R5:AH5,增益!$A:$A,增益!$V:$V,0)))*IF(VLOOKUP($Q5,武学奇术!$A:$ZZ,23,FALSE)=1,0,1)} -> 0.0929 | BO5: {=1+$B$14+VLOOKUP($Q5,武学奇术!$A:$ZZ,20,FALSE)+SUM(_xlfn.XLOOKUP(R5:AH5,增益!$A:$A,增益!$T:$T,0))} -> 1.35 | BP5: =MIN((1-BN5)*BK5,BK5*BL5) -> 0.9045 | BQ5: =1-BN5-BP5-BR5 -> 0.0026 | BR5: =IF(VLOOKUP($Q5,武学奇术!$A:$ZZ,22,FALSE)=1,0,(1-$BK5))*(1-$BN5) -> 0 | BS5: {=SUM(_xlfn.XLOOKUP(R5:AH5,增益!$A:$A,增益!$W:$W,0))+$I$5} -> 0.06
A6: 破竹 | F6: 单体奇术 | G6: =B19 -> 0.2678 | K6: =($L6*$BP6+$M6*$BN6+$N6*$BQ6+$O6*$BR6) -> 0 | L6: =((($AP6+$AQ6)/2*$AJ6+$AK6)*(1+$AR6)*(1+$AS6)+(($AU6+$AV6)/2*IF($G$1="鸣金",$AL6,$AJ6)+IF($G$1="鸣金",$AM6*1.5,0))*(1+$AW6)*(1+$AX6)+(($AY6+$AZ6)/2*IF($G$1="裂石",$AL6,$AJ6)+IF($G$1="裂石",$AM6*1.5,0))*(1+$BA6)*(1+$BB6)+(($BC6+$BD6)/2*IF($G$1="牵丝",$AL6,$AJ6)+IF($G$1="牵丝",$AM6*1.5,0))*(1+$BE6)*(1+$BF6)+(($BG6+$BH6)/2*IF($G$1="破竹",$AL6,$AJ6)+IF($G$1="破竹",$AM6*1.5,0))*(1+$BI6)*(1+$BJ6))*(1+$AN6)*$BM6*$P6*(1+IF(VLOOKUP($Q6,武学奇术!$A:$ZZ,30,FALSE)="弹道",$B$21,0))*(1+$BS6) -> 0 | M6: =(($AQ6*$AJ6+$AK6)*(1+$AR6)*(1+$AS6)+($AV6*IF($G$1="鸣金",$AL6,$AJ6)+IF($G$1="鸣金",$AM6*1.5,0))*(1+$AW6)*(1+$AX6)+($AZ6*IF($G$1="裂石",$AL6,$AJ6)+IF($G$1="裂石",$AM6*1.5,0))*(1+$BA6)*(1+$BB6)+($BD6*IF($G$1="牵丝",$AL6,$AJ6)+IF($G$1="牵丝",$AM6*1.5,0))*(1+$BE6)*(1+$BF6)+($BH6*IF($G$1="破竹",$AL6,$AJ6)+IF($G$1="破竹",$AM6*1.5,0))*(1+$BI6)*(1+$BJ6))*(1+$AN6)*$BO6*$P6*(1+IF(VLOOKUP($Q6,武学奇术!$A:$ZZ,30,FALSE)="弹道",$B$21,0))*(1+$BS6) -> 0 | N6: =((($AP6+$AQ6)/2*$AJ6+$AK6)*(1+$AR6)*(1+$AS6)+(($AU6+$AV6)/2*IF($G$1="鸣金",$AL6,$AJ6)+IF($G$1="鸣金",$AM6*1.5,0))*(1+$AW6)*(1+$AX6)+(($AY6+$AZ6)/2*IF($G$1="裂石",$AL6,$AJ6)+IF($G$1="裂石",$AM6*1.5,0))*(1+$BA6)*(1+$BB6)+(($BC6+$BD6)/2*IF($G$1="牵丝",$AL6,$AJ6)+IF($G$1="牵丝",$AM6*1.5,0))*(1+$BE6)*(1+$BF6)+(($BG6+$BH6)/2*IF($G$1="破竹",$AL6,$AJ6)+IF($G$1="破竹",$AM6*1.5,0))*(1+$BI6)*(1+$BJ6))*(1+$AN6)*$P6*(1+IF(VLOOKUP($Q6,武学奇术!$A:$ZZ,30,FALSE)="弹道",$B$21,0))*(1+$BS6) -> 0 | O6: =((($AP6*$AJ6+$AK6)*(1+$AR6)*(1+$AS6)+($AU6*IF($G$1="鸣金",$AL6,$AJ6)+IF($G$1="鸣金",$AM6*1.5,0))*(1+$AW6)*(1+$AX6)+($AY6*IF($G$1="裂石",$AL6,$AJ6)+IF($G$1="裂石",$AM6*1.5,0))*(1+$BA6)*(1+$BB6)+($BC6*IF($G$1="牵丝",$AL6,$AJ6)+IF($G$1="牵丝",$AM6*1.5,0))*(1+$BE6)*(1+$BF6)+($BG6*IF($G$1="破竹",$AL6,$AJ6)+IF($G$1="破竹",$AM6*1.5,0))*(1+$BI6)*(1+$BJ6))*(1+$AN6))*$P6*(1+IF(VLOOKUP($Q6,武学奇术!$A:$ZZ,30,FALSE)="弹道",$B$21,0))*(1+$BS6) -> 0 | P6: 1 | Q6: N/a | R6: N/a | S6: N/a | T6: N/a | U6: N/a | V6: N/a | W6: N/a | X6: N/a | Y6: N/a | Z6: N/a | AA6: N/a | AB6: N/a | AC6: N/a | AD6: N/a | AE6: N/a | AF6: N/a | AG6: N/a | AH6: N/a | AI6: =VLOOKUP($Q6,武学奇术!$A:$ZZ,25,FALSE) -> 心法 | AJ6: =VLOOKUP($Q6,武学奇术!$A:$ZZ,26,FALSE) -> 0 | AK6: =VLOOKUP($Q6,武学奇术!$A:$ZZ,27,FALSE)*(1+IF(OR($AI6=$F$4,$AI6=$F$5),$B$22,0)) -> 0 | AL6: =VLOOKUP($Q6,武学奇术!$A:$ZZ,28,FALSE) -> 0 | AM6: =VLOOKUP($Q6,武学奇术!$A:$ZZ,29,FALSE)*(1+IF(OR($AI6=$F$4,$AI6=$F$5),$B$22,0)) -> 0 | AN6: {=$G$3+IFERROR(VLOOKUP($AI6,$F$4:$G$7,2,FALSE),0)+VLOOKUP($Q6,武学奇术!$A:$ZZ,2,FALSE)+SUM(_xlfn.XLOOKUP($R6:$AH6,增益!$A:$A,增益!$B:$B,0))} -> 0.1837 | AO6: {=VLOOKUP($Q6,武学奇术!$A:$ZZ,5,FALSE)+SUM(_xlfn.XLOOKUP($R6:$AH6,增益!$A:$A,增益!$E:$E,0))} -> 0 | AP6: {=$D$10*(1+$AO6)+VLOOKUP($Q6,武学奇术!$A:$ZZ,3,FALSE)+SUM(_xlfn.XLOOKUP($R6:$AH6,增益!$A:$A,增益!$C:$C,0))-$I$2} -> 1797.4 | AQ6: {=$E$10*(1+$AO6)+VLOOKUP($Q6,武学奇术!$A:$ZZ,4,FALSE)+SUM(_xlfn.XLOOKUP($R6:$AH6,增益!$A:$A,增益!$D:$D,0))-$I$2} -> 5488 | AR6: {=IF($F$10-$I$3+VLOOKUP($Q6,武学奇术!$A:$ZZ,6,FALSE)+SUM(_xlfn.XLOOKUP(R6:AH6,增益!$A:$A,增益!$F:$F,0))>0,($F$10-$I$3+VLOOKUP($Q6,武学奇术!$A:$ZZ,6,FALSE)+SUM(_xlfn.XLOOKUP(R6:AH6,增益!$A:$A,增益!$F:$F,0)))/200,($F$10-$I$3+VLOOKUP($Q6,武学奇术!$A:$ZZ,6,FALSE)+SUM(_xlfn.XLOOKUP(R6:AH6,增益!$A:$A,增益!$F:$F,0)))/100)} -> 0.2925 | AS6: {=$G$10+VLOOKUP($Q6,武学奇术!$A:$ZZ,7,FALSE)+SUM(_xlfn.XLOOKUP(R6:AH6,增益!$A:$A,增益!$G:$G,0))} -> 0 | AT6: {=VLOOKUP($Q6,武学奇术!$A:$ZZ,8,FALSE)+SUM(_xlfn.XLOOKUP(R6:AH6,增益!$A:$A,增益!$H:$H,0))} -> 0 | AU6: =$D$11*(1+$AT6) -> 0 | AV6: =$E$11*(1+$AT6) -> 0 | AW6: {=IF($F$11-$I$4+VLOOKUP($Q6,武学奇术!$A:$ZZ,9,FALSE)+SUM(_xlfn.XLOOKUP(R6:AH6,增益!$A:$A,增益!$I:$I,0))>0,($F$11-$I$4+VLOOKUP($Q6,武学奇术!$A:$ZZ,9,FALSE)+SUM(_xlfn.XLOOKUP(R6:AH6,增益!$A:$A,增益!$I:$I,0)))/200,($F$11-$I$4+VLOOKUP($Q6,武学奇术!$A:$ZZ,9,FALSE)+SUM(_xlfn.XLOOKUP(R6:AH6,增益!$A:$A,增益!$I:$I,0)))/100)} -> -0.3 | AX6: {=$G$11+VLOOKUP($Q6,武学奇术!$A:$ZZ,10,FALSE)+SUM(_xlfn.XLOOKUP(R6:AH6,增益!$A:$A,增益!$J:$J,0))} -> 0 | AY6: =$D$12*(1+$AT6) -> 0 | AZ6: =$E$12*(1+$AT6) -> 0 | BA6: {=IF($F$12-$I$4+VLOOKUP($Q6,武学奇术!$A:$ZZ,11,FALSE)+SUM(_xlfn.XLOOKUP(R6:AH6,增益!$A:$A,增益!$K:$K,0))>0,($F$12-$I$4+VLOOKUP($Q6,武学奇术!$A:$ZZ,11,FALSE)+SUM(_xlfn.XLOOKUP(R6:AH6,增益!$A:$A,增益!$K:$K,0)))/200,($F$12-$I$4+VLOOKUP($Q6,武学奇术!$A:$ZZ,11,FALSE)+SUM(_xlfn.XLOOKUP(R6:AH6,增益!$A:$A,增益!$K:$K,0)))/100)} -> -0.3 | BB6: {=$G$12+VLOOKUP($Q6,武学奇术!$A:$ZZ,12,FALSE)+SUM(_xlfn.XLOOKUP(R6:AH6,增益!$A:$A,增益!$L:$L,0))} -> 0 | BC6: =$D$13*(1+$AT6) -> 571.2 | BD6: =$E$13*(1+$AT6) -> 1077.4 | BE6: {=IF($F$13-$I$4+VLOOKUP($Q6,武学奇术!$A:$ZZ,13,FALSE)+SUM(_xlfn.XLOOKUP(R6:AH6,增益!$A:$A,增益!$M:$M,0))>0,($F$13-$I$4+VLOOKUP($Q6,武学奇术!$A:$ZZ,13,FALSE)+SUM(_xlfn.XLOOKUP(R6:AH6,增益!$A:$A,增益!$K:$K,0)))/200,($F$13-$I$4+VLOOKUP($Q6,武学奇术!$A:$ZZ,13,FALSE)+SUM(_xlfn.XLOOKUP(R6:AH6,增益!$A:$A,增益!$M:$M,0)))/100)} -> 0 | BF6: {=$G$13+VLOOKUP($Q6,武学奇术!$A:$ZZ,14,FALSE)+SUM(_xlfn.XLOOKUP(R6:AH6,增益!$A:$A,增益!$N:$N,0))} -> 0.15 | BG6: =$D$14*(1+$AT6) -> 0 | BH6: =$E$14*(1+$AT6) -> 0 | BI6: {=IF($F$14-$I$4+VLOOKUP($Q6,武学奇术!$A:$ZZ,15,FALSE)+SUM(_xlfn.XLOOKUP(R6:AH6,增益!$A:$A,增益!$O:$O,0))>0,($F$14-$I$4+VLOOKUP($Q6,武学奇术!$A:$ZZ,15,FALSE)+SUM(_xlfn.XLOOKUP(R6:AH6,增益!$A:$A,增益!$O:$O,0)))/200,($F$14-$I$4+VLOOKUP($Q6,武学奇术!$A:$ZZ,15,FALSE)+SUM(_xlfn.XLOOKUP(R6:AH6,增益!$A:$A,增益!$O:$O,0)))/100)} -> -0.3 | BJ6: {=$G$14+VLOOKUP($Q6,武学奇术!$A:$ZZ,16,FALSE)+SUM(_xlfn.XLOOKUP(R6:AH6,增益!$A:$A,增益!$P:$P,0))} -> 0 | BK6: =MIN(IF(VLOOKUP($Q6,武学奇术!$A:$ZZ,23,FALSE)=1,100%,$B$8),100%) -> 1 | BL6: {=IF(VLOOKUP($Q6,武学奇术!$A:$ZZ,23,FALSE)=1,100%,MIN(80%,$B$9+VLOOKUP($Q6,武学奇术!$A:$ZZ,17,FALSE)+SUM(_xlfn.XLOOKUP(R6:AH6,增益!$A:$A,增益!$Q:$Q,0)))+$B$11+SUM(_xlfn.XLOOKUP(R6:AH6,增益!$A:$A,增益!$U:$U,0)))*IF(VLOOKUP($Q6,武学奇术!$A:$ZZ,24,FALSE)=1,0,1)} -> 0.9045 | BM6: {=1+$B$13+VLOOKUP($Q6,武学奇术!$A:$ZZ,18,FALSE)+SUM(_xlfn.XLOOKUP(R6:AH6,增益!$A:$A,增益!$R:$R,0))} -> 1.5 | BN6: {=IF(VLOOKUP($Q6,武学奇术!$A:$ZZ,24,FALSE)=1,100%,MIN(40%,$B$10+VLOOKUP($Q6,武学奇术!$A:$ZZ,19,FALSE)+SUM(_xlfn.XLOOKUP(R6:AH6,增益!$A:$A,增益!$S:$S,0)))+$B$12+SUM(_xlfn.XLOOKUP(R6:AH6,增益!$A:$A,增益!$V:$V,0)))*IF(VLOOKUP($Q6,武学奇术!$A:$ZZ,23,FALSE)=1,0,1)} -> 0.0929 | BO6: {=1+$B$14+VLOOKUP($Q6,武学奇术!$A:$ZZ,20,FALSE)+SUM(_xlfn.XLOOKUP(R6:AH6,增益!$A:$A,增益!$T:$T,0))} -> 1.35 | BP6: =MIN((1-BN6)*BK6,BK6*BL6) -> 0.9045 | BQ6: =1-BN6-BP6-BR6 -> 0.0026 | BR6: =IF(VLOOKUP($Q6,武学奇术!$A:$ZZ,22,FALSE)=1,0,(1-$BK6))*(1-$BN6) -> 0 | BS6: {=SUM(_xlfn.XLOOKUP(R6:AH6,增益!$A:$A,增益!$W:$W,0))+$I$5} -> 0.06
A7: 无相 | B7: 79.2 | C7: 92.4 | F7: 群体奇术 | G7: =B20 -> 0 | K7: =($L7*$BP7+$M7*$BN7+$N7*$BQ7+$O7*$BR7) -> 66305.511 | L7: =((($AP7+$AQ7)/2*$AJ7+$AK7)*(1+$AR7)*(1+$AS7)+(($AU7+$AV7)/2*IF($G$1="鸣金",$AL7,$AJ7)+IF($G$1="鸣金",$AM7*1.5,0))*(1+$AW7)*(1+$AX7)+(($AY7+$AZ7)/2*IF($G$1="裂石",$AL7,$AJ7)+IF($G$1="裂石",$AM7*1.5,0))*(1+$BA7)*(1+$BB7)+(($BC7+$BD7)/2*IF($G$1="牵丝",$AL7,$AJ7)+IF($G$1="牵丝",$AM7*1.5,0))*(1+$BE7)*(1+$BF7)+(($BG7+$BH7)/2*IF($G$1="破竹",$AL7,$AJ7)+IF($G$1="破竹",$AM7*1.5,0))*(1+$BI7)*(1+$BJ7))*(1+$AN7)*$BM7*$P7*(1+IF(VLOOKUP($Q7,武学奇术!$A:$ZZ,30,FALSE)="弹道",$B$21,0))*(1+$BS7) -> 66299.395 | M7: =(($AQ7*$AJ7+$AK7)*(1+$AR7)*(1+$AS7)+($AV7*IF($G$1="鸣金",$AL7,$AJ7)+IF($G$1="鸣金",$AM7*1.5,0))*(1+$AW7)*(1+$AX7)+($AZ7*IF($G$1="裂石",$AL7,$AJ7)+IF($G$1="裂石",$AM7*1.5,0))*(1+$BA7)*(1+$BB7)+($BD7*IF($G$1="牵丝",$AL7,$AJ7)+IF($G$1="牵丝",$AM7*1.5,0))*(1+$BE7)*(1+$BF7)+($BH7*IF($G$1="破竹",$AL7,$AJ7)+IF($G$1="破竹",$AM7*1.5,0))*(1+$BI7)*(1+$BJ7))*(1+$AN7)*$BO7*$P7*(1+IF(VLOOKUP($Q7,武学奇术!$A:$ZZ,30,FALSE)="弹道",$B$21,0))*(1+$BS7) -> 67228.497 | N7: =((($AP7+$AQ7)/2*$AJ7+$AK7)*(1+$AR7)*(1+$AS7)+(($AU7+$AV7)/2*IF($G$1="鸣金",$AL7,$AJ7)+IF($G$1="鸣金",$AM7*1.5,0))*(1+$AW7)*(1+$AX7)+(($AY7+$AZ7)/2*IF($G$1="裂石",$AL7,$AJ7)+IF($G$1="裂石",$AM7*1.5,0))*(1+$BA7)*(1+$BB7)+(($BC7+$BD7)/2*IF($G$1="牵丝",$AL7,$AJ7)+IF($G$1="牵丝",$AM7*1.5,0))*(1+$BE7)*(1+$BF7)+(($BG7+$BH7)/2*IF($G$1="破竹",$AL7,$AJ7)+IF($G$1="破竹",$AM7*1.5,0))*(1+$BI7)*(1+$BJ7))*(1+$AN7)*$P7*(1+IF(VLOOKUP($Q7,武学奇术!$A:$ZZ,30,FALSE)="弹道",$B$21,0))*(1+$BS7) -> 35454.222 | O7: =((($AP7*$AJ7+$AK7)*(1+$AR7)*(1+$AS7)+($AU7*IF($G$1="鸣金",$AL7,$AJ7)+IF($G$1="鸣金",$AM7*1.5,0))*(1+$AW7)*(1+$AX7)+($AY7*IF($G$1="裂石",$AL7,$AJ7)+IF($G$1="裂石",$AM7*1.5,0))*(1+$BA7)*(1+$BB7)+($BC7*IF($G$1="牵丝",$AL7,$AJ7)+IF($G$1="牵丝",$AM7*1.5,0))*(1+$BE7)*(1+$BF7)+($BG7*IF($G$1="破竹",$AL7,$AJ7)+IF($G$1="破竹",$AM7*1.5,0))*(1+$BI7)*(1+$BJ7))*(1+$AN7))*$P7*(1+IF(VLOOKUP($Q7,武学奇术!$A:$ZZ,30,FALSE)="弹道",$B$21,0))*(1+$BS7) -> 21109.557 | P7: 1 | Q7: 伞Q | R7: N/a | S7: 沧海帖1层 | T7: N/a | U7: N/a | V7: 风墙(弹道) | W7: N/a | X7: N/a | Y7: N/a | Z7: N/a | AA7: N/a | AB7: N/a | AC7: N/a | AD7: N/a | AE7: N/a | AF7: N/a | AG7: N/a | AH7: 无惧 | AI7: =VLOOKUP($Q7,武学奇术!$A:$ZZ,25,FALSE) -> 伞 | AJ7: =VLOOKUP($Q7,武学奇术!$A:$ZZ,26,FALSE) -> 2.3397 | AK7: =VLOOKUP($Q7,武学奇术!$A:$ZZ,27,FALSE)*(1+IF(OR($AI7=$F$4,$AI7=$F$5),$B$22,0)) -> 907.2 | AL7: =VLOOKUP($Q7,武学奇术!$A:$ZZ,28,FALSE) -> 3.5095 | AM7: =VLOOKUP($Q7,武学奇术!$A:$ZZ,29,FALSE)*(1+IF(OR($AI7=$F$4,$AI7=$F$5),$B$22,0)) -> 494.2 | AN7: {=$G$3+IFERROR(VLOOKUP($AI7,$F$4:$G$7,2,FALSE),0)+VLOOKUP($Q7,武学奇术!$A:$ZZ,2,FALSE)+SUM(_xlfn.XLOOKUP($R7:$AH7,增益!$A:$A,增益!$B:$B,0))} -> 0.7541 | AO7: {=VLOOKUP($Q7,武学奇术!$A:$ZZ,5,FALSE)+SUM(_xlfn.XLOOKUP($R7:$AH7,增益!$A:$A,增益!$E:$E,0))} -> 0 | AP7: {=$D$10*(1+$AO7)+VLOOKUP($Q7,武学奇术!$A:$ZZ,3,FALSE)+SUM(_xlfn.XLOOKUP($R7:$AH7,增益!$A:$A,增益!$C:$C,0))-$I$2} -> 1797.4 | AQ7: {=$E$10*(1+$AO7)+VLOOKUP($Q7,武学奇术!$A:$ZZ,4,FALSE)+SUM(_xlfn.XLOOKUP($R7:$AH7,增益!$A:$A,增益!$D:$D,0))-$I$2} -> 5488 | AR7: {=IF($F$10-$I$3+VLOOKUP($Q7,武学奇术!$A:$ZZ,6,FALSE)+SUM(_xlfn.XLOOKUP(R7:AH7,增益!$A:$A,增益!$F:$F,0))>0,($F$10-$I$3+VLOOKUP($Q7,武学奇术!$A:$ZZ,6,FALSE)+SUM(_xlfn.XLOOKUP(R7:AH7,增益!$A:$A,增益!$F:$F,0)))/200,($F$10-$I$3+VLOOKUP($Q7,武学奇术!$A:$ZZ,6,FALSE)+SUM(_xlfn.XLOOKUP(R7:AH7,增益!$A:$A,增益!$F:$F,0)))/100)} -> 0.3175 | AS7: {=$G$10+VLOOKUP($Q7,武学奇术!$A:$ZZ,7,FALSE)+SUM(_xlfn.XLOOKUP(R7:AH7,增益!$A:$A,增益!$G:$G,0))} -> 0.1 | AT7: {=VLOOKUP($Q7,武学奇术!$A:$ZZ,8,FALSE)+SUM(_xlfn.XLOOKUP(R7:AH7,增益!$A:$A,增益!$H:$H,0))} -> 0 | AU7: =$D$11*(1+$AT7) -> 0 | AV7: =$E$11*(1+$AT7) -> 0 | AW7: {=IF($F$11-$I$4+VLOOKUP($Q7,武学奇术!$A:$ZZ,9,FALSE)+SUM(_xlfn.XLOOKUP(R7:AH7,增益!$A:$A,增益!$I:$I,0))>0,($F$11-$I$4+VLOOKUP($Q7,武学奇术!$A:$ZZ,9,FALSE)+SUM(_xlfn.XLOOKUP(R7:AH7,增益!$A:$A,增益!$I:$I,0)))/200,($F$11-$I$4+VLOOKUP($Q7,武学奇术!$A:$ZZ,9,FALSE)+SUM(_xlfn.XLOOKUP(R7:AH7,增益!$A:$A,增益!$I:$I,0)))/100)} -> -0.3 | AX7: {=$G$11+VLOOKUP($Q7,武学奇术!$A:$ZZ,10,FALSE)+SUM(_xlfn.XLOOKUP(R7:AH7,增益!$A:$A,增益!$J:$J,0))} -> 0 | AY7: =$D$12*(1+$AT7) -> 0 | AZ7: =$E$12*(1+$AT7) -> 0 | BA7: {=IF($F$12-$I$4+VLOOKUP($Q7,武学奇术!$A:$ZZ,11,FALSE)+SUM(_xlfn.XLOOKUP(R7:AH7,增益!$A:$A,增益!$K:$K,0))>0,($F$12-$I$4+VLOOKUP($Q7,武学奇术!$A:$ZZ,11,FALSE)+SUM(_xlfn.XLOOKUP(R7:AH7,增益!$A:$A,增益!$K:$K,0)))/200,($F$12-$I$4+VLOOKUP($Q7,武学奇术!$A:$ZZ,11,FALSE)+SUM(_xlfn.XLOOKUP(R7:AH7,增益!$A:$A,增益!$K:$K,0)))/100)} -> -0.3 | BB7: {=$G$12+VLOOKUP($Q7,武学奇术!$A:$ZZ,12,FALSE)+SUM(_xlfn.XLOOKUP(R7:AH7,增益!$A:$A,增益!$L:$L,0))} -> 0 | BC7: =$D$13*(1+$AT7) -> 571.2 | BD7: =$E$13*(1+$AT7) -> 1077.4 | BE7: {=IF($F$13-$I$4+VLOOKUP($Q7,武学奇术!$A:$ZZ,13,FALSE)+SUM(_xlfn.XLOOKUP(R7:AH7,增益!$A:$A,增益!$M:$M,0))>0,($F$13-$I$4+VLOOKUP($Q7,武学奇术!$A:$ZZ,13,FALSE)+SUM(_xlfn.XLOOKUP(R7:AH7,增益!$A:$A,增益!$K:$K,0)))/200,($F$13-$I$4+VLOOKUP($Q7,武学奇术!$A:$ZZ,13,FALSE)+SUM(_xlfn.XLOOKUP(R7:AH7,增益!$A:$A,增益!$M:$M,0)))/100)} -> 0 | BF7: {=$G$13+VLOOKUP($Q7,武学奇术!$A:$ZZ,14,FALSE)+SUM(_xlfn.XLOOKUP(R7:AH7,增益!$A:$A,增益!$N:$N,0))} -> 0.25 | BG7: =$D$14*(1+$AT7) -> 0 | BH7: =$E$14*(1+$AT7) -> 0 | BI7: {=IF($F$14-$I$4+VLOOKUP($Q7,武学奇术!$A:$ZZ,15,FALSE)+SUM(_xlfn.XLOOKUP(R7:AH7,增益!$A:$A,增益!$O:$O,0))>0,($F$14-$I$4+VLOOKUP($Q7,武学奇术!$A:$ZZ,15,FALSE)+SUM(_xlfn.XLOOKUP(R7:AH7,增益!$A:$A,增益!$O:$O,0)))/200,($F$14-$I$4+VLOOKUP($Q7,武学奇术!$A:$ZZ,15,FALSE)+SUM(_xlfn.XLOOKUP(R7:AH7,增益!$A:$A,增益!$O:$O,0)))/100)} -> -0.3 | BJ7: {=$G$14+VLOOKUP($Q7,武学奇术!$A:$ZZ,16,FALSE)+SUM(_xlfn.XLOOKUP(R7:AH7,增益!$A:$A,增益!$P:$P,0))} -> 0 | BK7: =MIN(IF(VLOOKUP($Q7,武学奇术!$A:$ZZ,23,FALSE)=1,100%,$B$8),100%) -> 1 | BL7: {=IF(VLOOKUP($Q7,武学奇术!$A:$ZZ,23,FALSE)=1,100%,MIN(80%,$B$9+VLOOKUP($Q7,武学奇术!$A:$ZZ,17,FALSE)+SUM(_xlfn.XLOOKUP(R7:AH7,增益!$A:$A,增益!$Q:$Q,0)))+$B$11+SUM(_xlfn.XLOOKUP(R7:AH7,增益!$A:$A,增益!$U:$U,0)))*IF(VLOOKUP($Q7,武学奇术!$A:$ZZ,24,FALSE)=1,0,1)} -> 0.9045 | BM7: {=1+$B$13+VLOOKUP($Q7,武学奇术!$A:$ZZ,18,FALSE)+SUM(_xlfn.XLOOKUP(R7:AH7,增益!$A:$A,增益!$R:$R,0))} -> 1.87 | BN7: {=IF(VLOOKUP($Q7,武学奇术!$A:$ZZ,24,FALSE)=1,100%,MIN(40%,$B$10+VLOOKUP($Q7,武学奇术!$A:$ZZ,19,FALSE)+SUM(_xlfn.XLOOKUP(R7:AH7,增益!$A:$A,增益!$S:$S,0)))+$B$12+SUM(_xlfn.XLOOKUP(R7:AH7,增益!$A:$A,增益!$V:$V,0)))*IF(VLOOKUP($Q7,武学奇术!$A:$ZZ,23,FALSE)=1,0,1)} -> 0.0929 | BO7: {=1+$B$14+VLOOKUP($Q7,武学奇术!$A:$ZZ,20,FALSE)+SUM(_xlfn.XLOOKUP(R7:AH7,增益!$A:$A,增益!$T:$T,0))} -> 1.35 | BP7: =MIN((1-BN7)*BK7,BK7*BL7) -> 0.9045 | BQ7: =1-BN7-BP7-BR7 -> 0.0026 | BR7: =IF(VLOOKUP($Q7,武学奇术!$A:$ZZ,22,FALSE)=1,0,(1-$BK7))*(1-$BN7) -> 0 | BS7: {=SUM(_xlfn.XLOOKUP(R7:AH7,增益!$A:$A,增益!$W:$W,0))+$I$5} -> 0.11
A8: 精准率 | B8: 1 | C8: 实际属性 | H8: 战斗时间 | I8: 102 | K8: =($L8*$BP8+$M8*$BN8+$N8*$BQ8+$O8*$BR8) -> 76568.84 | L8: =((($AP8+$AQ8)/2*$AJ8+$AK8)*(1+$AR8)*(1+$AS8)+(($AU8+$AV8)/2*IF($G$1="鸣金",$AL8,$AJ8)+IF($G$1="鸣金",$AM8*1.5,0))*(1+$AW8)*(1+$AX8)+(($AY8+$AZ8)/2*IF($G$1="裂石",$AL8,$AJ8)+IF($G$1="裂石",$AM8*1.5,0))*(1+$BA8)*(1+$BB8)+(($BC8+$BD8)/2*IF($G$1="牵丝",$AL8,$AJ8)+IF($G$1="牵丝",$AM8*1.5,0))*(1+$BE8)*(1+$BF8)+(($BG8+$BH8)/2*IF($G$1="破竹",$AL8,$AJ8)+IF($G$1="破竹",$AM8*1.5,0))*(1+$BI8)*(1+$BJ8))*(1+$AN8)*$BM8*$P8*(1+IF(VLOOKUP($Q8,武学奇术!$A:$ZZ,30,FALSE)="弹道",$B$21,0))*(1+$BS8) -> 76560.229 | M8: =(($AQ8*$AJ8+$AK8)*(1+$AR8)*(1+$AS8)+($AV8*IF($G$1="鸣金",$AL8,$AJ8)+IF($G$1="鸣金",$AM8*1.5,0))*(1+$AW8)*(1+$AX8)+($AZ8*IF($G$1="裂石",$AL8,$AJ8)+IF($G$1="裂石",$AM8*1.5,0))*(1+$BA8)*(1+$BB8)+($BD8*IF($G$1="牵丝",$AL8,$AJ8)+IF($G$1="牵丝",$AM8*1.5,0))*(1+$BE8)*(1+$BF8)+($BH8*IF($G$1="破竹",$AL8,$AJ8)+IF($G$1="破竹",$AM8*1.5,0))*(1+$BI8)*(1+$BJ8))*(1+$AN8)*$BO8*$P8*(1+IF(VLOOKUP($Q8,武学奇术!$A:$ZZ,30,FALSE)="弹道",$B$21,0))*(1+$BS8) -> 77649.793 | N8: =((($AP8+$AQ8)/2*$AJ8+$AK8)*(1+$AR8)*(1+$AS8)+(($AU8+$AV8)/2*IF($G$1="鸣金",$AL8,$AJ8)+IF($G$1="鸣金",$AM8*1.5,0))*(1+$AW8)*(1+$AX8)+(($AY8+$AZ8)/2*IF($G$1="裂石",$AL8,$AJ8)+IF($G$1="裂石",$AM8*1.5,0))*(1+$BA8)*(1+$BB8)+(($BC8+$BD8)/2*IF($G$1="牵丝",$AL8,$AJ8)+IF($G$1="牵丝",$AM8*1.5,0))*(1+$BE8)*(1+$BF8)+(($BG8+$BH8)/2*IF($G$1="破竹",$AL8,$AJ8)+IF($G$1="破竹",$AM8*1.5,0))*(1+$BI8)*(1+$BJ8))*(1+$AN8)*$P8*(1+IF(VLOOKUP($Q8,武学奇术!$A:$ZZ,30,FALSE)="弹道",$B$21,0))*(1+$BS8) -> 40941.299 | O8: =((($AP8*$AJ8+$AK8)*(1+$AR8)*(1+$AS8)+($AU8*IF($G$1="鸣金",$AL8,$AJ8)+IF($G$1="鸣金",$AM8*1.5,0))*(1+$AW8)*(1+$AX8)+($AY8*IF($G$1="裂石",$AL8,$AJ8)+IF($G$1="裂石",$AM8*1.5,0))*(1+$BA8)*(1+$BB8)+($BC8*IF($G$1="牵丝",$AL8,$AJ8)+IF($G$1="牵丝",$AM8*1.5,0))*(1+$BE8)*(1+$BF8)+($BG8*IF($G$1="破竹",$AL8,$AJ8)+IF($G$1="破竹",$AM8*1.5,0))*(1+$BI8)*(1+$BJ8))*(1+$AN8))*$P8*(1+IF(VLOOKUP($Q8,武学奇术!$A:$ZZ,30,FALSE)="弹道",$B$21,0))*(1+$BS8) -> 24364.232 | P8: 1 | Q8: 伞Q | R8: 易水歌1层 | S8: 沧海帖1层 | T8: 连中 | U8: N/a | V8: 风墙(弹道) | W8: N/a | X8: N/a | Y8: N/a | Z8: N/a | AA8: N/a | AB8: N/a | AC8: N/a | AD8: N/a | AE8: N/a | AF8: N/a | AG8: N/a | AH8: 无惧 | AI8: =VLOOKUP($Q8,武学奇术!$A:$ZZ,25,FALSE) -> 伞 | AJ8: =VLOOKUP($Q8,武学奇术!$A:$ZZ,26,FALSE) -> 2.3397 | AK8: =VLOOKUP($Q8,武学奇术!$A:$ZZ,27,FALSE)*(1+IF(OR($AI8=$F$4,$AI8=$F$5),$B$22,0)) -> 907.2 | AL8: =VLOOKUP($Q8,武学奇术!$A:$ZZ,28,FALSE) -> 3.5095 | AM8: =VLOOKUP($Q8,武学奇术!$A:$ZZ,29,FALSE)*(1+IF(OR($AI8=$F$4,$AI8=$F$5),$B$22,0)) -> 494.2 | AN8: {=$G$3+IFERROR(VLOOKUP($AI8,$F$4:$G$7,2,FALSE),0)+VLOOKUP($Q8,武学奇术!$A:$ZZ,2,FALSE)+SUM(_xlfn.XLOOKUP($R8:$AH8,增益!$A:$A,增益!$B:$B,0))} -> 1.0141 | AO8: {=VLOOKUP($Q8,武学奇术!$A:$ZZ,5,FALSE)+SUM(_xlfn.XLOOKUP($R8:$AH8,增益!$A:$A,增益!$E:$E,0))} -> 0 | AP8: {=$D$10*(1+$AO8)+VLOOKUP($Q8,武学奇术!$A:$ZZ,3,FALSE)+SUM(_xlfn.XLOOKUP($R8:$AH8,增益!$A:$A,增益!$C:$C,0))-$I$2} -> 1797.4 | AQ8: {=$E$10*(1+$AO8)+VLOOKUP($Q8,武学奇术!$A:$ZZ,4,FALSE)+SUM(_xlfn.XLOOKUP($R8:$AH8,增益!$A:$A,增益!$D:$D,0))-$I$2} -> 5488 | AR8: {=IF($F$10-$I$3+VLOOKUP($Q8,武学奇术!$A:$ZZ,6,FALSE)+SUM(_xlfn.XLOOKUP(R8:AH8,增益!$A:$A,增益!$F:$F,0))>0,($F$10-$I$3+VLOOKUP($Q8,武学奇术!$A:$ZZ,6,FALSE)+SUM(_xlfn.XLOOKUP(R8:AH8,增益!$A:$A,增益!$F:$F,0)))/200,($F$10-$I$3+VLOOKUP($Q8,武学奇术!$A:$ZZ,6,FALSE)+SUM(_xlfn.XLOOKUP(R8:AH8,增益!$A:$A,增益!$F:$F,0)))/100)} -> 0.3275 | AS8: {=$G$10+VLOOKUP($Q8,武学奇术!$A:$ZZ,7,FALSE)+SUM(_xlfn.XLOOKUP(R8:AH8,增益!$A:$A,增益!$G:$G,0))} -> 0.1 | AT8: {=VLOOKUP($Q8,武学奇术!$A:$ZZ,8,FALSE)+SUM(_xlfn.XLOOKUP(R8:AH8,增益!$A:$A,增益!$H:$H,0))} -> 0 | AU8: =$D$11*(1+$AT8) -> 0 | AV8: =$E$11*(1+$AT8) -> 0 | AW8: {=IF($F$11-$I$4+VLOOKUP($Q8,武学奇术!$A:$ZZ,9,FALSE)+SUM(_xlfn.XLOOKUP(R8:AH8,增益!$A:$A,增益!$I:$I,0))>0,($F$11-$I$4+VLOOKUP($Q8,武学奇术!$A:$ZZ,9,FALSE)+SUM(_xlfn.XLOOKUP(R8:AH8,增益!$A:$A,增益!$I:$I,0)))/200,($F$11-$I$4+VLOOKUP($Q8,武学奇术!$A:$ZZ,9,FALSE)+SUM(_xlfn.XLOOKUP(R8:AH8,增益!$A:$A,增益!$I:$I,0)))/100)} -> -0.3 | AX8: {=$G$11+VLOOKUP($Q8,武学奇术!$A:$ZZ,10,FALSE)+SUM(_xlfn.XLOOKUP(R8:AH8,增益!$A:$A,增益!$J:$J,0))} -> 0 | AY8: =$D$12*(1+$AT8) -> 0 | AZ8: =$E$12*(1+$AT8) -> 0 | BA8: {=IF($F$12-$I$4+VLOOKUP($Q8,武学奇术!$A:$ZZ,11,FALSE)+SUM(_xlfn.XLOOKUP(R8:AH8,增益!$A:$A,增益!$K:$K,0))>0,($F$12-$I$4+VLOOKUP($Q8,武学奇术!$A:$ZZ,11,FALSE)+SUM(_xlfn.XLOOKUP(R8:AH8,增益!$A:$A,增益!$K:$K,0)))/200,($F$12-$I$4+VLOOKUP($Q8,武学奇术!$A:$ZZ,11,FALSE)+SUM(_xlfn.XLOOKUP(R8:AH8,增益!$A:$A,增益!$K:$K,0)))/100)} -> -0.3 | BB8: {=$G$12+VLOOKUP($Q8,武学奇术!$A:$ZZ,12,FALSE)+SUM(_xlfn.XLOOKUP(R8:AH8,增益!$A:$A,增益!$L:$L,0))} -> 0 | BC8: =$D$13*(1+$AT8) -> 571.2 | BD8: =$E$13*(1+$AT8) -> 1077.4 | BE8: {=IF($F$13-$I$4+VLOOKUP($Q8,武学奇术!$A:$ZZ,13,FALSE)+SUM(_xlfn.XLOOKUP(R8:AH8,增益!$A:$A,增益!$M:$M,0))>0,($F$13-$I$4+VLOOKUP($Q8,武学奇术!$A:$ZZ,13,FALSE)+SUM(_xlfn.XLOOKUP(R8:AH8,增益!$A:$A,增益!$K:$K,0)))/200,($F$13-$I$4+VLOOKUP($Q8,武学奇术!$A:$ZZ,13,FALSE)+SUM(_xlfn.XLOOKUP(R8:AH8,增益!$A:$A,增益!$M:$M,0)))/100)} -> 0 | BF8: {=$G$13+VLOOKUP($Q8,武学奇术!$A:$ZZ,14,FALSE)+SUM(_xlfn.XLOOKUP(R8:AH8,增益!$A:$A,增益!$N:$N,0))} -> 0.25 | BG8: =$D$14*(1+$AT8) -> 0 | BH8: =$E$14*(1+$AT8) -> 0 | BI8: {=IF($F$14-$I$4+VLOOKUP($Q8,武学奇术!$A:$ZZ,15,FALSE)+SUM(_xlfn.XLOOKUP(R8:AH8,增益!$A:$A,增益!$O:$O,0))>0,($F$14-$I$4+VLOOKUP($Q8,武学奇术!$A:$ZZ,15,FALSE)+SUM(_xlfn.XLOOKUP(R8:AH8,增益!$A:$A,增益!$O:$O,0)))/200,($F$14-$I$4+VLOOKUP($Q8,武学奇术!$A:$ZZ,15,FALSE)+SUM(_xlfn.XLOOKUP(R8:AH8,增益!$A:$A,增益!$O:$O,0)))/100)} -> -0.3 | BJ8: {=$G$14+VLOOKUP($Q8,武学奇术!$A:$ZZ,16,FALSE)+SUM(_xlfn.XLOOKUP(R8:AH8,增益!$A:$A,增益!$P:$P,0))} -> 0 | BK8: =MIN(IF(VLOOKUP($Q8,武学奇术!$A:$ZZ,23,FALSE)=1,100%,$B$8),100%) -> 1 | BL8: {=IF(VLOOKUP($Q8,武学奇术!$A:$ZZ,23,FALSE)=1,100%,MIN(80%,$B$9+VLOOKUP($Q8,武学奇术!$A:$ZZ,17,FALSE)+SUM(_xlfn.XLOOKUP(R8:AH8,增益!$A:$A,增益!$Q:$Q,0)))+$B$11+SUM(_xlfn.XLOOKUP(R8:AH8,增益!$A:$A,增益!$U:$U,0)))*IF(VLOOKUP($Q8,武学奇术!$A:$ZZ,24,FALSE)=1,0,1)} -> 0.9045 | BM8: {=1+$B$13+VLOOKUP($Q8,武学奇术!$A:$ZZ,18,FALSE)+SUM(_xlfn.XLOOKUP(R8:AH8,增益!$A:$A,增益!$R:$R,0))} -> 1.87 | BN8: {=IF(VLOOKUP($Q8,武学奇术!$A:$ZZ,24,FALSE)=1,100%,MIN(40%,$B$10+VLOOKUP($Q8,武学奇术!$A:$ZZ,19,FALSE)+SUM(_xlfn.XLOOKUP(R8:AH8,增益!$A:$A,增益!$S:$S,0)))+$B$12+SUM(_xlfn.XLOOKUP(R8:AH8,增益!$A:$A,增益!$V:$V,0)))*IF(VLOOKUP($Q8,武学奇术!$A:$ZZ,23,FALSE)=1,0,1)} -> 0.0929 | BO8: {=1+$B$14+VLOOKUP($Q8,武学奇术!$A:$ZZ,20,FALSE)+SUM(_xlfn.XLOOKUP(R8:AH8,增益!$A:$A,增益!$T:$T,0))} -> 1.35 | BP8: =MIN((1-BN8)*BK8,BK8*BL8) -> 0.9045 | BQ8: =1-BN8-BP8-BR8 -> 0.0026 | BR8: =IF(VLOOKUP($Q8,武学奇术!$A:$ZZ,22,FALSE)=1,0,(1-$BK8))*(1-$BN8) -> 0 | BS8: {=SUM(_xlfn.XLOOKUP(R8:AH8,增益!$A:$A,增益!$W:$W,0))+$I$5} -> 0.11
A9: 会心率 | B9: 0.7715 | D9: 最小攻击 | E9: 最大攻击 | F9: 穿透 | G9: 伤害加成 | K9: =($L9*$BP9+$M9*$BN9+$N9*$BQ9+$O9*$BR9) -> 31693.363 | L9: =((($AP9+$AQ9)/2*$AJ9+$AK9)*(1+$AR9)*(1+$AS9)+(($AU9+$AV9)/2*IF($G$1="鸣金",$AL9,$AJ9)+IF($G$1="鸣金",$AM9*1.5,0))*(1+$AW9)*(1+$AX9)+(($AY9+$AZ9)/2*IF($G$1="裂石",$AL9,$AJ9)+IF($G$1="裂石",$AM9*1.5,0))*(1+$BA9)*(1+$BB9)+(($BC9+$BD9)/2*IF($G$1="牵丝",$AL9,$AJ9)+IF($G$1="牵丝",$AM9*1.5,0))*(1+$BE9)*(1+$BF9)+(($BG9+$BH9)/2*IF($G$1="破竹",$AL9,$AJ9)+IF($G$1="破竹",$AM9*1.5,0))*(1+$BI9)*(1+$BJ9))*(1+$AN9)*$BM9*$P9*(1+IF(VLOOKUP($Q9,武学奇术!$A:$ZZ,30,FALSE)="弹道",$B$21,0))*(1+$BS9) -> 30992.566 | M9: =(($AQ9*$AJ9+$AK9)*(1+$AR9)*(1+$AS9)+($AV9*IF($G$1="鸣金",$AL9,$AJ9)+IF($G$1="鸣金",$AM9*1.5,0))*(1+$AW9)*(1+$AX9)+($AZ9*IF($G$1="裂石",$AL9,$AJ9)+IF($G$1="裂石",$AM9*1.5,0))*(1+$BA9)*(1+$BB9)+($BD9*IF($G$1="牵丝",$AL9,$AJ9)+IF($G$1="牵丝",$AM9*1.5,0))*(1+$BE9)*(1+$BF9)+($BH9*IF($G$1="破竹",$AL9,$AJ9)+IF($G$1="破竹",$AM9*1.5,0))*(1+$BI9)*(1+$BJ9))*(1+$AN9)*$BO9*$P9*(1+IF(VLOOKUP($Q9,武学奇术!$A:$ZZ,30,FALSE)="弹道",$B$21,0))*(1+$BS9) -> 38829.086 | N9: =((($AP9+$AQ9)/2*$AJ9+$AK9)*(1+$AR9)*(1+$AS9)+(($AU9+$AV9)/2*IF($G$1="鸣金",$AL9,$AJ9)+IF($G$1="鸣金",$AM9*1.5,0))*(1+$AW9)*(1+$AX9)+(($AY9+$AZ9)/2*IF($G$1="裂石",$AL9,$AJ9)+IF($G$1="裂石",$AM9*1.5,0))*(1+$BA9)*(1+$BB9)+(($BC9+$BD9)/2*IF($G$1="牵丝",$AL9,$AJ9)+IF($G$1="牵丝",$AM9*1.5,0))*(1+$BE9)*(1+$BF9)+(($BG9+$BH9)/2*IF($G$1="破竹",$AL9,$AJ9)+IF($G$1="破竹",$AM9*1.5,0))*(1+$BI9)*(1+$BJ9))*(1+$AN9)*$P9*(1+IF(VLOOKUP($Q9,武学奇术!$A:$ZZ,30,FALSE)="弹道",$B$21,0))*(1+$BS9) -> 20524.878 | O9: =((($AP9*$AJ9+$AK9)*(1+$AR9)*(1+$AS9)+($AU9*IF($G$1="鸣金",$AL9,$AJ9)+IF($G$1="鸣金",$AM9*1.5,0))*(1+$AW9)*(1+$AX9)+($AY9*IF($G$1="裂石",$AL9,$AJ9)+IF($G$1="裂石",$AM9*1.5,0))*(1+$BA9)*(1+$BB9)+($BC9*IF($G$1="牵丝",$AL9,$AJ9)+IF($G$1="牵丝",$AM9*1.5,0))*(1+$BE9)*(1+$BF9)+($BG9*IF($G$1="破竹",$AL9,$AJ9)+IF($G$1="破竹",$AM9*1.5,0))*(1+$BI9)*(1+$BJ9))*(1+$AN9))*$P9*(1+IF(VLOOKUP($Q9,武学奇术!$A:$ZZ,30,FALSE)="弹道",$B$21,0))*(1+$BS9) -> 12287.471 | P9: 1 | Q9: 伞重击派生 | R9: 易水歌2层 | S9: 沧海帖1层 | T9: N/a | U9: N/a | V9: N/a | W9: N/a | X9: N/a | Y9: N/a | Z9: N/a | AA9: N/a | AB9: 惧刃(拐) | AC9: N/a | AD9: N/a | AE9: N/a | AF9: N/a | AG9: N/a | AH9: 无惧 | AI9: =VLOOKUP($Q9,武学奇术!$A:$ZZ,25,FALSE) -> 伞 | AJ9: =VLOOKUP($Q9,武学奇术!$A:$ZZ,26,FALSE) -> 1.7001 | AK9: =VLOOKUP($Q9,武学奇术!$A:$ZZ,27,FALSE)*(1+IF(OR($AI9=$F$4,$AI9=$F$5),$B$22,0)) -> 659.4 | AL9: =VLOOKUP($Q9,武学奇术!$A:$ZZ,28,FALSE) -> 2.5502 | AM9: =VLOOKUP($Q9,武学奇术!$A:$ZZ,29,FALSE)*(1+IF(OR($AI9=$F$4,$AI9=$F$5),$B$22,0)) -> 358.4 | AN9: {=$G$3+IFERROR(VLOOKUP($AI9,$F$4:$G$7,2,FALSE),0)+VLOOKUP($Q9,武学奇术!$A:$ZZ,2,FALSE)+SUM(_xlfn.XLOOKUP($R9:$AH9,增益!$A:$A,增益!$B:$B,0))} -> 0.3741 | AO9: {=VLOOKUP($Q9,武学奇术!$A:$ZZ,5,FALSE)+SUM(_xlfn.XLOOKUP($R9:$AH9,增益!$A:$A,增益!$E:$E,0))} -> 0 | AP9: {=$D$10*(1+$AO9)+VLOOKUP($Q9,武学奇术!$A:$ZZ,3,FALSE)+SUM(_xlfn.XLOOKUP($R9:$AH9,增益!$A:$A,增益!$C:$C,0))-$I$2} -> 1797.4 | AQ9: {=$E$10*(1+$AO9)+VLOOKUP($Q9,武学奇术!$A:$ZZ,4,FALSE)+SUM(_xlfn.XLOOKUP($R9:$AH9,增益!$A:$A,增益!$D:$D,0))-$I$2} -> 5488 | AR9: {=IF($F$10-$I$3+VLOOKUP($Q9,武学奇术!$A:$ZZ,6,FALSE)+SUM(_xlfn.XLOOKUP(R9:AH9,增益!$A:$A,增益!$F:$F,0))>0,($F$10-$I$3+VLOOKUP($Q9,武学奇术!$A:$ZZ,6,FALSE)+SUM(_xlfn.XLOOKUP(R9:AH9,增益!$A:$A,增益!$F:$F,0)))/200,($F$10-$I$3+VLOOKUP($Q9,武学奇术!$A:$ZZ,6,FALSE)+SUM(_xlfn.XLOOKUP(R9:AH9,增益!$A:$A,增益!$F:$F,0)))/100)} -> 0.3125 | AS9: {=$G$10+VLOOKUP($Q9,武学奇术!$A:$ZZ,7,FALSE)+SUM(_xlfn.XLOOKUP(R9:AH9,增益!$A:$A,增益!$G:$G,0))} -> 0.1 | AT9: {=VLOOKUP($Q9,武学奇术!$A:$ZZ,8,FALSE)+SUM(_xlfn.XLOOKUP(R9:AH9,增益!$A:$A,增益!$H:$H,0))} -> 0 | AU9: =$D$11*(1+$AT9) -> 0 | AV9: =$E$11*(1+$AT9) -> 0 | AW9: {=IF($F$11-$I$4+VLOOKUP($Q9,武学奇术!$A:$ZZ,9,FALSE)+SUM(_xlfn.XLOOKUP(R9:AH9,增益!$A:$A,增益!$I:$I,0))>0,($F$11-$I$4+VLOOKUP($Q9,武学奇术!$A:$ZZ,9,FALSE)+SUM(_xlfn.XLOOKUP(R9:AH9,增益!$A:$A,增益!$I:$I,0)))/200,($F$11-$I$4+VLOOKUP($Q9,武学奇术!$A:$ZZ,9,FALSE)+SUM(_xlfn.XLOOKUP(R9:AH9,增益!$A:$A,增益!$I:$I,0)))/100)} -> -0.14 | AX9: {=$G$11+VLOOKUP($Q9,武学奇术!$A:$ZZ,10,FALSE)+SUM(_xlfn.XLOOKUP(R9:AH9,增益!$A:$A,增益!$J:$J,0))} -> 0 | AY9: =$D$12*(1+$AT9) -> 0 | AZ9: =$E$12*(1+$AT9) -> 0 | BA9: {=IF($F$12-$I$4+VLOOKUP($Q9,武学奇术!$A:$ZZ,11,FALSE)+SUM(_xlfn.XLOOKUP(R9:AH9,增益!$A:$A,增益!$K:$K,0))>0,($F$12-$I$4+VLOOKUP($Q9,武学奇术!$A:$ZZ,11,FALSE)+SUM(_xlfn.XLOOKUP(R9:AH9,增益!$A:$A,增益!$K:$K,0)))/200,($F$12-$I$4+VLOOKUP($Q9,武学奇术!$A:$ZZ,11,FALSE)+SUM(_xlfn.XLOOKUP(R9:AH9,增益!$A:$A,增益!$K:$K,0)))/100)} -> -0.14 | BB9: {=$G$12+VLOOKUP($Q9,武学奇术!$A:$ZZ,12,FALSE)+SUM(_xlfn.XLOOKUP(R9:AH9,增益!$A:$A,增益!$L:$L,0))} -> 0 | BC9: =$D$13*(1+$AT9) -> 571.2 | BD9: =$E$13*(1+$AT9) -> 1077.4 | BE9: {=IF($F$13-$I$4+VLOOKUP($Q9,武学奇术!$A:$ZZ,13,FALSE)+SUM(_xlfn.XLOOKUP(R9:AH9,增益!$A:$A,增益!$M:$M,0))>0,($F$13-$I$4+VLOOKUP($Q9,武学奇术!$A:$ZZ,13,FALSE)+SUM(_xlfn.XLOOKUP(R9:AH9,增益!$A:$A,增益!$K:$K,0)))/200,($F$13-$I$4+VLOOKUP($Q9,武学奇术!$A:$ZZ,13,FALSE)+SUM(_xlfn.XLOOKUP(R9:AH9,增益!$A:$A,增益!$M:$M,0)))/100)} -> 0.08 | BF9: {=$G$13+VLOOKUP($Q9,武学奇术!$A:$ZZ,14,FALSE)+SUM(_xlfn.XLOOKUP(R9:AH9,增益!$A:$A,增益!$N:$N,0))} -> 0.25 | BG9: =$D$14*(1+$AT9) -> 0 | BH9: =$E$14*(1+$AT9) -> 0 | BI9: {=IF($F$14-$I$4+VLOOKUP($Q9,武学奇术!$A:$ZZ,15,FALSE)+SUM(_xlfn.XLOOKUP(R9:AH9,增益!$A:$A,增益!$O:$O,0))>0,($F$14-$I$4+VLOOKUP($Q9,武学奇术!$A:$ZZ,15,FALSE)+SUM(_xlfn.XLOOKUP(R9:AH9,增益!$A:$A,增益!$O:$O,0)))/200,($F$14-$I$4+VLOOKUP($Q9,武学奇术!$A:$ZZ,15,FALSE)+SUM(_xlfn.XLOOKUP(R9:AH9,增益!$A:$A,增益!$O:$O,0)))/100)} -> -0.14 | BJ9: {=$G$14+VLOOKUP($Q9,武学奇术!$A:$ZZ,16,FALSE)+SUM(_xlfn.XLOOKUP(R9:AH9,增益!$A:$A,增益!$P:$P,0))} -> 0 | BK9: =MIN(IF(VLOOKUP($Q9,武学奇术!$A:$ZZ,23,FALSE)=1,100%,$B$8),100%) -> 1 | BL9: {=IF(VLOOKUP($Q9,武学奇术!$A:$ZZ,23,FALSE)=1,100%,MIN(80%,$B$9+VLOOKUP($Q9,武学奇术!$A:$ZZ,17,FALSE)+SUM(_xlfn.XLOOKUP(R9:AH9,增益!$A:$A,增益!$Q:$Q,0)))+$B$11+SUM(_xlfn.XLOOKUP(R9:AH9,增益!$A:$A,增益!$U:$U,0)))*IF(VLOOKUP($Q9,武学奇术!$A:$ZZ,24,FALSE)=1,0,1)} -> 0.9045 | BM9: {=1+$B$13+VLOOKUP($Q9,武学奇术!$A:$ZZ,18,FALSE)+SUM(_xlfn.XLOOKUP(R9:AH9,增益!$A:$A,增益!$R:$R,0))} -> 1.51 | BN9: {=IF(VLOOKUP($Q9,武学奇术!$A:$ZZ,24,FALSE)=1,100%,MIN(40%,$B$10+VLOOKUP($Q9,武学奇术!$A:$ZZ,19,FALSE)+SUM(_xlfn.XLOOKUP(R9:AH9,增益!$A:$A,增益!$S:$S,0)))+$B$12+SUM(_xlfn.XLOOKUP(R9:AH9,增益!$A:$A,增益!$V:$V,0)))*IF(VLOOKUP($Q9,武学奇术!$A:$ZZ,23,FALSE)=1,0,1)} -> 0.0929 | BO9: {=1+$B$14+VLOOKUP($Q9,武学奇术!$A:$ZZ,20,FALSE)+SUM(_xlfn.XLOOKUP(R9:AH9,增益!$A:$A,增益!$T:$T,0))} -> 1.35 | BP9: =MIN((1-BN9)*BK9,BK9*BL9) -> 0.9045 | BQ9: =1-BN9-BP9-BR9 -> 0.0026 | BR9: =IF(VLOOKUP($Q9,武学奇术!$A:$ZZ,22,FALSE)=1,0,(1-$BK9))*(1-$BN9) -> 0 | BS9: {=SUM(_xlfn.XLOOKUP(R9:AH9,增益!$A:$A,增益!$W:$W,0))+$I$5} -> 0.11
A10: 会意率 | B10: 0.0929 | C10: 外功 | D10: =(B2+B23)*IF($G$2="撼天",1.06,1) -> 2355.4 | E10: =MAX(B2+B23,C2+B24)*IF($G$2="撼天",1.06,1) -> 6046 | F10: =D2 -> 63.5 | G10: =E2 -> 0 | H10: 总伤 | I10: =SUM(K:K) -> 15919658 | K10: =($L10*$BP10+$M10*$BN10+$N10*$BQ10+$O10*$BR10) -> 13357.642 | L10: =((($AP10+$AQ10)/2*$AJ10+$AK10)*(1+$AR10)*(1+$AS10)+(($AU10+$AV10)/2*IF($G$1="鸣金",$AL10,$AJ10)+IF($G$1="鸣金",$AM10*1.5,0))*(1+$AW10)*(1+$AX10)+(($AY10+$AZ10)/2*IF($G$1="裂石",$AL10,$AJ10)+IF($G$1="裂石",$AM10*1.5,0))*(1+$BA10)*(1+$BB10)+(($BC10+$BD10)/2*IF($G$1="牵丝",$AL10,$AJ10)+IF($G$1="牵丝",$AM10*1.5,0))*(1+$BE10)*(1+$BF10)+(($BG10+$BH10)/2*IF($G$1="破竹",$AL10,$AJ10)+IF($G$1="破竹",$AM10*1.5,0))*(1+$BI10)*(1+$BJ10))*(1+$AN10)*$BM10*$P10*(1+IF(VLOOKUP($Q10,武学奇术!$A:$ZZ,30,FALSE)="弹道",$B$21,0))*(1+$BS10) -> 13071.945 | M10: =(($AQ10*$AJ10+$AK10)*(1+$AR10)*(1+$AS10)+($AV10*IF($G$1="鸣金",$AL10,$AJ10)+IF($G$1="鸣金",$AM10*1.5,0))*(1+$AW10)*(1+$AX10)+($AZ10*IF($G$1="裂石",$AL10,$AJ10)+IF($G$1="裂石",$AM10*1.5,0))*(1+$BA10)*(1+$BB10)+($BD10*IF($G$1="牵丝",$AL10,$AJ10)+IF($G$1="牵丝",$AM10*1.5,0))*(1+$BE10)*(1+$BF10)+($BH10*IF($G$1="破竹",$AL10,$AJ10)+IF($G$1="破竹",$AM10*1.5,0))*(1+$BI10)*(1+$BJ10))*(1+$AN10)*$BO10*$P10*(1+IF(VLOOKUP($Q10,武学奇术!$A:$ZZ,30,FALSE)="弹道",$B$21,0))*(1+$BS10) -> 16272.423 | N10: =((($AP10+$AQ10)/2*$AJ10+$AK10)*(1+$AR10)*(1+$AS10)+(($AU10+$AV10)/2*IF($G$1="鸣金",$AL10,$AJ10)+IF($G$1="鸣金",$AM10*1.5,0))*(1+$AW10)*(1+$AX10)+(($AY10+$AZ10)/2*IF($G$1="裂石",$AL10,$AJ10)+IF($G$1="裂石",$AM10*1.5,0))*(1+$BA10)*(1+$BB10)+(($BC10+$BD10)/2*IF($G$1="牵丝",$AL10,$AJ10)+IF($G$1="牵丝",$AM10*1.5,0))*(1+$BE10)*(1+$BF10)+(($BG10+$BH10)/2*IF($G$1="破竹",$AL10,$AJ10)+IF($G$1="破竹",$AM10*1.5,0))*(1+$BI10)*(1+$BJ10))*(1+$AN10)*$P10*(1+IF(VLOOKUP($Q10,武学奇术!$A:$ZZ,30,FALSE)="弹道",$B$21,0))*(1+$BS10) -> 8599.9639 | O10: =((($AP10*$AJ10+$AK10)*(1+$AR10)*(1+$AS10)+($AU10*IF($G$1="鸣金",$AL10,$AJ10)+IF($G$1="鸣金",$AM10*1.5,0))*(1+$AW10)*(1+$AX10)+($AY10*IF($G$1="裂石",$AL10,$AJ10)+IF($G$1="裂石",$AM10*1.5,0))*(1+$BA10)*(1+$BB10)+($BC10*IF($G$1="牵丝",$AL10,$AJ10)+IF($G$1="牵丝",$AM10*1.5,0))*(1+$BE10)*(1+$BF10)+($BG10*IF($G$1="破竹",$AL10,$AJ10)+IF($G$1="破竹",$AM10*1.5,0))*(1+$BI10)*(1+$BJ10))*(1+$AN10))*$P10*(1+IF(VLOOKUP($Q10,武学奇术!$A:$ZZ,30,FALSE)="弹道",$B$21,0))*(1+$BS10) -> 5146.2816 | P10: 1 | Q10: 丢伞 | R10: 易水歌2层 | S10: 沧海帖2层 | T10: N/a | U10: N/a | V10: N/a | W10: N/a | X10: N/a | Y10: N/a | Z10: N/a | AA10: N/a | AB10: 惧刃(拐) | AC10: N/a | AD10: N/a | AE10: N/a | AF10: N/a | AG10: N/a | AH10: 无惧 | AI10: =VLOOKUP($Q10,武学奇术!$A:$ZZ,25,FALSE) -> 伞 | AJ10: =VLOOKUP($Q10,武学奇术!$A:$ZZ,26,FALSE) -> 0.54 | AK10: =VLOOKUP($Q10,武学奇术!$A:$ZZ,27,FALSE)*(1+IF(OR($AI10=$F$4,$AI10=$F$5),$B$22,0)) -> 207.2 | AL10: =VLOOKUP($Q10,武学奇术!$A:$ZZ,28,FALSE) -> 0.81 | AM10: =VLOOKUP($Q10,武学奇术!$A:$ZZ,29,FALSE)*(1+IF(OR($AI10=$F$4,$AI10=$F$5),$B$22,0)) -> 114.1 | AN10: {=$G$3+IFERROR(VLOOKUP($AI10,$F$4:$G$7,2,FALSE),0)+VLOOKUP($Q10,武学奇术!$A:$ZZ,2,FALSE)+SUM(_xlfn.XLOOKUP($R10:$AH10,增益!$A:$A,增益!$B:$B,0))} -> 0.3741 | AO10: {=VLOOKUP($Q10,武学奇术!$A:$ZZ,5,FALSE)+SUM(_xlfn.XLOOKUP($R10:$AH10,增益!$A:$A,增益!$E:$E,0))} -> 0 | AP10: {=$D$10*(1+$AO10)+VLOOKUP($Q10,武学奇术!$A:$ZZ,3,FALSE)+SUM(_xlfn.XLOOKUP($R10:$AH10,增益!$A:$A,增益!$C:$C,0))-$I$2} -> 1797.4 | AQ10: {=$E$10*(1+$AO10)+VLOOKUP($Q10,武学奇术!$A:$ZZ,4,FALSE)+SUM(_xlfn.XLOOKUP($R10:$AH10,增益!$A:$A,增益!$D:$D,0))-$I$2} -> 5488 | AR10: {=IF($F$10-$I$3+VLOOKUP($Q10,武学奇术!$A:$ZZ,6,FALSE)+SUM(_xlfn.XLOOKUP(R10:AH10,增益!$A:$A,增益!$F:$F,0))>0,($F$10-$I$3+VLOOKUP($Q10,武学奇术!$A:$ZZ,6,FALSE)+SUM(_xlfn.XLOOKUP(R10:AH10,增益!$A:$A,增益!$F:$F,0)))/200,($F$10-$I$3+VLOOKUP($Q10,武学奇术!$A:$ZZ,6,FALSE)+SUM(_xlfn.XLOOKUP(R10:AH10,增益!$A:$A,增益!$F:$F,0)))/100)} -> 0.3125 | AS10: {=$G$10+VLOOKUP($Q10,武学奇术!$A:$ZZ,7,FALSE)+SUM(_xlfn.XLOOKUP(R10:AH10,增益!$A:$A,增益!$G:$G,0))} -> 0.1 | AT10: {=VLOOKUP($Q10,武学奇术!$A:$ZZ,8,FALSE)+SUM(_xlfn.XLOOKUP(R10:AH10,增益!$A:$A,增益!$H:$H,0))} -> 0 | AU10: =$D$11*(1+$AT10) -> 0 | AV10: =$E$11*(1+$AT10) -> 0 | AW10: {=IF($F$11-$I$4+VLOOKUP($Q10,武学奇术!$A:$ZZ,9,FALSE)+SUM(_xlfn.XLOOKUP(R10:AH10,增益!$A:$A,增益!$I:$I,0))>0,($F$11-$I$4+VLOOKUP($Q10,武学奇术!$A:$ZZ,9,FALSE)+SUM(_xlfn.XLOOKUP(R10:AH10,增益!$A:$A,增益!$I:$I,0)))/200,($F$11-$I$4+VLOOKUP($Q10,武学奇术!$A:$ZZ,9,FALSE)+SUM(_xlfn.XLOOKUP(R10:AH10,增益!$A:$A,增益!$I:$I,0)))/100)} -> -0.14 | AX10: {=$G$11+VLOOKUP($Q10,武学奇术!$A:$ZZ,10,FALSE)+SUM(_xlfn.XLOOKUP(R10:AH10,增益!$A:$A,增益!$J:$J,0))} -> 0 | AY10: =$D$12*(1+$AT10) -> 0 | AZ10: =$E$12*(1+$AT10) -> 0 | BA10: {=IF($F$12-$I$4+VLOOKUP($Q10,武学奇术!$A:$ZZ,11,FALSE)+SUM(_xlfn.XLOOKUP(R10:AH10,增益!$A:$A,增益!$K:$K,0))>0,($F$12-$I$4+VLOOKUP($Q10,武学奇术!$A:$ZZ,11,FALSE)+SUM(_xlfn.XLOOKUP(R10:AH10,增益!$A:$A,增益!$K:$K,0)))/200,($F$12-$I$4+VLOOKUP($Q10,武学奇术!$A:$ZZ,11,FALSE)+SUM(_xlfn.XLOOKUP(R10:AH10,增益!$A:$A,增益!$K:$K,0)))/100)} -> -0.14 | BB10: {=$G$12+VLOOKUP($Q10,武学奇术!$A:$ZZ,12,FALSE)+SUM(_xlfn.XLOOKUP(R10:AH10,增益!$A:$A,增益!$L:$L,0))} -> 0 | BC10: =$D$13*(1+$AT10) -> 571.2 | BD10: =$E$13*(1+$AT10) -> 1077.4 | BE10: {=IF($F$13-$I$4+VLOOKUP($Q10,武学奇术!$A:$ZZ,13,FALSE)+SUM(_xlfn.XLOOKUP(R10:AH10,增益!$A:$A,增益!$M:$M,0))>0,($F$13-$I$4+VLOOKUP($Q10,武学奇术!$A:$ZZ,13,FALSE)+SUM(_xlfn.XLOOKUP(R10:AH10,增益!$A:$A,增益!$K:$K,0)))/200,($F$13-$I$4+VLOOKUP($Q10,武学奇术!$A:$ZZ,13,FALSE)+SUM(_xlfn.XLOOKUP(R10:AH10,增益!$A:$A,增益!$M:$M,0)))/100)} -> 0.08 | BF10: {=$G$13+VLOOKUP($Q10,武学奇术!$A:$ZZ,14,FALSE)+SUM(_xlfn.XLOOKUP(R10:AH10,增益!$A:$A,增益!$N:$N,0))} -> 0.25 | BG10: =$D$14*(1+$AT10) -> 0 | BH10: =$E$14*(1+$AT10) -> 0 | BI10: {=IF($F$14-$I$4+VLOOKUP($Q10,武学奇术!$A:$ZZ,15,FALSE)+SUM(_xlfn.XLOOKUP(R10:AH10,增益!$A:$A,增益!$O:$O,0))>0,($F$14-$I$4+VLOOKUP($Q10,武学奇术!$A:$ZZ,15,FALSE)+SUM(_xlfn.XLOOKUP(R10:AH10,增益!$A:$A,增益!$O:$O,0)))/200,($F$14-$I$4+VLOOKUP($Q10,武学奇术!$A:$ZZ,15,FALSE)+SUM(_xlfn.XLOOKUP(R10:AH10,增益!$A:$A,增益!$O:$O,0)))/100)} -> -0.14 | BJ10: {=$G$14+VLOOKUP($Q10,武学奇术!$A:$ZZ,16,FALSE)+SUM(_xlfn.XLOOKUP(R10:AH10,增益!$A:$A,增益!$P:$P,0))} -> 0 | BK10: =MIN(IF(VLOOKUP($Q10,武学奇术!$A:$ZZ,23,FALSE)=1,100%,$B$8),100%) -> 1 | BL10: {=IF(VLOOKUP($Q10,武学奇术!$A:$ZZ,23,FALSE)=1,100%,MIN(80%,$B$9+VLOOKUP($Q10,武学奇术!$A:$ZZ,17,FALSE)+SUM(_xlfn.XLOOKUP(R10:AH10,增益!$A:$A,增益!$Q:$Q,0)))+$B$11+SUM(_xlfn.XLOOKUP(R10:AH10,增益!$A:$A,增益!$U:$U,0)))*IF(VLOOKUP($Q10,武学奇术!$A:$ZZ,24,FALSE)=1,0,1)} -> 0.9045 | BM10: {=1+$B$13+VLOOKUP($Q10,武学奇术!$A:$ZZ,18,FALSE)+SUM(_xlfn.XLOOKUP(R10:AH10,增益!$A:$A,增益!$R:$R,0))} -> 1.52 | BN10: {=IF(VLOOKUP($Q10,武学奇术!$A:$ZZ,24,FALSE)=1,100%,MIN(40%,$B$10+VLOOKUP($Q10,武学奇术!$A:$ZZ,19,FALSE)+SUM(_xlfn.XLOOKUP(R10:AH10,增益!$A:$A,增益!$S:$S,0)))+$B$12+SUM(_xlfn.XLOOKUP(R10:AH10,增益!$A:$A,增益!$V:$V,0)))*IF(VLOOKUP($Q10,武学奇术!$A:$ZZ,23,FALSE)=1,0,1)} -> 0.0929 | BO10: {=1+$B$14+VLOOKUP($Q10,武学奇术!$A:$ZZ,20,FALSE)+SUM(_xlfn.XLOOKUP(R10:AH10,增益!$A:$A,增益!$T:$T,0))} -> 1.35 | BP10: =MIN((1-BN10)*BK10,BK10*BL10) -> 0.9045 | BQ10: =1-BN10-BP10-BR10 -> 0.0026 | BR10: =IF(VLOOKUP($Q10,武学奇术!$A:$ZZ,22,FALSE)=1,0,(1-$BK10))*(1-$BN10) -> 0 | BS10: {=SUM(_xlfn.XLOOKUP(R10:AH10,增益!$A:$A,增益!$W:$W,0))+$I$5} -> 0.11
